Workbook

Sheet Resumen
A1: Datos depurados · ZP-05 Vista del Mar · ventana de calibración 12–15/09/2026
A2: Periodo de calibración propuesto: 12/09 00:00 – 15/09 23:45. Dato depurado = fórmula sobre el dato inicial (ver leyenda).
A4: Sensor | B4: Tipo | C4: Unidad | D4: Elemento INP | E4: Offset | F4: Uso recomendado | G4: Hoja
A5: P1 | B5: Presión | C5: m | D5: VN3948790 | E5: =P1!$C$3 -> 0.01 | F5: Usar solo la media horaria (tolerancia mayor) | G5: P1
A6: P2 | B6: Presión | C6: m | D6: VN3942278 | E6: =P2!$C$3 -> -0.27 | F6: Válido | G6: P2
A7: P3 | B7: Presión | C7: m | D7: VN3943135 | E7: =P3!$C$3 -> -0.29 | F7: Válido (suavizado) | G7: P3
A8: P4 | B8: Presión | C8: m | D8: VN3950683 | E8: =P4!$C$3 -> 0.03 | F8: Válido | G8: P4
A9: P5 | B9: Presión | C9: m | D9: VN3948890 | E9: =P5!$C$3 -> 0 | F9: Válido (suavizado) | G9: P5
A10: P6 | B10: Presión | C10: m | D10: VN3582511 | E10: =P6!$C$3 -> -0.24 | F10: Válido | G10: P6
A11: P7 | B11: Presión | C11: m | D11: VN3751475 | E11: =P7!$C$3 -> 0.03 | F11: Válido | G11: P7
A12: P8 | B12: Presión | C12: m | D12: VN3950311 | E12: =P8!$C$3 -> -0.28 | F12: Válido (suavizado) | G12: P8
A13: P9 | B13: Presión | C13: m | D13: VN3948722 | E13: =P9!$C$3 -> -1.3 | F13: Válido | G13: P9
A14: P10 | B14: Presión | C14: m | D14: VN3745765 | E14: =P10!$C$3 -> -1.64 | F14: Válido | G14: P10
A15: P11 | B15: Presión | C15: m | D15: 3949453 | E15: =P11!$C$3 -> -1.32 | F15: Usar solo la media horaria (tolerancia mayor) | G15: P11
A16: L1 | B16: Presión | C16: m | D16: VN3948124 | E16: =L1!$C$3 -> 0 | F16: Válido (suavizado) | G16: L1
A17: L2 | B17: Presión | C17: m | D17: 3949579 | E17: =L2!$C$3 -> 0 | F17: Válido (suavizado) | G17: L2
A18: L3 | B18: Presión | C18: m | D18: 3949333_n2a_1 | E18: =L3!$C$3 -> 0 | F18: Válido (suavizado) | G18: L3
A19: Q1 | B19: Caudal | C19: L/s | D19: 3950155 | E19: =Q1!$C$3 -> 0 | F19: Válido | G19: Q1
A20: Q2 | B20: Caudal | C20: L/s | D20: 3950006 | E20: =Q2!$C$3 -> 0 | F20: Válido | G20: Q2
A21: Q3 | B21: Caudal | C21: L/s | D21: 3949916 | E21: =Q3!$C$3 -> 0 | F21: Válido | G21: Q3
A22: Q4 | B22: Caudal | C22: L/s | D22: 3926415 | E22: =Q4!$C$3 -> 0 | F22: Válido | G22: Q4
A23: N_Meneses | B23: Nivel | C23: m | D23: 3949680 | E23: =N_Meneses!$C$3 -> 0 | F23: Usar solo la media horaria (tolerancia mayor) | G23: N_Meneses
A24: N_Durazno | B24: Nivel | C24: m | D24: 3949679 | E24: =N_Durazno!$C$3 -> 0 | F24: No usar como meta | G24: N_Durazno
A26: Leyenda de la columna «Marca»
A27: 0 | B27: válido | C27: Dato depurado = corregido = dato inicial − offset
A28: 1 | B28: envolvente | C28: Oscilación más rápida que el registro: MEDIA.ACOTADA (TRIMMEAN, 50 %) del dato corregido en la ventana de la hoja (±4 lecturas = 2 h, o ±8 = 4 h)
A29: 2 | B29: interpolado | C29: Pico aislado o hueco ≤ 1 h: interpolación lineal (valor en «Reemplazo»)
A30: 3 | B30: perfil típico | C30: Hueco de 1 a 6 h: perfil diario del propio sensor ajustado a los extremos (valor en «Reemplazo»)
A31: 4 | B31: balance de masa | C31: Nivel de tanque reconstruido con los caudales de entrada y salida (valor en «Reemplazo»)
A32: 9 | B32: excluido | C32: Sin instalar, corte de suministro, sensor fuera del agua: queda vacío
A34: En azul: valores editables (offset, marca y reemplazo). Si cambia una marca o el offset, el dato depurado se recalcula.
A35: Dato inicial: lectura del equipo llevada a la malla común de 15 min (interpolada en la hora real de cada lectura). Presión en m c.a., caudal en L/s, nivel en m.

Sheet Gráficos
A1: Dato inicial y dato depurado por sensor
A2: Ventana 12/09 00:00 – 15/09 23:45 · gris: dato inicial · rojo: dato depurado

Sheet P1
A1: P1 · Presión (m) · VN3948790
A2: Usar solo la media horaria (tolerancia mayor)
A3: Offset | C3: 0.01
A4: Ventana (lecturas a cada lado) | C4: 8
A6: Fecha y hora | B6: Dato inicial (m) | C6: Marca | D6: Reemplazo | E6: Corregido (m) | F6: Dato depurado (m) | G6: Motivo
A7: 46276.917 | B7: 83.6583 | C7: 1 | E7: =IF(OR(C7=9,B7=""),"",B7-$C$3) -> 83.6483 | F7: =IF(C7=9,"",IF(C7=0,E7,IF(C7=1,IF(COUNT(E7:E15)=0,"",TRIMMEAN(E7:E15,0.5)),IF(D7="","",D7)))) -> 83.3845 | G7: fuera de la ventana: solo para la media móvil del borde
A8: 46276.927 | B8: 84.7777 | C8: 1 | E8: =IF(OR(C8=9,B8=""),"",B8-$C$3) -> 84.7677 | F8: =IF(C8=9,"",IF(C8=0,E8,IF(C8=1,IF(COUNT(E7:E16)=0,"",TRIMMEAN(E7:E16,0.5)),IF(D8="","",D8)))) -> 84.1443 | G8: fuera de la ventana: solo para la media móvil del borde
A9: 46276.938 | B9: 83.5719 | C9: 1 | E9: =IF(OR(C9=9,B9=""),"",B9-$C$3) -> 83.5619 | F9: =IF(C9=9,"",IF(C9=0,E9,IF(C9=1,IF(COUNT(E7:E17)=0,"",TRIMMEAN(E7:E17,0.5)),IF(D9="","",D9)))) -> 83.140571 | G9: fuera de la ventana: solo para la media móvil del borde
A10: 46276.948 | B10: 84.0383 | C10: 1 | E10: =IF(OR(C10=9,B10=""),"",B10-$C$3) -> 84.0283 | F10: =IF(C10=9,"",IF(C10=0,E10,IF(C10=1,IF(COUNT(E7:E18)=0,"",TRIMMEAN(E7:E18,0.5)),IF(D10="","",D10)))) -> 82.823467 | G10: fuera de la ventana: solo para la media móvil del borde
A11: 46276.958 | B11: 77.1282 | C11: 1 | E11: =IF(OR(C11=9,B11=""),"",B11-$C$3) -> 77.1182 | F11: =IF(C11=9,"",IF(C11=0,E11,IF(C11=1,IF(COUNT(E7:E19)=0,"",TRIMMEAN(E7:E19,0.5)),IF(D11="","",D11)))) -> 83.554871 | G11: fuera de la ventana: solo para la media móvil del borde
A12: 46276.969 | B12: 80.9263 | C12: 1 | E12: =IF(OR(C12=9,B12=""),"",B12-$C$3) -> 80.9163 | F12: =IF(C12=9,"",IF(C12=0,E12,IF(C12=1,IF(COUNT(E7:E20)=0,"",TRIMMEAN(E7:E20,0.5)),IF(D12="","",D12)))) -> 86.292 | G12: fuera de la ventana: solo para la media móvil del borde
A13: 46276.979 | B13: 74.0174 | C13: 1 | E13: =IF(OR(C13=9,B13=""),"",B13-$C$3) -> 74.0074 | F13: =IF(C13=9,"",IF(C13=0,E13,IF(C13=1,IF(COUNT(E7:E21)=0,"",TRIMMEAN(E7:E21,0.5)),IF(D13="","",D13)))) -> 87.751211 | G13: fuera de la ventana: solo para la media móvil del borde
A14: 46276.99 | B14: 108.7518 | C14: 1 | E14: =IF(OR(C14=9,B14=""),"",B14-$C$3) -> 108.7418 | F14: =IF(C14=9,"",IF(C14=0,E14,IF(C14=1,IF(COUNT(E7:E22)=0,"",TRIMMEAN(E7:E22,0.5)),IF(D14="","",D14)))) -> 87.50365 | G14: fuera de la ventana: solo para la media móvil del borde
A15: 46277 | B15: 113.0443 | C15: 1 | E15: =IF(OR(C15=9,B15=""),"",B15-$C$3) -> 113.0343 | F15: =IF(C15=9,"",IF(C15=0,E15,IF(C15=1,IF(COUNT(E7:E23)=0,"",TRIMMEAN(E7:E23,0.5)),IF(D15="","",D15)))) -> 87.946822 | G15: oscilación más rápida que el registro → media recortada de 4 h
A16: 46277.01 | B16: 87.9533 | C16: 1 | E16: =IF(OR(C16=9,B16=""),"",B16-$C$3) -> 87.9433 | F16: =IF(C16=9,"",IF(C16=0,E16,IF(C16=1,IF(COUNT(E8:E24)=0,"",TRIMMEAN(E8:E24,0.5)),IF(D16="","",D16)))) -> 89.096533 | G16: oscilación más rápida que el registro → media recortada de 4 h
A17: 46277.021 | B17: 54.4413 | C17: 1 | E17: =IF(OR(C17=9,B17=""),"",B17-$C$3) -> 54.4313 | F17: =IF(C17=9,"",IF(C17=0,E17,IF(C17=1,IF(COUNT(E9:E25)=0,"",TRIMMEAN(E9:E25,0.5)),IF(D17="","",D17)))) -> 91.111656 | G17: oscilación más rápida que el registro → media recortada de 4 h
A18: 46277.031 | B18: 80.0283 | C18: 1 | E18: =IF(OR(C18=9,B18=""),"",B18-$C$3) -> 80.0183 | F18: =IF(C18=9,"",IF(C18=0,E18,IF(C18=1,IF(COUNT(E10:E26)=0,"",TRIMMEAN(E10:E26,0.5)),IF(D18="","",D18)))) -> 92.237278 | G18: oscilación más rápida que el registro → media recortada de 4 h
A19: 46277.042 | B19: 115.0428 | C19: 1 | E19: =IF(OR(C19=9,B19=""),"",B19-$C$3) -> 115.0328 | F19: =IF(C19=9,"",IF(C19=0,E19,IF(C19=1,IF(COUNT(E11:E27)=0,"",TRIMMEAN(E11:E27,0.5)),IF(D19="","",D19)))) -> 93.547856 | G19: oscilación más rápida que el registro → media recortada de 4 h
A20: 46277.052 | B20: 105.4619 | C20: 1 | E20: =IF(OR(C20=9,B20=""),"",B20-$C$3) -> 105.4519 | F20: =IF(C20=9,"",IF(C20=0,E20,IF(C20=1,IF(COUNT(E12:E28)=0,"",TRIMMEAN(E12:E28,0.5)),IF(D20="","",D20)))) -> 96.274033 | G20: oscilación más rápida que el registro → media recortada de 4 h
A21: 46277.062 | B21: 99.4349 | C21: 1 | E21: =IF(OR(C21=9,B21=""),"",B21-$C$3) -> 99.4249 | F21: =IF(C21=9,"",IF(C21=0,E21,IF(C21=1,IF(COUNT(E13:E29)=0,"",TRIMMEAN(E13:E29,0.5)),IF(D21="","",D21)))) -> 96.274033 | G21: oscilación más rápida que el registro → media recortada de 4 h
A22: 46277.073 | B22: 95.7485 | C22: 1 | E22: =IF(OR(C22=9,B22=""),"",B22-$C$3) -> 95.7385 | F22: =IF(C22=9,"",IF(C22=0,E22,IF(C22=1,IF(COUNT(E14:E30)=0,"",TRIMMEAN(E14:E30,0.5)),IF(D22="","",D22)))) -> 96.274033 | G22: oscilación más rápida que el registro → media recortada de 4 h
A23: 46277.083 | B23: 91.5022 | C23: 1 | E23: =IF(OR(C23=9,B23=""),"",B23-$C$3) -> 91.4922 | F23: =IF(C23=9,"",IF(C23=0,E23,IF(C23=1,IF(COUNT(E15:E31)=0,"",TRIMMEAN(E15:E31,0.5)),IF(D23="","",D23)))) -> 94.334056 | G23: oscilación más rápida que el registro → media recortada de 4 h
A24: 46277.094 | B24: 94.0057 | C24: 1 | E24: =IF(OR(C24=9,B24=""),"",B24-$C$3) -> 93.9957 | F24: =IF(C24=9,"",IF(C24=0,E24,IF(C24=1,IF(COUNT(E16:E32)=0,"",TRIMMEAN(E16:E32,0.5)),IF(D24="","",D24)))) -> 94.287367 | G24: oscilación más rápida que el registro → media recortada de 4 h
A25: 46277.104 | B25: 102.9138 | C25: 1 | E25: =IF(OR(C25=9,B25=""),"",B25-$C$3) -> 102.9038 | F25: =IF(C25=9,"",IF(C25=0,E25,IF(C25=1,IF(COUNT(E17:E33)=0,"",TRIMMEAN(E17:E33,0.5)),IF(D25="","",D25)))) -> 95.949644 | G25: oscilación más rápida que el registro → media recortada de 4 h
A26: 46277.115 | B26: 93.7025 | C26: 1 | E26: =IF(OR(C26=9,B26=""),"",B26-$C$3) -> 93.6925 | F26: =IF(C26=9,"",IF(C26=0,E26,IF(C26=1,IF(COUNT(E18:E34)=0,"",TRIMMEAN(E18:E34,0.5)),IF(D26="","",D26)))) -> 97.869 | G26: oscilación más rápida que el registro → media recortada de 4 h
... A398: 46280.99 | B398: 105.5759 | C398: 1 | E398: =IF(OR(C398=9,B398=""),"",B398-$C$3) -> 105.5659 | F398: =IF(C398=9,"",IF(C398=0,E398,IF(C398=1,IF(COUNT(E390:E406)=0,"",TRIMMEAN(E390:E406,0.5)),IF(D398="","",D398)))) -> 77.829656 | G398: oscilación más rápida que el registro → media recortada de 4 h
A399: 46281 | B399: 96.8657 | C399: 1 | E399: =IF(OR(C399=9,B399=""),"",B399-$C$3) -> 96.8557 | F399: =IF(C399=9,"",IF(C399=0,E399,IF(C399=1,IF(COUNT(E391:E406)=0,"",TRIMMEAN(E391:E406,0.5)),IF(D399="","",D399)))) -> 77.424725 | G399: fuera de la ventana: solo para la media móvil del borde
A400: 46281.01 | B400: 98.434 | C400: 1 | E400: =IF(OR(C400=9,B400=""),"",B400-$C$3) -> 98.424 | F400: =IF(C400=9,"",IF(C400=0,E400,IF(C400=1,IF(COUNT(E392:E406)=0,"",TRIMMEAN(E392:E406,0.5)),IF(D400="","",D400)))) -> 75.744489 | G400: fuera de la ventana: solo para la media móvil del borde
A401: 46281.021 | B401: 87.5593 | C401: 1 | E401: =IF(OR(C401=9,B401=""),"",B401-$C$3) -> 87.5493 | F401: =IF(C401=9,"",IF(C401=0,E401,IF(C401=1,IF(COUNT(E393:E406)=0,"",TRIMMEAN(E393:E406,0.5)),IF(D401="","",D401)))) -> 77.77865 | G401: fuera de la ventana: solo para la media móvil del borde
A402: 46281.031 | B402: 101.7522 | C402: 1 | E402: =IF(OR(C402=9,B402=""),"",B402-$C$3) -> 101.7422 | F402: =IF(C402=9,"",IF(C402=0,E402,IF(C402=1,IF(COUNT(E394:E406)=0,"",TRIMMEAN(E394:E406,0.5)),IF(D402="","",D402)))) -> 80.428357 | G402: fuera de la ventana: solo para la media móvil del borde
A403: 46281.042 | B403: 74.2807 | C403: 1 | E403: =IF(OR(C403=9,B403=""),"",B403-$C$3) -> 74.2707 | F403: =IF(C403=9,"",IF(C403=0,E403,IF(C403=1,IF(COUNT(E395:E406)=0,"",TRIMMEAN(E395:E406,0.5)),IF(D403="","",D403)))) -> 83.702017 | G403: fuera de la ventana: solo para la media móvil del borde
A404: 46281.052 | B404: 60.7964 | C404: 1 | E404: =IF(OR(C404=9,B404=""),"",B404-$C$3) -> 60.7864 | F404: =IF(C404=9,"",IF(C404=0,E404,IF(C404=1,IF(COUNT(E396:E406)=0,"",TRIMMEAN(E396:E406,0.5)),IF(D404="","",D404)))) -> 85.805157 | G404: fuera de la ventana: solo para la media móvil del borde
A405: 46281.062 | B405: 95.9939 | C405: 1 | E405: =IF(OR(C405=9,B405=""),"",B405-$C$3) -> 95.9839 | F405: =IF(C405=9,"",IF(C405=0,E405,IF(C405=1,IF(COUNT(E397:E406)=0,"",TRIMMEAN(E397:E406,0.5)),IF(D405="","",D405)))) -> 89.3087 | G405: fuera de la ventana: solo para la media móvil del borde
A406: 46281.073 | B406: 64.7939 | C406: 1 | E406: =IF(OR(C406=9,B406=""),"",B406-$C$3) -> 64.7839 | F406: =IF(C406=9,"",IF(C406=0,E406,IF(C406=1,IF(COUNT(E398:E406)=0,"",TRIMMEAN(E398:E406,0.5)),IF(D406="","",D406)))) -> 90.61672 | G406: fuera de la ventana: solo para la media móvil del borde

Sheet P2
A1: P2 · Presión (m) · VN3942278
A2: Válido
A3: Offset | C3: -0.27
A4: Ventana (lecturas a cada lado) | C4: 4
A6: Fecha y hora | B6: Dato inicial (m) | C6: Marca | D6: Reemplazo | E6: Corregido (m) | F6: Dato depurado (m) | G6: Motivo
A7: 46276.917 | B7: 79.0742 | C7: 0 | E7: =IF(OR(C7=9,B7=""),"",B7-$C$3) -> 79.3442 | F7: =IF(C7=9,"",IF(C7=0,E7,IF(C7=1,IF(COUNT(E7:E11)=0,"",TRIMMEAN(E7:E11,0.5)),IF(D7="","",D7)))) -> 79.3442 | G7: fuera de la ventana: solo para la media móvil del borde
A8: 46276.927 | B8: 78.6653 | C8: 0 | E8: =IF(OR(C8=9,B8=""),"",B8-$C$3) -> 78.9353 | F8: =IF(C8=9,"",IF(C8=0,E8,IF(C8=1,IF(COUNT(E7:E12)=0,"",TRIMMEAN(E7:E12,0.5)),IF(D8="","",D8)))) -> 78.9353 | G8: fuera de la ventana: solo para la media móvil del borde
A9: 46276.938 | B9: 79.1571 | C9: 0 | E9: =IF(OR(C9=9,B9=""),"",B9-$C$3) -> 79.4271 | F9: =IF(C9=9,"",IF(C9=0,E9,IF(C9=1,IF(COUNT(E7:E13)=0,"",TRIMMEAN(E7:E13,0.5)),IF(D9="","",D9)))) -> 79.4271 | G9: fuera de la ventana: solo para la media móvil del borde
A10: 46276.948 | B10: 78.8386 | C10: 0 | E10: =IF(OR(C10=9,B10=""),"",B10-$C$3) -> 79.1086 | F10: =IF(C10=9,"",IF(C10=0,E10,IF(C10=1,IF(COUNT(E7:E14)=0,"",TRIMMEAN(E7:E14,0.5)),IF(D10="","",D10)))) -> 79.1086 | G10: fuera de la ventana: solo para la media móvil del borde
A11: 46276.958 | B11: 79.1194 | C11: 0 | E11: =IF(OR(C11=9,B11=""),"",B11-$C$3) -> 79.3894 | F11: =IF(C11=9,"",IF(C11=0,E11,IF(C11=1,IF(COUNT(E7:E15)=0,"",TRIMMEAN(E7:E15,0.5)),IF(D11="","",D11)))) -> 79.3894 | G11: fuera de la ventana: solo para la media móvil del borde
A12: 46276.969 | B12: 80.308 | C12: 0 | E12: =IF(OR(C12=9,B12=""),"",B12-$C$3) -> 80.578 | F12: =IF(C12=9,"",IF(C12=0,E12,IF(C12=1,IF(COUNT(E8:E16)=0,"",TRIMMEAN(E8:E16,0.5)),IF(D12="","",D12)))) -> 80.578 | G12: fuera de la ventana: solo para la media móvil del borde
A13: 46276.979 | B13: 80.7153 | C13: 0 | E13: =IF(OR(C13=9,B13=""),"",B13-$C$3) -> 80.9853 | F13: =IF(C13=9,"",IF(C13=0,E13,IF(C13=1,IF(COUNT(E9:E17)=0,"",TRIMMEAN(E9:E17,0.5)),IF(D13="","",D13)))) -> 80.9853 | G13: fuera de la ventana: solo para la media móvil del borde
A14: 46276.99 | B14: 81.1089 | C14: 0 | E14: =IF(OR(C14=9,B14=""),"",B14-$C$3) -> 81.3789 | F14: =IF(C14=9,"",IF(C14=0,E14,IF(C14=1,IF(COUNT(E10:E18)=0,"",TRIMMEAN(E10:E18,0.5)),IF(D14="","",D14)))) -> 81.3789 | G14: fuera de la ventana: solo para la media móvil del borde
A15: 46277 | B15: 80.9549 | C15: 0 | E15: =IF(OR(C15=9,B15=""),"",B15-$C$3) -> 81.2249 | F15: =IF(C15=9,"",IF(C15=0,E15,IF(C15=1,IF(COUNT(E11:E19)=0,"",TRIMMEAN(E11:E19,0.5)),IF(D15="","",D15)))) -> 81.2249
A16: 46277.01 | B16: 80.874 | C16: 0 | E16: =IF(OR(C16=9,B16=""),"",B16-$C$3) -> 81.144 | F16: =IF(C16=9,"",IF(C16=0,E16,IF(C16=1,IF(COUNT(E12:E20)=0,"",TRIMMEAN(E12:E20,0.5)),IF(D16="","",D16)))) -> 81.144
A17: 46277.021 | B17: 80.8271 | C17: 0 | E17: =IF(OR(C17=9,B17=""),"",B17-$C$3) -> 81.0971 | F17: =IF(C17=9,"",IF(C17=0,E17,IF(C17=1,IF(COUNT(E13:E21)=0,"",TRIMMEAN(E13:E21,0.5)),IF(D17="","",D17)))) -> 81.0971
A18: 46277.031 | B18: 81.1724 | C18: 0 | E18: =IF(OR(C18=9,B18=""),"",B18-$C$3) -> 81.4424 | F18: =IF(C18=9,"",IF(C18=0,E18,IF(C18=1,IF(COUNT(E14:E22)=0,"",TRIMMEAN(E14:E22,0.5)),IF(D18="","",D18)))) -> 81.4424
A19: 46277.042 | B19: 80.7112 | C19: 0 | E19: =IF(OR(C19=9,B19=""),"",B19-$C$3) -> 80.9812 | F19: =IF(C19=9,"",IF(C19=0,E19,IF(C19=1,IF(COUNT(E15:E23)=0,"",TRIMMEAN(E15:E23,0.5)),IF(D19="","",D19)))) -> 80.9812
A20: 46277.052 | B20: 81.2724 | C20: 0 | E20: =IF(OR(C20=9,B20=""),"",B20-$C$3) -> 81.5424 | F20: =IF(C20=9,"",IF(C20=0,E20,IF(C20=1,IF(COUNT(E16:E24)=0,"",TRIMMEAN(E16:E24,0.5)),IF(D20="","",D20)))) -> 81.5424
A21: 46277.062 | B21: 80.8628 | C21: 0 | E21: =IF(OR(C21=9,B21=""),"",B21-$C$3) -> 81.1328 | F21: =IF(C21=9,"",IF(C21=0,E21,IF(C21=1,IF(COUNT(E17:E25)=0,"",TRIMMEAN(E17:E25,0.5)),IF(D21="","",D21)))) -> 81.1328
A22: 46277.073 | B22: 81.2251 | C22: 0 | E22: =IF(OR(C22=9,B22=""),"",B22-$C$3) -> 81.4951 | F22: =IF(C22=9,"",IF(C22=0,E22,IF(C22=1,IF(COUNT(E18:E26)=0,"",TRIMMEAN(E18:E26,0.5)),IF(D22="","",D22)))) -> 81.4951
A23: 46277.083 | B23: 80.8233 | C23: 0 | E23: =IF(OR(C23=9,B23=""),"",B23-$C$3) -> 81.0933 | F23: =IF(C23=9,"",IF(C23=0,E23,IF(C23=1,IF(COUNT(E19:E27)=0,"",TRIMMEAN(E19:E27,0.5)),IF(D23="","",D23)))) -> 81.0933
A24: 46277.094 | B24: 81.1344 | C24: 0 | E24: =IF(OR(C24=9,B24=""),"",B24-$C$3) -> 81.4044 | F24: =IF(C24=9,"",IF(C24=0,E24,IF(C24=1,IF(COUNT(E20:E28)=0,"",TRIMMEAN(E20:E28,0.5)),IF(D24="","",D24)))) -> 81.4044
A25: 46277.104 | B25: 81.3835 | C25: 0 | E25: =IF(OR(C25=9,B25=""),"",B25-$C$3) -> 81.6535 | F25: =IF(C25=9,"",IF(C25=0,E25,IF(C25=1,IF(COUNT(E21:E29)=0,"",TRIMMEAN(E21:E29,0.5)),IF(D25="","",D25)))) -> 81.6535
A26: 46277.115 | B26: 81.1408 | C26: 0 | E26: =IF(OR(C26=9,B26=""),"",B26-$C$3) -> 81.4108 | F26: =IF(C26=9,"",IF(C26=0,E26,IF(C26=1,IF(COUNT(E22:E30)=0,"",TRIMMEAN(E22:E30,0.5)),IF(D26="","",D26)))) -> 81.4108
... A398: 46280.99 | B398: 81.2156 | C398: 0 | E398: =IF(OR(C398=9,B398=""),"",B398-$C$3) -> 81.4856 | F398: =IF(C398=9,"",IF(C398=0,E398,IF(C398=1,IF(COUNT(E394:E402)=0,"",TRIMMEAN(E394:E402,0.5)),IF(D398="","",D398)))) -> 81.4856
A399: 46281 | B399: 81.2863 | C399: 0 | E399: =IF(OR(C399=9,B399=""),"",B399-$C$3) -> 81.5563 | F399: =IF(C399=9,"",IF(C399=0,E399,IF(C399=1,IF(COUNT(E395:E403)=0,"",TRIMMEAN(E395:E403,0.5)),IF(D399="","",D399)))) -> 81.5563 | G399: fuera de la ventana: solo para la media móvil del borde
A400: 46281.01 | B400: 81.1024 | C400: 0 | E400: =IF(OR(C400=9,B400=""),"",B400-$C$3) -> 81.3724 | F400: =IF(C400=9,"",IF(C400=0,E400,IF(C400=1,IF(COUNT(E396:E404)=0,"",TRIMMEAN(E396:E404,0.5)),IF(D400="","",D400)))) -> 81.3724 | G400: fuera de la ventana: solo para la media móvil del borde
A401: 46281.021 | B401: 81.8533 | C401: 0 | E401: =IF(OR(C401=9,B401=""),"",B401-$C$3) -> 82.1233 | F401: =IF(C401=9,"",IF(C401=0,E401,IF(C401=1,IF(COUNT(E397:E405)=0,"",TRIMMEAN(E397:E405,0.5)),IF(D401="","",D401)))) -> 82.1233 | G401: fuera de la ventana: solo para la media móvil del borde
A402: 46281.031 | B402: 81.5762 | C402: 0 | E402: =IF(OR(C402=9,B402=""),"",B402-$C$3) -> 81.8462 | F402: =IF(C402=9,"",IF(C402=0,E402,IF(C402=1,IF(COUNT(E398:E406)=0,"",TRIMMEAN(E398:E406,0.5)),IF(D402="","",D402)))) -> 81.8462 | G402: fuera de la ventana: solo para la media móvil del borde
A403: 46281.042 | B403: 81.563 | C403: 0 | E403: =IF(OR(C403=9,B403=""),"",B403-$C$3) -> 81.833 | F403: =IF(C403=9,"",IF(C403=0,E403,IF(C403=1,IF(COUNT(E399:E406)=0,"",TRIMMEAN(E399:E406,0.5)),IF(D403="","",D403)))) -> 81.833 | G403: fuera de la ventana: solo para la media móvil del borde
A404: 46281.052 | B404: 81.3346 | C404: 0 | E404: =IF(OR(C404=9,B404=""),"",B404-$C$3) -> 81.6046 | F404: =IF(C404=9,"",IF(C404=0,E404,IF(C404=1,IF(COUNT(E400:E406)=0,"",TRIMMEAN(E400:E406,0.5)),IF(D404="","",D404)))) -> 81.6046 | G404: fuera de la ventana: solo para la media móvil del borde
A405: 46281.062 | B405: 81.8298 | C405: 0 | E405: =IF(OR(C405=9,B405=""),"",B405-$C$3) -> 82.0998 | F405: =IF(C405=9,"",IF(C405=0,E405,IF(C405=1,IF(COUNT(E401:E406)=0,"",TRIMMEAN(E401:E406,0.5)),IF(D405="","",D405)))) -> 82.0998 | G405: fuera de la ventana: solo para la media móvil del borde
A406: 46281.073 | B406: 81.959 | C406: 0 | E406: =IF(OR(C406=9,B406=""),"",B406-$C$3) -> 82.229 | F406: =IF(C406=9,"",IF(C406=0,E406,IF(C406=1,IF(COUNT(E402:E406)=0,"",TRIMMEAN(E402:E406,0.5)),IF(D406="","",D406)))) -> 82.229 | G406: fuera de la ventana: solo para la media móvil del borde

Sheet P3
A1: P3 · Presión (m) · VN3943135
A2: Válido (suavizado)
A3: Offset | C3: -0.29
A4: Ventana (lecturas a cada lado) | C4: 4
A6: Fecha y hora | B6: Dato inicial (m) | C6: Marca | D6: Reemplazo | E6: Corregido (m) | F6: Dato depurado (m) | G6: Motivo
A7: 46276.917 | B7: 138.0748 | C7: 0 | E7: =IF(OR(C7=9,B7=""),"",B7-$C$3) -> 138.3648 | F7: =IF(C7=9,"",IF(C7=0,E7,IF(C7=1,IF(COUNT(E7:E11)=0,"",TRIMMEAN(E7:E11,0.5)),IF(D7="","",D7)))) -> 138.3648 | G7: fuera de la ventana: solo para la media móvil del borde
A8: 46276.927 | B8: 141.2292 | C8: 0 | E8: =IF(OR(C8=9,B8=""),"",B8-$C$3) -> 141.5192 | F8: =IF(C8=9,"",IF(C8=0,E8,IF(C8=1,IF(COUNT(E7:E12)=0,"",TRIMMEAN(E7:E12,0.5)),IF(D8="","",D8)))) -> 141.5192 | G8: fuera de la ventana: solo para la media móvil del borde
A9: 46276.938 | B9: 140.5609 | C9: 0 | E9: =IF(OR(C9=9,B9=""),"",B9-$C$3) -> 140.8509 | F9: =IF(C9=9,"",IF(C9=0,E9,IF(C9=1,IF(COUNT(E7:E13)=0,"",TRIMMEAN(E7:E13,0.5)),IF(D9="","",D9)))) -> 140.8509 | G9: fuera de la ventana: solo para la media móvil del borde
A10: 46276.948 | B10: 139.6595 | C10: 0 | E10: =IF(OR(C10=9,B10=""),"",B10-$C$3) -> 139.9495 | F10: =IF(C10=9,"",IF(C10=0,E10,IF(C10=1,IF(COUNT(E7:E14)=0,"",TRIMMEAN(E7:E14,0.5)),IF(D10="","",D10)))) -> 139.9495 | G10: fuera de la ventana: solo para la media móvil del borde
A11: 46276.958 | B11: 131.4242 | C11: 0 | E11: =IF(OR(C11=9,B11=""),"",B11-$C$3) -> 131.7142 | F11: =IF(C11=9,"",IF(C11=0,E11,IF(C11=1,IF(COUNT(E7:E15)=0,"",TRIMMEAN(E7:E15,0.5)),IF(D11="","",D11)))) -> 131.7142 | G11: fuera de la ventana: solo para la media móvil del borde
A12: 46276.969 | B12: 109.864 | C12: 0 | E12: =IF(OR(C12=9,B12=""),"",B12-$C$3) -> 110.154 | F12: =IF(C12=9,"",IF(C12=0,E12,IF(C12=1,IF(COUNT(E8:E16)=0,"",TRIMMEAN(E8:E16,0.5)),IF(D12="","",D12)))) -> 110.154 | G12: fuera de la ventana: solo para la media móvil del borde
A13: 46276.979 | B13: 107.8993 | C13: 0 | E13: =IF(OR(C13=9,B13=""),"",B13-$C$3) -> 108.1893 | F13: =IF(C13=9,"",IF(C13=0,E13,IF(C13=1,IF(COUNT(E9:E17)=0,"",TRIMMEAN(E9:E17,0.5)),IF(D13="","",D13)))) -> 108.1893 | G13: fuera de la ventana: solo para la media móvil del borde
A14: 46276.99 | B14: 100.9468 | C14: 0 | E14: =IF(OR(C14=9,B14=""),"",B14-$C$3) -> 101.2368 | F14: =IF(C14=9,"",IF(C14=0,E14,IF(C14=1,IF(COUNT(E10:E18)=0,"",TRIMMEAN(E10:E18,0.5)),IF(D14="","",D14)))) -> 101.2368 | G14: fuera de la ventana: solo para la media móvil del borde
A15: 46277 | B15: 100.5478 | C15: 1 | E15: =IF(OR(C15=9,B15=""),"",B15-$C$3) -> 100.8378 | F15: =IF(C15=9,"",IF(C15=0,E15,IF(C15=1,IF(COUNT(E11:E19)=0,"",TRIMMEAN(E11:E19,0.5)),IF(D15="","",D15)))) -> 103.82952 | G15: oscilación más rápida que el registro → media recortada de 2 h
A16: 46277.01 | B16: 101.3636 | C16: 1 | E16: =IF(OR(C16=9,B16=""),"",B16-$C$3) -> 101.6536 | F16: =IF(C16=9,"",IF(C16=0,E16,IF(C16=1,IF(COUNT(E12:E20)=0,"",TRIMMEAN(E12:E20,0.5)),IF(D16="","",D16)))) -> 103.82952 | G16: oscilación más rápida que el registro → media recortada de 2 h
A17: 46277.021 | B17: 106.0944 | C17: 1 | E17: =IF(OR(C17=9,B17=""),"",B17-$C$3) -> 106.3844 | F17: =IF(C17=9,"",IF(C17=0,E17,IF(C17=1,IF(COUNT(E13:E21)=0,"",TRIMMEAN(E13:E21,0.5)),IF(D17="","",D17)))) -> 102.5187 | G17: oscilación más rápida que el registro → media recortada de 2 h
A18: 46277.031 | B18: 101.3935 | C18: 1 | E18: =IF(OR(C18=9,B18=""),"",B18-$C$3) -> 101.6835 | F18: =IF(C18=9,"",IF(C18=0,E18,IF(C18=1,IF(COUNT(E14:E22)=0,"",TRIMMEAN(E14:E22,0.5)),IF(D18="","",D18)))) -> 102.5187 | G18: oscilación más rápida que el registro → media recortada de 2 h
A19: 46277.042 | B19: 99.7109 | C19: 1 | E19: =IF(OR(C19=9,B19=""),"",B19-$C$3) -> 100.0009 | F19: =IF(C19=9,"",IF(C19=0,E19,IF(C19=1,IF(COUNT(E15:E23)=0,"",TRIMMEAN(E15:E23,0.5)),IF(D19="","",D19)))) -> 103.22122 | G19: oscilación más rápida que el registro → media recortada de 2 h
A20: 46277.052 | B20: 109.5621 | C20: 1 | E20: =IF(OR(C20=9,B20=""),"",B20-$C$3) -> 109.8521 | F20: =IF(C20=9,"",IF(C20=0,E20,IF(C20=1,IF(COUNT(E16:E24)=0,"",TRIMMEAN(E16:E24,0.5)),IF(D20="","",D20)))) -> 104.03998 | G20: oscilación más rápida que el registro → media recortada de 2 h
A21: 46277.062 | B21: 101.3452 | C21: 1 | E21: =IF(OR(C21=9,B21=""),"",B21-$C$3) -> 101.6352 | F21: =IF(C21=9,"",IF(C21=0,E21,IF(C21=1,IF(COUNT(E17:E25)=0,"",TRIMMEAN(E17:E25,0.5)),IF(D21="","",D21)))) -> 105.67968 | G21: oscilación más rápida que el registro → media recortada de 2 h
A22: 46277.073 | B22: 110.0631 | C22: 1 | E22: =IF(OR(C22=9,B22=""),"",B22-$C$3) -> 110.3531 | F22: =IF(C22=9,"",IF(C22=0,E22,IF(C22=1,IF(COUNT(E18:E26)=0,"",TRIMMEAN(E18:E26,0.5)),IF(D22="","",D22)))) -> 105.96412 | G22: oscilación más rápida que el registro → media recortada de 2 h
... A402: 46281.031 | B402: 103.9761 | C402: 1 | E402: =IF(OR(C402=9,B402=""),"",B402-$C$3) -> 104.2661 | F402: =IF(C402=9,"",IF(C402=0,E402,IF(C402=1,IF(COUNT(E398:E406)=0,"",TRIMMEAN(E398:E406,0.5)),IF(D402="","",D402)))) -> 103.88906 | G402: fuera de la ventana: solo para la media móvil del borde
A403: 46281.042 | B403: 101.3547 | C403: 1 | E403: =IF(OR(C403=9,B403=""),"",B403-$C$3) -> 101.6447 | F403: =IF(C403=9,"",IF(C403=0,E403,IF(C403=1,IF(COUNT(E399:E406)=0,"",TRIMMEAN(E399:E406,0.5)),IF(D403="","",D403)))) -> 103.41173 | G403: fuera de la ventana: solo para la media móvil del borde
A404: 46281.052 | B404: 100.3772 | C404: 1 | E404: =IF(OR(C404=9,B404=""),"",B404-$C$3) -> 100.6672 | F404: =IF(C404=9,"",IF(C404=0,E404,IF(C404=1,IF(COUNT(E400:E406)=0,"",TRIMMEAN(E400:E406,0.5)),IF(D404="","",D404)))) -> 103.88906 | G404: fuera de la ventana: solo para la media móvil del borde
A405: 46281.062 | B405: 110.3609 | C405: 1 | E405: =IF(OR(C405=9,B405=""),"",B405-$C$3) -> 110.6509 | F405: =IF(C405=9,"",IF(C405=0,E405,IF(C405=1,IF(COUNT(E401:E406)=0,"",TRIMMEAN(E401:E406,0.5)),IF(D405="","",D405)))) -> 104.33695 | G405: fuera de la ventana: solo para la media móvil del borde
A406: 46281.073 | B406: 105.3486 | C406: 1 | E406: =IF(OR(C406=9,B406=""),"",B406-$C$3) -> 105.6386 | F406: =IF(C406=9,"",IF(C406=0,E406,IF(C406=1,IF(COUNT(E402:E406)=0,"",TRIMMEAN(E402:E406,0.5)),IF(D406="","",D406)))) -> 103.8498 | G406: fuera de la ventana: solo para la media móvil del borde

Sheet P4
A1: P4 · Presión (m) · VN3950683
A2: Válido
A3: Offset | C3: 0.03
A4: Ventana (lecturas a cada lado) | C4: 4
A6: Fecha y hora | B6: Dato inicial (m) | C6: Marca | D6: Reemplazo | E6: Corregido (m) | F6: Dato depurado (m) | G6: Motivo
A7: 46276.917 | B7: 97.2303 | C7: 0 | E7: =IF(OR(C7=9,B7=""),"",B7-$C$3) -> 97.2003 | F7: =IF(C7=9,"",IF(C7=0,E7,IF(C7=1,IF(COUNT(E7:E11)=0,"",TRIMMEAN(E7:E11,0.5)),IF(D7="","",D7)))) -> 97.2003 | G7: fuera de la ventana: solo para la media móvil del borde
A8: 46276.927 | B8: 97.6008 | C8: 0 | E8: =IF(OR(C8=9,B8=""),"",B8-$C$3) -> 97.5708 | F8: =IF(C8=9,"",IF(C8=0,E8,IF(C8=1,IF(COUNT(E7:E12)=0,"",TRIMMEAN(E7:E12,0.5)),IF(D8="","",D8)))) -> 97.5708 | G8: fuera de la ventana: solo para la media móvil del borde
A9: 46276.938 | B9: 101.2854 | C9: 0 | E9: =IF(OR(C9=9,B9=""),"",B9-$C$3) -> 101.2554 | F9: =IF(C9=9,"",IF(C9=0,E9,IF(C9=1,IF(COUNT(E7:E13)=0,"",TRIMMEAN(E7:E13,0.5)),IF(D9="","",D9)))) -> 101.2554 | G9: fuera de la ventana: solo para la media móvil del borde
A10: 46276.948 | B10: 101.5964 | C10: 0 | E10: =IF(OR(C10=9,B10=""),"",B10-$C$3) -> 101.5664 | F10: =IF(C10=9,"",IF(C10=0,E10,IF(C10=1,IF(COUNT(E7:E14)=0,"",TRIMMEAN(E7:E14,0.5)),IF(D10="","",D10)))) -> 101.5664 | G10: fuera de la ventana: solo para la media móvil del borde
A11: 46276.958 | B11: 92.9067 | C11: 0 | E11: =IF(OR(C11=9,B11=""),"",B11-$C$3) -> 92.8767 | F11: =IF(C11=9,"",IF(C11=0,E11,IF(C11=1,IF(COUNT(E7:E15)=0,"",TRIMMEAN(E7:E15,0.5)),IF(D11="","",D11)))) -> 92.8767 | G11: fuera de la ventana: solo para la media móvil del borde
A12: 46276.969 | B12: 70.1856 | C12: 0 | E12: =IF(OR(C12=9,B12=""),"",B12-$C$3) -> 70.1556 | F12: =IF(C12=9,"",IF(C12=0,E12,IF(C12=1,IF(COUNT(E8:E16)=0,"",TRIMMEAN(E8:E16,0.5)),IF(D12="","",D12)))) -> 70.1556 | G12: fuera de la ventana: solo para la media móvil del borde
A13: 46276.979 | B13: 66.7679 | C13: 0 | E13: =IF(OR(C13=9,B13=""),"",B13-$C$3) -> 66.7379 | F13: =IF(C13=9,"",IF(C13=0,E13,IF(C13=1,IF(COUNT(E9:E17)=0,"",TRIMMEAN(E9:E17,0.5)),IF(D13="","",D13)))) -> 66.7379 | G13: fuera de la ventana: solo para la media móvil del borde
A14: 46276.99 | B14: 62.14 | C14: 0 | E14: =IF(OR(C14=9,B14=""),"",B14-$C$3) -> 62.11 | F14: =IF(C14=9,"",IF(C14=0,E14,IF(C14=1,IF(COUNT(E10:E18)=0,"",TRIMMEAN(E10:E18,0.5)),IF(D14="","",D14)))) -> 62.11 | G14: fuera de la ventana: solo para la media móvil del borde
A15: 46277 | B15: 61.0812 | C15: 0 | E15: =IF(OR(C15=9,B15=""),"",B15-$C$3) -> 61.0512 | F15: =IF(C15=9,"",IF(C15=0,E15,IF(C15=1,IF(COUNT(E11:E19)=0,"",TRIMMEAN(E11:E19,0.5)),IF(D15="","",D15)))) -> 61.0512
A16: 46277.01 | B16: 65.5391 | C16: 0 | E16: =IF(OR(C16=9,B16=""),"",B16-$C$3) -> 65.5091 | F16: =IF(C16=9,"",IF(C16=0,E16,IF(C16=1,IF(COUNT(E12:E20)=0,"",TRIMMEAN(E12:E20,0.5)),IF(D16="","",D16)))) -> 65.5091
A17: 46277.021 | B17: 66.7577 | C17: 0 | E17: =IF(OR(C17=9,B17=""),"",B17-$C$3) -> 66.7277 | F17: =IF(C17=9,"",IF(C17=0,E17,IF(C17=1,IF(COUNT(E13:E21)=0,"",TRIMMEAN(E13:E21,0.5)),IF(D17="","",D17)))) -> 66.7277
A18: 46277.031 | B18: 59.2593 | C18: 0 | E18: =IF(OR(C18=9,B18=""),"",B18-$C$3) -> 59.2293 | F18: =IF(C18=9,"",IF(C18=0,E18,IF(C18=1,IF(COUNT(E14:E22)=0,"",TRIMMEAN(E14:E22,0.5)),IF(D18="","",D18)))) -> 59.2293
A19: 46277.042 | B19: 65.828 | C19: 0 | E19: =IF(OR(C19=9,B19=""),"",B19-$C$3) -> 65.798 | F19: =IF(C19=9,"",IF(C19=0,E19,IF(C19=1,IF(COUNT(E15:E23)=0,"",TRIMMEAN(E15:E23,0.5)),IF(D19="","",D19)))) -> 65.798
A20: 46277.052 | B20: 60.6461 | C20: 0 | E20: =IF(OR(C20=9,B20=""),"",B20-$C$3) -> 60.6161 | F20: =IF(C20=9,"",IF(C20=0,E20,IF(C20=1,IF(COUNT(E16:E24)=0,"",TRIMMEAN(E16:E24,0.5)),IF(D20="","",D20)))) -> 60.6161
A21: 46277.062 | B21: 62.1162 | C21: 0 | E21: =IF(OR(C21=9,B21=""),"",B21-$C$3) -> 62.0862 | F21: =IF(C21=9,"",IF(C21=0,E21,IF(C21=1,IF(COUNT(E17:E25)=0,"",TRIMMEAN(E17:E25,0.5)),IF(D21="","",D21)))) -> 62.0862
A22: 46277.073 | B22: 59.6145 | C22: 0 | E22: =IF(OR(C22=9,B22=""),"",B22-$C$3) -> 59.5845 | F22: =IF(C22=9,"",IF(C22=0,E22,IF(C22=1,IF(COUNT(E18:E26)=0,"",TRIMMEAN(E18:E26,0.5)),IF(D22="","",D22)))) -> 59.5845
A23: 46277.083 | B23: 66.5809 | C23: 0 | E23: =IF(OR(C23=9,B23=""),"",B23-$C$3) -> 66.5509 | F23: =IF(C23=9,"",IF(C23=0,E23,IF(C23=1,IF(COUNT(E19:E27)=0,"",TRIMMEAN(E19:E27,0.5)),IF(D23="","",D23)))) -> 66.5509
A24: 46277.094 | B24: 59.1404 | C24: 0 | E24: =IF(OR(C24=9,B24=""),"",B24-$C$3) -> 59.1104 | F24: =IF(C24=9,"",IF(C24=0,E24,IF(C24=1,IF(COUNT(E20:E28)=0,"",TRIMMEAN(E20:E28,0.5)),IF(D24="","",D24)))) -> 59.1104
A25: 46277.104 | B25: 59.7624 | C25: 0 | E25: =IF(OR(C25=9,B25=""),"",B25-$C$3) -> 59.7324 | F25: =IF(C25=9,"",IF(C25=0,E25,IF(C25=1,IF(COUNT(E21:E29)=0,"",TRIMMEAN(E21:E29,0.5)),IF(D25="","",D25)))) -> 59.7324
A26: 46277.115 | B26: 65.3522 | C26: 0 | E26: =IF(OR(C26=9,B26=""),"",B26-$C$3) -> 65.3222 | F26: =IF(C26=9,"",IF(C26=0,E26,IF(C26=1,IF(COUNT(E22:E30)=0,"",TRIMMEAN(E22:E30,0.5)),IF(D26="","",D26)))) -> 65.3222
... A363: 46280.625 | B363: 58.8361 | C363: 0 | E363: =IF(OR(C363=9,B363=""),"",B363-$C$3) -> 58.8061 | F363: =IF(C363=9,"",IF(C363=0,E363,IF(C363=1,IF(COUNT(E359:E367)=0,"",TRIMMEAN(E359:E367,0.5)),IF(D363="","",D363)))) -> 58.8061
A364: 46280.635 | B364: 67.3933 | C364: 2 | D364: 59.3687 | E364: =IF(OR(C364=9,B364=""),"",B364-$C$3) -> 67.3633 | F364: =IF(C364=9,"",IF(C364=0,E364,IF(C364=1,IF(COUNT(E360:E368)=0,"",TRIMMEAN(E360:E368,0.5)),IF(D364="","",D364)))) -> 59.3687 | G364: pico aislado
A365: 46280.646 | B365: 59.9612 | C365: 0 | E365: =IF(OR(C365=9,B365=""),"",B365-$C$3) -> 59.9312 | F365: =IF(C365=9,"",IF(C365=0,E365,IF(C365=1,IF(COUNT(E361:E369)=0,"",TRIMMEAN(E361:E369,0.5)),IF(D365="","",D365)))) -> 59.9312
A366: 46280.656 | B366: 59.793 | C366: 0 | E366: =IF(OR(C366=9,B366=""),"",B366-$C$3) -> 59.763 | F366: =IF(C366=9,"",IF(C366=0,E366,IF(C366=1,IF(COUNT(E362:E370)=0,"",TRIMMEAN(E362:E370,0.5)),IF(D366="","",D366)))) -> 59.763
A367: 46280.667 | B367: 57.8368 | C367: 0 | E367: =IF(OR(C367=9,B367=""),"",B367-$C$3) -> 57.8068 | F367: =IF(C367=9,"",IF(C367=0,E367,IF(C367=1,IF(COUNT(E363:E371)=0,"",TRIMMEAN(E363:E371,0.5)),IF(D367="","",D367)))) -> 57.8068
A368: 46280.677 | B368: 61.0846 | C368: 0 | E368: =IF(OR(C368=9,B368=""),"",B368-$C$3) -> 61.0546 | F368: =IF(C368=9,"",IF(C368=0,E368,IF(C368=1,IF(COUNT(E364:E372)=0,"",TRIMMEAN(E364:E372,0.5)),IF(D368="","",D368)))) -> 61.0546
A369: 46280.688 | B369: 62.7009 | C369: 0 | E369: =IF(OR(C369=9,B369=""),"",B369-$C$3) -> 62.6709 | F369: =IF(C369=9,"",IF(C369=0,E369,IF(C369=1,IF(COUNT(E365:E373)=0,"",TRIMMEAN(E365:E373,0.5)),IF(D369="","",D369)))) -> 62.6709
A370: 46280.698 | B370: 63.4283 | C370: 0 | E370: =IF(OR(C370=9,B370=""),"",B370-$C$3) -> 63.3983 | F370: =IF(C370=9,"",IF(C370=0,E370,IF(C370=1,IF(COUNT(E366:E374)=0,"",TRIMMEAN(E366:E374,0.5)),IF(D370="","",D370)))) -> 63.3983
A371: 46280.708 | B371: 62.3236 | C371: 0 | E371: =IF(OR(C371=9,B371=""),"",B371-$C$3) -> 62.2936 | F371: =IF(C371=9,"",IF(C371=0,E371,IF(C371=1,IF(COUNT(E367:E375)=0,"",TRIMMEAN(E367:E375,0.5)),IF(D371="","",D371)))) -> 62.2936
A372: 46280.719 | B372: 62.5224 | C372: 0 | E372: =IF(OR(C372=9,B372=""),"",B372-$C$3) -> 62.4924 | F372: =IF(C372=9,"",IF(C372=0,E372,IF(C372=1,IF(COUNT(E368:E376)=0,"",TRIMMEAN(E368:E376,0.5)),IF(D372="","",D372)))) -> 62.4924
A373: 46280.729 | B373: 59.4412 | C373: 0 | E373: =IF(OR(C373=9,B373=""),"",B373-$C$3) -> 59.4112 | F373: =IF(C373=9,"",IF(C373=0,E373,IF(C373=1,IF(COUNT(E369:E377)=0,"",TRIMMEAN(E369:E377,0.5)),IF(D373="","",D373)))) -> 59.4112
A374: 46280.74 | B374: 60.8977 | C374: 0 | E374: =IF(OR(C374=9,B374=""),"",B374-$C$3) -> 60.8677 | F374: =IF(C374=9,"",IF(C374=0,E374,IF(C374=1,IF(COUNT(E370:E378)=0,"",TRIMMEAN(E370:E378,0.5)),IF(D374="","",D374)))) -> 60.8677
A375: 46280.75 | B375: 57.7043 | C375: 0 | E375: =IF(OR(C375=9,B375=""),"",B375-$C$3) -> 57.6743 | F375: =IF(C375=9,"",IF(C375=0,E375,IF(C375=1,IF(COUNT(E371:E379)=0,"",TRIMMEAN(E371:E379,0.5)),IF(D375="","",D375)))) -> 57.6743
A376: 46280.76 | B376: 65.1992 | C376: 0 | E376: =IF(OR(C376=9,B376=""),"",B376-$C$3) -> 65.1692 | F376: =IF(C376=9,"",IF(C376=0,E376,IF(C376=1,IF(COUNT(E372:E380)=0,"",TRIMMEAN(E372:E380,0.5)),IF(D376="","",D376)))) -> 65.1692
... A398: 46280.99 | B398: 60.3232 | C398: 0 | E398: =IF(OR(C398=9,B398=""),"",B398-$C$3) -> 60.2932 | F398: =IF(C398=9,"",IF(C398=0,E398,IF(C398=1,IF(COUNT(E394:E402)=0,"",TRIMMEAN(E394:E402,0.5)),IF(D398="","",D398)))) -> 60.2932
...

Sheet P5
A1: P5 · Presión (m) · VN3948890
A2: Válido (suavizado)
A3: Offset | C3: 0
A4: Ventana (lecturas a cada lado) | C4: 4
A6: Fecha y hora | B6: Dato inicial (m) | C6: Marca | D6: Reemplazo | E6: Corregido (m) | F6: Dato depurado (m) | G6: Motivo
A7: 46276.917 | B7: 43.6415 | C7: 1 | E7: =IF(OR(C7=9,B7=""),"",B7-$C$3) -> 43.6415 | F7: =IF(C7=9,"",IF(C7=0,E7,IF(C7=1,IF(COUNT(E7:E11)=0,"",TRIMMEAN(E7:E11,0.5)),IF(D7="","",D7)))) -> 45.4159 | G7: fuera de la ventana: solo para la media móvil del borde
A8: 46276.927 | B8: 46.5131 | C8: 1 | E8: =IF(OR(C8=9,B8=""),"",B8-$C$3) -> 46.5131 | F8: =IF(C8=9,"",IF(C8=0,E8,IF(C8=1,IF(COUNT(E7:E12)=0,"",TRIMMEAN(E7:E12,0.5)),IF(D8="","",D8)))) -> 46.060575 | G8: fuera de la ventana: solo para la media móvil del borde
A9: 46276.938 | B9: 50.9454 | C9: 1 | E9: =IF(OR(C9=9,B9=""),"",B9-$C$3) -> 50.9454 | F9: =IF(C9=9,"",IF(C9=0,E9,IF(C9=1,IF(COUNT(E7:E13)=0,"",TRIMMEAN(E7:E13,0.5)),IF(D9="","",D9)))) -> 46.12366 | G9: fuera de la ventana: solo para la media móvil del borde
A10: 46276.948 | B10: 44.5964 | C10: 1 | E10: =IF(OR(C10=9,B10=""),"",B10-$C$3) -> 44.5964 | F10: =IF(C10=9,"",IF(C10=0,E10,IF(C10=1,IF(COUNT(E7:E14)=0,"",TRIMMEAN(E7:E14,0.5)),IF(D10="","",D10)))) -> 45.655925 | G10: fuera de la ventana: solo para la media móvil del borde
A11: 46276.958 | B11: 45.1382 | C11: 1 | E11: =IF(OR(C11=9,B11=""),"",B11-$C$3) -> 45.1382 | F11: =IF(C11=9,"",IF(C11=0,E11,IF(C11=1,IF(COUNT(E7:E15)=0,"",TRIMMEAN(E7:E15,0.5)),IF(D11="","",D11)))) -> 46.12366 | G11: fuera de la ventana: solo para la media móvil del borde
A12: 46276.969 | B12: 47.9946 | C12: 1 | E12: =IF(OR(C12=9,B12=""),"",B12-$C$3) -> 47.9946 | F12: =IF(C12=9,"",IF(C12=0,E12,IF(C12=1,IF(COUNT(E8:E16)=0,"",TRIMMEAN(E8:E16,0.5)),IF(D12="","",D12)))) -> 47.39346 | G12: fuera de la ventana: solo para la media móvil del borde
A13: 46276.979 | B13: 46.376 | C13: 1 | E13: =IF(OR(C13=9,B13=""),"",B13-$C$3) -> 46.376 | F13: =IF(C13=9,"",IF(C13=0,E13,IF(C13=1,IF(COUNT(E9:E17)=0,"",TRIMMEAN(E9:E17,0.5)),IF(D13="","",D13)))) -> 47.01012 | G13: fuera de la ventana: solo para la media móvil del borde
A14: 46276.99 | B14: 44.3472 | C14: 1 | E14: =IF(OR(C14=9,B14=""),"",B14-$C$3) -> 44.3472 | F14: =IF(C14=9,"",IF(C14=0,E14,IF(C14=1,IF(COUNT(E10:E18)=0,"",TRIMMEAN(E10:E18,0.5)),IF(D14="","",D14)))) -> 46.59122 | G14: fuera de la ventana: solo para la media móvil del borde
A15: 46277 | B15: 57.9874 | C15: 1 | E15: =IF(OR(C15=9,B15=""),"",B15-$C$3) -> 57.9874 | F15: =IF(C15=9,"",IF(C15=0,E15,IF(C15=1,IF(COUNT(E11:E19)=0,"",TRIMMEAN(E11:E19,0.5)),IF(D15="","",D15)))) -> 46.54138 | G15: oscilación más rápida que el registro → media recortada de 2 h
A16: 46277.01 | B16: 57.0735 | C16: 1 | E16: =IF(OR(C16=9,B16=""),"",B16-$C$3) -> 57.0735 | F16: =IF(C16=9,"",IF(C16=0,E16,IF(C16=1,IF(COUNT(E12:E20)=0,"",TRIMMEAN(E12:E20,0.5)),IF(D16="","",D16)))) -> 46.35938 | G16: oscilación más rápida que el registro → media recortada de 2 h
A17: 46277.021 | B17: 42.3809 | C17: 1 | E17: =IF(OR(C17=9,B17=""),"",B17-$C$3) -> 42.3809 | F17: =IF(C17=9,"",IF(C17=0,E17,IF(C17=1,IF(COUNT(E13:E21)=0,"",TRIMMEAN(E13:E21,0.5)),IF(D17="","",D17)))) -> 45.62374 | G17: oscilación más rápida que el registro → media recortada de 2 h
A18: 46277.031 | B18: 48.8509 | C18: 1 | E18: =IF(OR(C18=9,B18=""),"",B18-$C$3) -> 48.8509 | F18: =IF(C18=9,"",IF(C18=0,E18,IF(C18=1,IF(COUNT(E14:E22)=0,"",TRIMMEAN(E14:E22,0.5)),IF(D18="","",D18)))) -> 45.94174 | G18: oscilación más rápida que el registro → media recortada de 2 h
A19: 46277.042 | B19: 44.2282 | C19: 1 | E19: =IF(OR(C19=9,B19=""),"",B19-$C$3) -> 44.2282 | F19: =IF(C19=9,"",IF(C19=0,E19,IF(C19=1,IF(COUNT(E15:E23)=0,"",TRIMMEAN(E15:E23,0.5)),IF(D19="","",D19)))) -> 45.91068 | G19: oscilación más rápida que el registro → media recortada de 2 h
A20: 46277.052 | B20: 43.3712 | C20: 1 | E20: =IF(OR(C20=9,B20=""),"",B20-$C$3) -> 43.3712 | F20: =IF(C20=9,"",IF(C20=0,E20,IF(C20=1,IF(COUNT(E16:E24)=0,"",TRIMMEAN(E16:E24,0.5)),IF(D20="","",D20)))) -> 45.91068 | G20: oscilación más rápida que el registro → media recortada de 2 h
A21: 46277.062 | B21: 44.3164 | C21: 1 | E21: =IF(OR(C21=9,B21=""),"",B21-$C$3) -> 44.3164 | F21: =IF(C21=9,"",IF(C21=0,E21,IF(C21=1,IF(COUNT(E17:E25)=0,"",TRIMMEAN(E17:E25,0.5)),IF(D21="","",D21)))) -> 45.07632 | G21: oscilación más rápida que el registro → media recortada de 2 h
A22: 46277.073 | B22: 47.966 | C22: 1 | E22: =IF(OR(C22=9,B22=""),"",B22-$C$3) -> 47.966 | F22: =IF(C22=9,"",IF(C22=0,E22,IF(C22=1,IF(COUNT(E18:E26)=0,"",TRIMMEAN(E18:E26,0.5)),IF(D22="","",D22)))) -> 45.07632 | G22: oscilación más rápida que el registro → media recortada de 2 h
... A402: 46281.031 | B402: 46.9756 | C402: 1 | E402: =IF(OR(C402=9,B402=""),"",B402-$C$3) -> 46.9756 | F402: =IF(C402=9,"",IF(C402=0,E402,IF(C402=1,IF(COUNT(E398:E406)=0,"",TRIMMEAN(E398:E406,0.5)),IF(D402="","",D402)))) -> 45.0104 | G402: fuera de la ventana: solo para la media móvil del borde
A403: 46281.042 | B403: 44.555 | C403: 1 | E403: =IF(OR(C403=9,B403=""),"",B403-$C$3) -> 44.555 | F403: =IF(C403=9,"",IF(C403=0,E403,IF(C403=1,IF(COUNT(E399:E406)=0,"",TRIMMEAN(E399:E406,0.5)),IF(D403="","",D403)))) -> 45.412225 | G403: fuera de la ventana: solo para la media móvil del borde
A404: 46281.052 | B404: 44.3825 | C404: 1 | E404: =IF(OR(C404=9,B404=""),"",B404-$C$3) -> 44.3825 | F404: =IF(C404=9,"",IF(C404=0,E404,IF(C404=1,IF(COUNT(E400:E406)=0,"",TRIMMEAN(E400:E406,0.5)),IF(D404="","",D404)))) -> 47.31402 | G404: fuera de la ventana: solo para la media móvil del borde
A405: 46281.062 | B405: 42.4364 | C405: 1 | E405: =IF(OR(C405=9,B405=""),"",B405-$C$3) -> 42.4364 | F405: =IF(C405=9,"",IF(C405=0,E405,IF(C405=1,IF(COUNT(E401:E406)=0,"",TRIMMEAN(E401:E406,0.5)),IF(D405="","",D405)))) -> 45.412225 | G405: fuera de la ventana: solo para la media móvil del borde
A406: 46281.073 | B406: 54.9212 | C406: 1 | E406: =IF(OR(C406=9,B406=""),"",B406-$C$3) -> 54.9212 | F406: =IF(C406=9,"",IF(C406=0,E406,IF(C406=1,IF(COUNT(E402:E406)=0,"",TRIMMEAN(E402:E406,0.5)),IF(D406="","",D406)))) -> 45.304367 | G406: fuera de la ventana: solo para la media móvil del borde

Sheet P6
A1: P6 · Presión (m) · VN3582511
A2: Válido
A3: Offset | C3: -0.24
A4: Ventana (lecturas a cada lado) | C4: 4
A6: Fecha y hora | B6: Dato inicial (m) | C6: Marca | D6: Reemplazo | E6: Corregido (m) | F6: Dato depurado (m) | G6: Motivo
A7: 46276.917 | B7: 41.6906 | C7: 0 | E7: =IF(OR(C7=9,B7=""),"",B7-$C$3) -> 41.9306 | F7: =IF(C7=9,"",IF(C7=0,E7,IF(C7=1,IF(COUNT(E7:E11)=0,"",TRIMMEAN(E7:E11,0.5)),IF(D7="","",D7)))) -> 41.9306 | G7: fuera de la ventana: solo para la media móvil del borde
A8: 46276.927 | B8: 41.662 | C8: 0 | E8: =IF(OR(C8=9,B8=""),"",B8-$C$3) -> 41.902 | F8: =IF(C8=9,"",IF(C8=0,E8,IF(C8=1,IF(COUNT(E7:E12)=0,"",TRIMMEAN(E7:E12,0.5)),IF(D8="","",D8)))) -> 41.902 | G8: fuera de la ventana: solo para la media móvil del borde
A9: 46276.938 | B9: 42.0492 | C9: 0 | E9: =IF(OR(C9=9,B9=""),"",B9-$C$3) -> 42.2892 | F9: =IF(C9=9,"",IF(C9=0,E9,IF(C9=1,IF(COUNT(E7:E13)=0,"",TRIMMEAN(E7:E13,0.5)),IF(D9="","",D9)))) -> 42.2892 | G9: fuera de la ventana: solo para la media móvil del borde
A10: 46276.948 | B10: 42.5283 | C10: 0 | E10: =IF(OR(C10=9,B10=""),"",B10-$C$3) -> 42.7683 | F10: =IF(C10=9,"",IF(C10=0,E10,IF(C10=1,IF(COUNT(E7:E14)=0,"",TRIMMEAN(E7:E14,0.5)),IF(D10="","",D10)))) -> 42.7683 | G10: fuera de la ventana: solo para la media móvil del borde
A11: 46276.958 | B11: 42.2466 | C11: 0 | E11: =IF(OR(C11=9,B11=""),"",B11-$C$3) -> 42.4866 | F11: =IF(C11=9,"",IF(C11=0,E11,IF(C11=1,IF(COUNT(E7:E15)=0,"",TRIMMEAN(E7:E15,0.5)),IF(D11="","",D11)))) -> 42.4866 | G11: fuera de la ventana: solo para la media móvil del borde
A12: 46276.969 | B12: 41.7322 | C12: 0 | E12: =IF(OR(C12=9,B12=""),"",B12-$C$3) -> 41.9722 | F12: =IF(C12=9,"",IF(C12=0,E12,IF(C12=1,IF(COUNT(E8:E16)=0,"",TRIMMEAN(E8:E16,0.5)),IF(D12="","",D12)))) -> 41.9722 | G12: fuera de la ventana: solo para la media móvil del borde
A13: 46276.979 | B13: 42.0674 | C13: 0 | E13: =IF(OR(C13=9,B13=""),"",B13-$C$3) -> 42.3074 | F13: =IF(C13=9,"",IF(C13=0,E13,IF(C13=1,IF(COUNT(E9:E17)=0,"",TRIMMEAN(E9:E17,0.5)),IF(D13="","",D13)))) -> 42.3074 | G13: fuera de la ventana: solo para la media móvil del borde
A14: 46276.99 | B14: 41.8787 | C14: 0 | E14: =IF(OR(C14=9,B14=""),"",B14-$C$3) -> 42.1187 | F14: =IF(C14=9,"",IF(C14=0,E14,IF(C14=1,IF(COUNT(E10:E18)=0,"",TRIMMEAN(E10:E18,0.5)),IF(D14="","",D14)))) -> 42.1187 | G14: fuera de la ventana: solo para la media móvil del borde
A15: 46277 | B15: 42.225 | C15: 0 | E15: =IF(OR(C15=9,B15=""),"",B15-$C$3) -> 42.465 | F15: =IF(C15=9,"",IF(C15=0,E15,IF(C15=1,IF(COUNT(E11:E19)=0,"",TRIMMEAN(E11:E19,0.5)),IF(D15="","",D15)))) -> 42.465
A16: 46277.01 | B16: 42.5059 | C16: 0 | E16: =IF(OR(C16=9,B16=""),"",B16-$C$3) -> 42.7459 | F16: =IF(C16=9,"",IF(C16=0,E16,IF(C16=1,IF(COUNT(E12:E20)=0,"",TRIMMEAN(E12:E20,0.5)),IF(D16="","",D16)))) -> 42.7459
A17: 46277.021 | B17: 42.3385 | C17: 0 | E17: =IF(OR(C17=9,B17=""),"",B17-$C$3) -> 42.5785 | F17: =IF(C17=9,"",IF(C17=0,E17,IF(C17=1,IF(COUNT(E13:E21)=0,"",TRIMMEAN(E13:E21,0.5)),IF(D17="","",D17)))) -> 42.5785
A18: 46277.031 | B18: 42.6503 | C18: 0 | E18: =IF(OR(C18=9,B18=""),"",B18-$C$3) -> 42.8903 | F18: =IF(C18=9,"",IF(C18=0,E18,IF(C18=1,IF(COUNT(E14:E22)=0,"",TRIMMEAN(E14:E22,0.5)),IF(D18="","",D18)))) -> 42.8903
A19: 46277.042 | B19: 42.4458 | C19: 0 | E19: =IF(OR(C19=9,B19=""),"",B19-$C$3) -> 42.6858 | F19: =IF(C19=9,"",IF(C19=0,E19,IF(C19=1,IF(COUNT(E15:E23)=0,"",TRIMMEAN(E15:E23,0.5)),IF(D19="","",D19)))) -> 42.6858
A20: 46277.052 | B20: 42.5397 | C20: 0 | E20: =IF(OR(C20=9,B20=""),"",B20-$C$3) -> 42.7797 | F20: =IF(C20=9,"",IF(C20=0,E20,IF(C20=1,IF(COUNT(E16:E24)=0,"",TRIMMEAN(E16:E24,0.5)),IF(D20="","",D20)))) -> 42.7797
A21: 46277.062 | B21: 42.566 | C21: 0 | E21: =IF(OR(C21=9,B21=""),"",B21-$C$3) -> 42.806 | F21: =IF(C21=9,"",IF(C21=0,E21,IF(C21=1,IF(COUNT(E17:E25)=0,"",TRIMMEAN(E17:E25,0.5)),IF(D21="","",D21)))) -> 42.806
A22: 46277.073 | B22: 42.7249 | C22: 0 | E22: =IF(OR(C22=9,B22=""),"",B22-$C$3) -> 42.9649 | F22: =IF(C22=9,"",IF(C22=0,E22,IF(C22=1,IF(COUNT(E18:E26)=0,"",TRIMMEAN(E18:E26,0.5)),IF(D22="","",D22)))) -> 42.9649
A23: 46277.083 | B23: 42.8553 | C23: 0 | E23: =IF(OR(C23=9,B23=""),"",B23-$C$3) -> 43.0953 | F23: =IF(C23=9,"",IF(C23=0,E23,IF(C23=1,IF(COUNT(E19:E27)=0,"",TRIMMEAN(E19:E27,0.5)),IF(D23="","",D23)))) -> 43.0953
A24: 46277.094 | B24: 42.7189 | C24: 0 | E24: =IF(OR(C24=9,B24=""),"",B24-$C$3) -> 42.9589 | F24: =IF(C24=9,"",IF(C24=0,E24,IF(C24=1,IF(COUNT(E20:E28)=0,"",TRIMMEAN(E20:E28,0.5)),IF(D24="","",D24)))) -> 42.9589
A25: 46277.104 | B25: 42.5914 | C25: 0 | E25: =IF(OR(C25=9,B25=""),"",B25-$C$3) -> 42.8314 | F25: =IF(C25=9,"",IF(C25=0,E25,IF(C25=1,IF(COUNT(E21:E29)=0,"",TRIMMEAN(E21:E29,0.5)),IF(D25="","",D25)))) -> 42.8314
A26: 46277.115 | B26: 42.7363 | C26: 0 | E26: =IF(OR(C26=9,B26=""),"",B26-$C$3) -> 42.9763 | F26: =IF(C26=9,"",IF(C26=0,E26,IF(C26=1,IF(COUNT(E22:E30)=0,"",TRIMMEAN(E22:E30,0.5)),IF(D26="","",D26)))) -> 42.9763
... A398: 46280.99 | B398: 42.8998 | C398: 0 | E398: =IF(OR(C398=9,B398=""),"",B398-$C$3) -> 43.1398 | F398: =IF(C398=9,"",IF(C398=0,E398,IF(C398=1,IF(COUNT(E394:E402)=0,"",TRIMMEAN(E394:E402,0.5)),IF(D398="","",D398)))) -> 43.1398
A399: 46281 | B399: 42.7665 | C399: 0 | E399: =IF(OR(C399=9,B399=""),"",B399-$C$3) -> 43.0065 | F399: =IF(C399=9,"",IF(C399=0,E399,IF(C399=1,IF(COUNT(E395:E403)=0,"",TRIMMEAN(E395:E403,0.5)),IF(D399="","",D399)))) -> 43.0065 | G399: fuera de la ventana: solo para la media móvil del borde
A400: 46281.01 | B400: 42.4707 | C400: 0 | E400: =IF(OR(C400=9,B400=""),"",B400-$C$3) -> 42.7107 | F400: =IF(C400=9,"",IF(C400=0,E400,IF(C400=1,IF(COUNT(E396:E404)=0,"",TRIMMEAN(E396:E404,0.5)),IF(D400="","",D400)))) -> 42.7107 | G400: fuera de la ventana: solo para la media móvil del borde
A401: 46281.021 | B401: 42.8197 | C401: 0 | E401: =IF(OR(C401=9,B401=""),"",B401-$C$3) -> 43.0597 | F401: =IF(C401=9,"",IF(C401=0,E401,IF(C401=1,IF(COUNT(E397:E405)=0,"",TRIMMEAN(E397:E405,0.5)),IF(D401="","",D401)))) -> 43.0597 | G401: fuera de la ventana: solo para la media móvil del borde
A402: 46281.031 | B402: 42.2229 | C402: 0 | E402: =IF(OR(C402=9,B402=""),"",B402-$C$3) -> 42.4629 | F402: =IF(C402=9,"",IF(C402=0,E402,IF(C402=1,IF(COUNT(E398:E406)=0,"",TRIMMEAN(E398:E406,0.5)),IF(D402="","",D402)))) -> 42.4629 | G402: fuera de la ventana: solo para la media móvil del borde
A403: 46281.042 | B403: 42.4877 | C403: 0 | E403: =IF(OR(C403=9,B403=""),"",B403-$C$3) -> 42.7277 | F403: =IF(C403=9,"",IF(C403=0,E403,IF(C403=1,IF(COUNT(E399:E406)=0,"",TRIMMEAN(E399:E406,0.5)),IF(D403="","",D403)))) -> 42.7277 | G403: fuera de la ventana: solo para la media móvil del borde
A404: 46281.052 | B404: 42.3192 | C404: 0 | E404: =IF(OR(C404=9,B404=""),"",B404-$C$3) -> 42.5592 | F404: =IF(C404=9,"",IF(C404=0,E404,IF(C404=1,IF(COUNT(E400:E406)=0,"",TRIMMEAN(E400:E406,0.5)),IF(D404="","",D404)))) -> 42.5592 | G404: fuera de la ventana: solo para la media móvil del borde
A405: 46281.062 | B405: 41.773 | C405: 0 | E405: =IF(OR(C405=9,B405=""),"",B405-$C$3) -> 42.013 | F405: =IF(C405=9,"",IF(C405=0,E405,IF(C405=1,IF(COUNT(E401:E406)=0,"",TRIMMEAN(E401:E406,0.5)),IF(D405="","",D405)))) -> 42.013 | G405: fuera de la ventana: solo para la media móvil del borde
A406: 46281.073 | B406: 41.6951 | C406: 0 | E406: =IF(OR(C406=9,B406=""),"",B406-$C$3) -> 41.9351 | F406: =IF(C406=9,"",IF(C406=0,E406,IF(C406=1,IF(COUNT(E402:E406)=0,"",TRIMMEAN(E402:E406,0.5)),IF(D406="","",D406)))) -> 41.9351 | G406: fuera de la ventana: solo para la media móvil del borde

Sheet P7
A1: P7 · Presión (m) · VN3751475
A2: Válido
A3: Offset | C3: 0.03
A4: Ventana (lecturas a cada lado) | C4: 4
A6: Fecha y hora | B6: Dato inicial (m) | C6: Marca | D6: Reemplazo | E6: Corregido (m) | F6: Dato depurado (m) | G6: Motivo
A7: 46276.917 | B7: 86.345 | C7: 0 | E7: =IF(OR(C7=9,B7=""),"",B7-$C$3) -> 86.315 | F7: =IF(C7=9,"",IF(C7=0,E7,IF(C7=1,IF(COUNT(E7:E11)=0,"",TRIMMEAN(E7:E11,0.5)),IF(D7="","",D7)))) -> 86.315 | G7: fuera de la ventana: solo para la media móvil del borde
A8: 46276.927 | B8: 86.4078 | C8: 0 | E8: =IF(OR(C8=9,B8=""),"",B8-$C$3) -> 86.3778 | F8: =IF(C8=9,"",IF(C8=0,E8,IF(C8=1,IF(COUNT(E7:E12)=0,"",TRIMMEAN(E7:E12,0.5)),IF(D8="","",D8)))) -> 86.3778 | G8: fuera de la ventana: solo para la media móvil del borde
A9: 46276.938 | B9: 86.5506 | C9: 0 | E9: =IF(OR(C9=9,B9=""),"",B9-$C$3) -> 86.5206 | F9: =IF(C9=9,"",IF(C9=0,E9,IF(C9=1,IF(COUNT(E7:E13)=0,"",TRIMMEAN(E7:E13,0.5)),IF(D9="","",D9)))) -> 86.5206 | G9: fuera de la ventana: solo para la media móvil del borde
A10: 46276.948 | B10: 86.2271 | C10: 0 | E10: =IF(OR(C10=9,B10=""),"",B10-$C$3) -> 86.1971 | F10: =IF(C10=9,"",IF(C10=0,E10,IF(C10=1,IF(COUNT(E7:E14)=0,"",TRIMMEAN(E7:E14,0.5)),IF(D10="","",D10)))) -> 86.1971 | G10: fuera de la ventana: solo para la media móvil del borde
A11: 46276.958 | B11: 86.2239 | C11: 0 | E11: =IF(OR(C11=9,B11=""),"",B11-$C$3) -> 86.1939 | F11: =IF(C11=9,"",IF(C11=0,E11,IF(C11=1,IF(COUNT(E7:E15)=0,"",TRIMMEAN(E7:E15,0.5)),IF(D11="","",D11)))) -> 86.1939 | G11: fuera de la ventana: solo para la media móvil del borde
A12: 46276.969 | B12: 86.3332 | C12: 0 | E12: =IF(OR(C12=9,B12=""),"",B12-$C$3) -> 86.3032 | F12: =IF(C12=9,"",IF(C12=0,E12,IF(C12=1,IF(COUNT(E8:E16)=0,"",TRIMMEAN(E8:E16,0.5)),IF(D12="","",D12)))) -> 86.3032 | G12: fuera de la ventana: solo para la media móvil del borde
A13: 46276.979 | B13: 86.8394 | C13: 0 | E13: =IF(OR(C13=9,B13=""),"",B13-$C$3) -> 86.8094 | F13: =IF(C13=9,"",IF(C13=0,E13,IF(C13=1,IF(COUNT(E9:E17)=0,"",TRIMMEAN(E9:E17,0.5)),IF(D13="","",D13)))) -> 86.8094 | G13: fuera de la ventana: solo para la media móvil del borde
A14: 46276.99 | B14: 86.5322 | C14: 0 | E14: =IF(OR(C14=9,B14=""),"",B14-$C$3) -> 86.5022 | F14: =IF(C14=9,"",IF(C14=0,E14,IF(C14=1,IF(COUNT(E10:E18)=0,"",TRIMMEAN(E10:E18,0.5)),IF(D14="","",D14)))) -> 86.5022 | G14: fuera de la ventana: solo para la media móvil del borde
A15: 46277 | B15: 87.3097 | C15: 0 | E15: =IF(OR(C15=9,B15=""),"",B15-$C$3) -> 87.2797 | F15: =IF(C15=9,"",IF(C15=0,E15,IF(C15=1,IF(COUNT(E11:E19)=0,"",TRIMMEAN(E11:E19,0.5)),IF(D15="","",D15)))) -> 87.2797
A16: 46277.01 | B16: 87.0694 | C16: 0 | E16: =IF(OR(C16=9,B16=""),"",B16-$C$3) -> 87.0394 | F16: =IF(C16=9,"",IF(C16=0,E16,IF(C16=1,IF(COUNT(E12:E20)=0,"",TRIMMEAN(E12:E20,0.5)),IF(D16="","",D16)))) -> 87.0394
A17: 46277.021 | B17: 87.1848 | C17: 0 | E17: =IF(OR(C17=9,B17=""),"",B17-$C$3) -> 87.1548 | F17: =IF(C17=9,"",IF(C17=0,E17,IF(C17=1,IF(COUNT(E13:E21)=0,"",TRIMMEAN(E13:E21,0.5)),IF(D17="","",D17)))) -> 87.1548
A18: 46277.031 | B18: 86.8222 | C18: 0 | E18: =IF(OR(C18=9,B18=""),"",B18-$C$3) -> 86.7922 | F18: =IF(C18=9,"",IF(C18=0,E18,IF(C18=1,IF(COUNT(E14:E22)=0,"",TRIMMEAN(E14:E22,0.5)),IF(D18="","",D18)))) -> 86.7922
A19: 46277.042 | B19: 86.1496 | C19: 0 | E19: =IF(OR(C19=9,B19=""),"",B19-$C$3) -> 86.1196 | F19: =IF(C19=9,"",IF(C19=0,E19,IF(C19=1,IF(COUNT(E15:E23)=0,"",TRIMMEAN(E15:E23,0.5)),IF(D19="","",D19)))) -> 86.1196
A20: 46277.052 | B20: 86.7117 | C20: 0 | E20: =IF(OR(C20=9,B20=""),"",B20-$C$3) -> 86.6817 | F20: =IF(C20=9,"",IF(C20=0,E20,IF(C20=1,IF(COUNT(E16:E24)=0,"",TRIMMEAN(E16:E24,0.5)),IF(D20="","",D20)))) -> 86.6817
A21: 46277.062 | B21: 86.9209 | C21: 0 | E21: =IF(OR(C21=9,B21=""),"",B21-$C$3) -> 86.8909 | F21: =IF(C21=9,"",IF(C21=0,E21,IF(C21=1,IF(COUNT(E17:E25)=0,"",TRIMMEAN(E17:E25,0.5)),IF(D21="","",D21)))) -> 86.8909
A22: 46277.073 | B22: 86.9087 | C22: 0 | E22: =IF(OR(C22=9,B22=""),"",B22-$C$3) -> 86.8787 | F22: =IF(C22=9,"",IF(C22=0,E22,IF(C22=1,IF(COUNT(E18:E26)=0,"",TRIMMEAN(E18:E26,0.5)),IF(D22="","",D22)))) -> 86.8787
A23: 46277.083 | B23: 86.8577 | C23: 0 | E23: =IF(OR(C23=9,B23=""),"",B23-$C$3) -> 86.8277 | F23: =IF(C23=9,"",IF(C23=0,E23,IF(C23=1,IF(COUNT(E19:E27)=0,"",TRIMMEAN(E19:E27,0.5)),IF(D23="","",D23)))) -> 86.8277
A24: 46277.094 | B24: 86.8606 | C24: 0 | E24: =IF(OR(C24=9,B24=""),"",B24-$C$3) -> 86.8306 | F24: =IF(C24=9,"",IF(C24=0,E24,IF(C24=1,IF(COUNT(E20:E28)=0,"",TRIMMEAN(E20:E28,0.5)),IF(D24="","",D24)))) -> 86.8306
A25: 46277.104 | B25: 87.0413 | C25: 0 | E25: =IF(OR(C25=9,B25=""),"",B25-$C$3) -> 87.0113 | F25: =IF(C25=9,"",IF(C25=0,E25,IF(C25=1,IF(COUNT(E21:E29)=0,"",TRIMMEAN(E21:E29,0.5)),IF(D25="","",D25)))) -> 87.0113
A26: 46277.115 | B26: 87.1082 | C26: 0 | E26: =IF(OR(C26=9,B26=""),"",B26-$C$3) -> 87.0782 | F26: =IF(C26=9,"",IF(C26=0,E26,IF(C26=1,IF(COUNT(E22:E30)=0,"",TRIMMEAN(E22:E30,0.5)),IF(D26="","",D26)))) -> 87.0782
... A398: 46280.99 | B398: 86.8932 | C398: 0 | E398: =IF(OR(C398=9,B398=""),"",B398-$C$3) -> 86.8632 | F398: =IF(C398=9,"",IF(C398=0,E398,IF(C398=1,IF(COUNT(E394:E402)=0,"",TRIMMEAN(E394:E402,0.5)),IF(D398="","",D398)))) -> 86.8632
A399: 46281 | B399: 86.4188 | C399: 0 | E399: =IF(OR(C399=9,B399=""),"",B399-$C$3) -> 86.3888 | F399: =IF(C399=9,"",IF(C399=0,E399,IF(C399=1,IF(COUNT(E395:E403)=0,"",TRIMMEAN(E395:E403,0.5)),IF(D399="","",D399)))) -> 86.3888 | G399: fuera de la ventana: solo para la media móvil del borde
A400: 46281.01 | B400: 86.3177 | C400: 0 | E400: =IF(OR(C400=9,B400=""),"",B400-$C$3) -> 86.2877 | F400: =IF(C400=9,"",IF(C400=0,E400,IF(C400=1,IF(COUNT(E396:E404)=0,"",TRIMMEAN(E396:E404,0.5)),IF(D400="","",D400)))) -> 86.2877 | G400: fuera de la ventana: solo para la media móvil del borde
A401: 46281.021 | B401: 86.7504 | C401: 0 | E401: =IF(OR(C401=9,B401=""),"",B401-$C$3) -> 86.7204 | F401: =IF(C401=9,"",IF(C401=0,E401,IF(C401=1,IF(COUNT(E397:E405)=0,"",TRIMMEAN(E397:E405,0.5)),IF(D401="","",D401)))) -> 86.7204 | G401: fuera de la ventana: solo para la media móvil del borde
A402: 46281.031 | B402: 86.8528 | C402: 0 | E402: =IF(OR(C402=9,B402=""),"",B402-$C$3) -> 86.8228 | F402: =IF(C402=9,"",IF(C402=0,E402,IF(C402=1,IF(COUNT(E398:E406)=0,"",TRIMMEAN(E398:E406,0.5)),IF(D402="","",D402)))) -> 86.8228 | G402: fuera de la ventana: solo para la media móvil del borde
A403: 46281.042 | B403: 86.3197 | C403: 0 | E403: =IF(OR(C403=9,B403=""),"",B403-$C$3) -> 86.2897 | F403: =IF(C403=9,"",IF(C403=0,E403,IF(C403=1,IF(COUNT(E399:E406)=0,"",TRIMMEAN(E399:E406,0.5)),IF(D403="","",D403)))) -> 86.2897 | G403: fuera de la ventana: solo para la media móvil del borde
A404: 46281.052 | B404: 87.2452 | C404: 0 | E404: =IF(OR(C404=9,B404=""),"",B404-$C$3) -> 87.2152 | F404: =IF(C404=9,"",IF(C404=0,E404,IF(C404=1,IF(COUNT(E400:E406)=0,"",TRIMMEAN(E400:E406,0.5)),IF(D404="","",D404)))) -> 87.2152 | G404: fuera de la ventana: solo para la media móvil del borde
A405: 46281.062 | B405: 87.0792 | C405: 0 | E405: =IF(OR(C405=9,B405=""),"",B405-$C$3) -> 87.0492 | F405: =IF(C405=9,"",IF(C405=0,E405,IF(C405=1,IF(COUNT(E401:E406)=0,"",TRIMMEAN(E401:E406,0.5)),IF(D405="","",D405)))) -> 87.0492 | G405: fuera de la ventana: solo para la media móvil del borde
A406: 46281.073 | B406: 86.6689 | C406: 0 | E406: =IF(OR(C406=9,B406=""),"",B406-$C$3) -> 86.6389 | F406: =IF(C406=9,"",IF(C406=0,E406,IF(C406=1,IF(COUNT(E402:E406)=0,"",TRIMMEAN(E402:E406,0.5)),IF(D406="","",D406)))) -> 86.6389 | G406: fuera de la ventana: solo para la media móvil del borde

Sheet P8
A1: P8 · Presión (m) · VN3950311
A2: Válido (suavizado)
A3: Offset | C3: -0.28
A4: Ventana (lecturas a cada lado) | C4: 4
A6: Fecha y hora | B6: Dato inicial (m) | C6: Marca | D6: Reemplazo | E6: Corregido (m) | F6: Dato depurado (m) | G6: Motivo
A7: 46276.917 | B7: 63.8651 | C7: 0 | E7: =IF(OR(C7=9,B7=""),"",B7-$C$3) -> 64.1451 | F7: =IF(C7=9,"",IF(C7=0,E7,IF(C7=1,IF(COUNT(E7:E11)=0,"",TRIMMEAN(E7:E11,0.5)),IF(D7="","",D7)))) -> 64.1451 | G7: fuera de la ventana: solo para la media móvil del borde
A8: 46276.927 | B8: 63.8717 | C8: 0 | E8: =IF(OR(C8=9,B8=""),"",B8-$C$3) -> 64.1517 | F8: =IF(C8=9,"",IF(C8=0,E8,IF(C8=1,IF(COUNT(E7:E12)=0,"",TRIMMEAN(E7:E12,0.5)),IF(D8="","",D8)))) -> 64.1517 | G8: fuera de la ventana: solo para la media móvil del borde
A9: 46276.938 | B9: 64.356 | C9: 0 | E9: =IF(OR(C9=9,B9=""),"",B9-$C$3) -> 64.636 | F9: =IF(C9=9,"",IF(C9=0,E9,IF(C9=1,IF(COUNT(E7:E13)=0,"",TRIMMEAN(E7:E13,0.5)),IF(D9="","",D9)))) -> 64.636 | G9: fuera de la ventana: solo para la media móvil del borde
A10: 46276.948 | B10: 63.7072 | C10: 0 | E10: =IF(OR(C10=9,B10=""),"",B10-$C$3) -> 63.9872 | F10: =IF(C10=9,"",IF(C10=0,E10,IF(C10=1,IF(COUNT(E7:E14)=0,"",TRIMMEAN(E7:E14,0.5)),IF(D10="","",D10)))) -> 63.9872 | G10: fuera de la ventana: solo para la media móvil del borde
A11: 46276.958 | B11: 63.5211 | C11: 0 | E11: =IF(OR(C11=9,B11=""),"",B11-$C$3) -> 63.8011 | F11: =IF(C11=9,"",IF(C11=0,E11,IF(C11=1,IF(COUNT(E7:E15)=0,"",TRIMMEAN(E7:E15,0.5)),IF(D11="","",D11)))) -> 63.8011 | G11: fuera de la ventana: solo para la media móvil del borde
A12: 46276.969 | B12: 76.3326 | C12: 2 | D12: 62.0315 | E12: =IF(OR(C12=9,B12=""),"",B12-$C$3) -> 76.6126 | F12: =IF(C12=9,"",IF(C12=0,E12,IF(C12=1,IF(COUNT(E8:E16)=0,"",TRIMMEAN(E8:E16,0.5)),IF(D12="","",D12)))) -> 62.0315 | G12: fuera de la ventana: solo para la media móvil del borde
A13: 46276.979 | B13: 59.9818 | C13: 0 | E13: =IF(OR(C13=9,B13=""),"",B13-$C$3) -> 60.2618 | F13: =IF(C13=9,"",IF(C13=0,E13,IF(C13=1,IF(COUNT(E9:E17)=0,"",TRIMMEAN(E9:E17,0.5)),IF(D13="","",D13)))) -> 60.2618 | G13: fuera de la ventana: solo para la media móvil del borde
A14: 46276.99 | B14: 43.0811 | C14: 2 | D14: 60.0301 | E14: =IF(OR(C14=9,B14=""),"",B14-$C$3) -> 43.3611 | F14: =IF(C14=9,"",IF(C14=0,E14,IF(C14=1,IF(COUNT(E10:E18)=0,"",TRIMMEAN(E10:E18,0.5)),IF(D14="","",D14)))) -> 60.0301 | G14: fuera de la ventana: solo para la media móvil del borde
A15: 46277 | B15: 66.0153 | C15: 1 | E15: =IF(OR(C15=9,B15=""),"",B15-$C$3) -> 66.2953 | F15: =IF(C15=9,"",IF(C15=0,E15,IF(C15=1,IF(COUNT(E11:E19)=0,"",TRIMMEAN(E11:E19,0.5)),IF(D15="","",D15)))) -> 59.79838 | G15: oscilación más rápida que el registro → media recortada de 2 h
A16: 46277.01 | B16: 43.2735 | C16: 1 | E16: =IF(OR(C16=9,B16=""),"",B16-$C$3) -> 43.5535 | F16: =IF(C16=9,"",IF(C16=0,E16,IF(C16=1,IF(COUNT(E12:E20)=0,"",TRIMMEAN(E12:E20,0.5)),IF(D16="","",D16)))) -> 60.03808 | G16: oscilación más rápida que el registro → media recortada de 2 h
A17: 46277.021 | B17: 43.5741 | C17: 1 | E17: =IF(OR(C17=9,B17=""),"",B17-$C$3) -> 43.8541 | F17: =IF(C17=9,"",IF(C17=0,E17,IF(C17=1,IF(COUNT(E13:E21)=0,"",TRIMMEAN(E13:E21,0.5)),IF(D17="","",D17)))) -> 60.03808 | G17: oscilación más rápida que el registro → media recortada de 2 h
A18: 46277.031 | B18: 84.167 | C18: 1 | E18: =IF(OR(C18=9,B18=""),"",B18-$C$3) -> 84.447 | F18: =IF(C18=9,"",IF(C18=0,E18,IF(C18=1,IF(COUNT(E14:E22)=0,"",TRIMMEAN(E14:E22,0.5)),IF(D18="","",D18)))) -> 61.1626 | G18: oscilación más rápida que el registro → media recortada de 2 h
A19: 46277.042 | B19: 64.4996 | C19: 1 | E19: =IF(OR(C19=9,B19=""),"",B19-$C$3) -> 64.7796 | F19: =IF(C19=9,"",IF(C19=0,E19,IF(C19=1,IF(COUNT(E15:E23)=0,"",TRIMMEAN(E15:E23,0.5)),IF(D19="","",D19)))) -> 63.57198 | G19: oscilación más rápida que el registro → media recortada de 2 h
A20: 46277.052 | B20: 64.7196 | C20: 1 | E20: =IF(OR(C20=9,B20=""),"",B20-$C$3) -> 64.9996 | F20: =IF(C20=9,"",IF(C20=0,E20,IF(C20=1,IF(COUNT(E16:E24)=0,"",TRIMMEAN(E16:E24,0.5)),IF(D20="","",D20)))) -> 63.6949 | G20: oscilación más rápida que el registro → media recortada de 2 h
A21: 46277.062 | B21: 68.307 | C21: 1 | E21: =IF(OR(C21=9,B21=""),"",B21-$C$3) -> 68.587 | F21: =IF(C21=9,"",IF(C21=0,E21,IF(C21=1,IF(COUNT(E17:E25)=0,"",TRIMMEAN(E17:E25,0.5)),IF(D21="","",D21)))) -> 66.2321 | G21: oscilación más rápida que el registro → media recortada de 2 h
A22: 46277.073 | B22: 65.6044 | C22: 1 | E22: =IF(OR(C22=9,B22=""),"",B22-$C$3) -> 65.8844 | F22: =IF(C22=9,"",IF(C22=0,E22,IF(C22=1,IF(COUNT(E18:E26)=0,"",TRIMMEAN(E18:E26,0.5)),IF(D22="","",D22)))) -> 66.2321 | G22: oscilación más rápida que el registro → media recortada de 2 h
