Workbook

Sheet Resumen
A1: Datos depurados · ZP_05
A2: Periodo de calibración propuesto: 12/09 00:00 – 16/09 00:00. Dato depurado = fórmula sobre el dato inicial (ver leyenda).
A4: Sensor | B4: Tipo | C4: Unidad | D4: Elemento INP | E4: Offset | F4: Uso recomendado | G4: Hoja
A5: P1 | B5: Presión | C5: m | D5: VN3948790 | E5: ='P1'!$C$3 | F5: Usar solo la media horaria (tolerancia mayor) | G5: P1
A6: P2 | B6: Presión | C6: m | D6: VN3942278 | E6: ='P2'!$C$3 | F6: Válido | G6: P2
A7: P3 | B7: Presión | C7: m | D7: VN3943135 | E7: ='P3'!$C$3 | F7: Válido (suavizado) | G7: P3
A8: P4 | B8: Presión | C8: m | D8: VN3950683 | E8: ='P4'!$C$3 | F8: Válido | G8: P4
A9: P5 | B9: Presión | C9: m | D9: VN3948890 | E9: ='P5'!$C$3 | F9: Válido (suavizado) | G9: P5
A10: P6 | B10: Presión | C10: m | D10: VN3582511 | E10: ='P6'!$C$3 | F10: Válido | G10: P6
A11: P7 | B11: Presión | C11: m | D11: VN3751475 | E11: ='P7'!$C$3 | F11: Válido | G11: P7
A12: P8 | B12: Presión | C12: m | D12: VN3950311 | E12: ='P8'!$C$3 | F12: Válido (suavizado) | G12: P8
A13: P9 | B13: Presión | C13: m | D13: VN3948722 | E13: ='P9'!$C$3 | F13: Válido | G13: P9
A14: P10 | B14: Presión | C14: m | D14: VN3745765 | E14: ='P10'!$C$3 | F14: Válido | G14: P10
A15: P11 | B15: Presión | C15: m | D15: 3949453 | E15: ='P11'!$C$3 | F15: Usar solo la media horaria (tolerancia mayor) | G15: P11
A16: L1 | B16: Presión | C16: m | D16: VN3948124 | E16: ='L1'!$C$3 | F16: Válido (suavizado) | G16: L1
A17: L2 | B17: Presión | C17: m | D17: 3949344_n2a_2 | E17: ='L2'!$C$3 | F17: Válido (suavizado) | G17: L2
A18: L3 | B18: Presión | C18: m | D18: 3949333_n2a_1 | E18: ='L3'!$C$3 | F18: Válido (suavizado) | G18: L3
A19: Q1 | B19: Caudal | C19: L/s | D19: 3950155 | E19: ='Q1'!$C$3 | F19: Válido | G19: Q1
A20: Q2 | B20: Caudal | C20: L/s | D20: 3950006 | E20: ='Q2'!$C$3 | F20: Válido | G20: Q2
A21: Q3 | B21: Caudal | C21: L/s | D21: 3949916 | E21: ='Q3'!$C$3 | F21: Válido | G21: Q3
A22: Q4 | B22: Caudal | C22: L/s | D22: 3926415 | E22: ='Q4'!$C$3 | F22: Válido | G22: Q4
A23: N_Meneses | B23: Nivel | C23: m | D23: 3949680 | E23: ='N_Meneses'!$C$3 | F23: Usar solo la media horaria (tolerancia mayor) | G23: N_Meneses
A24: N_Durazno | B24: Nivel | C24: m | D24: 3949679 | E24: ='N_Durazno'!$C$3 | F24: No usar como meta | G24: N_Durazno
A26: Leyenda de la columna «Marca»
A27: 0 | B27: válido | C27: Dato depurado = corregido = dato inicial − offset
A28: 1 | B28: envolvente | C28: Oscilación más rápida que el registro: MEDIA.ACOTADA (TRIMMEAN, 50 %) del dato corregido en la ventana de la hoja (±4 lecturas = 2 h, o ±8 = 4 h)
A29: 2 | B29: interpolado | C29: Pico aislado o hueco ≤ 1 h: interpolación lineal (valor en «Reemplazo»)
A30: 3 | B30: perfil típico | C30: Hueco de 1 a 6 h: perfil diario del propio sensor ajustado a los extremos (valor en «Reemplazo»)
A31: 4 | B31: balance de masa | C31: Nivel de tanque reconstruido con los caudales de entrada y salida (valor en «Reemplazo»)
A32: 9 | B32: excluido | C32: Sin instalar, corte de suministro, sensor fuera del agua: queda vacío
A34: En azul: valores editables (offset, marca y reemplazo). Si cambia una marca o el offset, el dato depurado se recalcula.
A35: Dato inicial: lectura del equipo llevada a la malla común de 15 min (interpolada en la hora real de cada lectura). Presión en m c.a., caudal en L/s, nivel en m.

Sheet P1
A1: P1 · Presión (m) · VN3948790
A2: Usar solo la media horaria (tolerancia mayor)
A3: Offset | C3: 0.01
A4: Ventana (lecturas a cada lado) | C4: 8
A6: Fecha y hora | B6: Dato inicial (m) | C6: Marca | D6: Reemplazo | E6: Corregido (m) | F6: Dato depurado (m) | G6: Motivo
A7: 46273.344 | B7: -0.2801 | C7: 9 | E7: =IF(OR(C7=9,B7=""),"",B7-$C$3) | F7: =IF(C7=9,"",IF(C7=0,E7,IF(C7=1,IF(COUNT(E7:E15)=0,"",TRIMMEAN(E7:E15,0.5)),IF(D7="","",D7)))) | G7: equipo sin instalar
A8: 46273.354 | B8: -0.2895 | C8: 9 | E8: =IF(OR(C8=9,B8=""),"",B8-$C$3) | F8: =IF(C8=9,"",IF(C8=0,E8,IF(C8=1,IF(COUNT(E7:E16)=0,"",TRIMMEAN(E7:E16,0.5)),IF(D8="","",D8)))) | G8: equipo sin instalar
A9: 46273.365 | B9: -0.8403 | C9: 9 | E9: =IF(OR(C9=9,B9=""),"",B9-$C$3) | F9: =IF(C9=9,"",IF(C9=0,E9,IF(C9=1,IF(COUNT(E7:E17)=0,"",TRIMMEAN(E7:E17,0.5)),IF(D9="","",D9)))) | G9: equipo sin instalar
A10: 46273.375 | B10: -0.8683 | C10: 9 | E10: =IF(OR(C10=9,B10=""),"",B10-$C$3) | F10: =IF(C10=9,"",IF(C10=0,E10,IF(C10=1,IF(COUNT(E7:E18)=0,"",TRIMMEAN(E7:E18,0.5)),IF(D10="","",D10)))) | G10: equipo sin instalar
A11: 46273.385 | B11: -0.8683 | C11: 9 | E11: =IF(OR(C11=9,B11=""),"",B11-$C$3) | F11: =IF(C11=9,"",IF(C11=0,E11,IF(C11=1,IF(COUNT(E7:E19)=0,"",TRIMMEAN(E7:E19,0.5)),IF(D11="","",D11)))) | G11: equipo sin instalar
A12: 46273.396 | B12: -0.8683 | C12: 9 | E12: =IF(OR(C12=9,B12=""),"",B12-$C$3) | F12: =IF(C12=9,"",IF(C12=0,E12,IF(C12=1,IF(COUNT(E7:E20)=0,"",TRIMMEAN(E7:E20,0.5)),IF(D12="","",D12)))) | G12: equipo sin instalar
A13: 46273.406 | B13: -0.8776 | C13: 9 | E13: =IF(OR(C13=9,B13=""),"",B13-$C$3) | F13: =IF(C13=9,"",IF(C13=0,E13,IF(C13=1,IF(COUNT(E7:E21)=0,"",TRIMMEAN(E7:E21,0.5)),IF(D13="","",D13)))) | G13: equipo sin instalar
A14: 46273.417 | B14: -0.8403 | C14: 9 | E14: =IF(OR(C14=9,B14=""),"",B14-$C$3) | F14: =IF(C14=9,"",IF(C14=0,E14,IF(C14=1,IF(COUNT(E7:E22)=0,"",TRIMMEAN(E7:E22,0.5)),IF(D14="","",D14)))) | G14: equipo sin instalar
A15: 46273.427 | B15: 70.738 | C15: 9 | E15: =IF(OR(C15=9,B15=""),"",B15-$C$3) | F15: =IF(C15=9,"",IF(C15=0,E15,IF(C15=1,IF(COUNT(E7:E23)=0,"",TRIMMEAN(E7:E23,0.5)),IF(D15="","",D15)))) | G15: equipo sin instalar
A16: 46273.438 | B16: 75.6421 | C16: 1 | E16: =IF(OR(C16=9,B16=""),"",B16-$C$3) | F16: =IF(C16=9,"",IF(C16=0,E16,IF(C16=1,IF(COUNT(E8:E24)=0,"",TRIMMEAN(E8:E24,0.5)),IF(D16="","",D16)))) | G16: oscilación más rápida que el registro → media recortada de 4 h
A17: 46273.448 | B17: 79.438 | C17: 1 | E17: =IF(OR(C17=9,B17=""),"",B17-$C$3) | F17: =IF(C17=9,"",IF(C17=0,E17,IF(C17=1,IF(COUNT(E9:E25)=0,"",TRIMMEAN(E9:E25,0.5)),IF(D17="","",D17)))) | G17: oscilación más rápida que el registro → media recortada de 4 h
A18: 46273.458 | B18: 84.3403 | C18: 1 | E18: =IF(OR(C18=9,B18=""),"",B18-$C$3) | F18: =IF(C18=9,"",IF(C18=0,E18,IF(C18=1,IF(COUNT(E10:E26)=0,"",TRIMMEAN(E10:E26,0.5)),IF(D18="","",D18)))) | G18: oscilación más rápida que el registro → media recortada de 4 h
A19: 46273.469 | B19: 78.1651 | C19: 1 | E19: =IF(OR(C19=9,B19=""),"",B19-$C$3) | F19: =IF(C19=9,"",IF(C19=0,E19,IF(C19=1,IF(COUNT(E11:E27)=0,"",TRIMMEAN(E11:E27,0.5)),IF(D19="","",D19)))) | G19: oscilación más rápida que el registro → media recortada de 4 h
A20: 46273.479 | B20: 75.5161 | C20: 1 | E20: =IF(OR(C20=9,B20=""),"",B20-$C$3) | F20: =IF(C20=9,"",IF(C20=0,E20,IF(C20=1,IF(COUNT(E12:E28)=0,"",TRIMMEAN(E12:E28,0.5)),IF(D20="","",D20)))) | G20: oscilación más rápida que el registro → media recortada de 4 h
A21: 46273.49 | B21: 77.9318 | C21: 1 | E21: =IF(OR(C21=9,B21=""),"",B21-$C$3) | F21: =IF(C21=9,"",IF(C21=0,E21,IF(C21=1,IF(COUNT(E13:E29)=0,"",TRIMMEAN(E13:E29,0.5)),IF(D21="","",D21)))) | G21: oscilación más rápida que el registro → media recortada de 4 h
A22: 46273.5 | B22: 75.0782 | C22: 1 | E22: =IF(OR(C22=9,B22=""),"",B22-$C$3) | F22: =IF(C22=9,"",IF(C22=0,E22,IF(C22=1,IF(COUNT(E14:E30)=0,"",TRIMMEAN(E14:E30,0.5)),IF(D22="","",D22)))) | G22: oscilación más rápida que el registro → media recortada de 4 h
A23: 46273.51 | B23: 72.5383 | C23: 1 | E23: =IF(OR(C23=9,B23=""),"",B23-$C$3) | F23: =IF(C23=9,"",IF(C23=0,E23,IF(C23=1,IF(COUNT(E15:E31)=0,"",TRIMMEAN(E15:E31,0.5)),IF(D23="","",D23)))) | G23: oscilación más rápida que el registro → media recortada de 4 h
A24: 46273.521 | B24: 79.0647 | C24: 1 | E24: =IF(OR(C24=9,B24=""),"",B24-$C$3) | F24: =IF(C24=9,"",IF(C24=0,E24,IF(C24=1,IF(COUNT(E16:E32)=0,"",TRIMMEAN(E16:E32,0.5)),IF(D24="","",D24)))) | G24: oscilación más rápida que el registro → media recortada de 4 h
A25: 46273.531 | B25: 78.0211 | C25: 1 | E25: =IF(OR(C25=9,B25=""),"",B25-$C$3) | F25: =IF(C25=9,"",IF(C25=0,E25,IF(C25=1,IF(COUNT(E17:E33)=0,"",TRIMMEAN(E17:E33,0.5)),IF(D25="","",D25)))) | G25: oscilación más rápida que el registro → media recortada de 4 h
A26: 46273.542 | B26: 74.8138 | C26: 1 | E26: =IF(OR(C26=9,B26=""),"",B26-$C$3) | F26: =IF(C26=9,"",IF(C26=0,E26,IF(C26=1,IF(COUNT(E18:E34)=0,"",TRIMMEAN(E18:E34,0.5)),IF(D26="","",D26)))) | G26: oscilación más rápida que el registro → media recortada de 4 h
... A165: 46274.99 | B165: 71.162 | C165: 1 | E165: =IF(OR(C165=9,B165=""),"",B165-$C$3) | F165: =IF(C165=9,"",IF(C165=0,E165,IF(C165=1,IF(COUNT(E157:E173)=0,"",TRIMMEAN(E157:E173,0.5)),IF(D165="","",D165)))) | G165: oscilación más rápida que el registro → media recortada de 4 h
A166: 46275 | B166: 68.9711 | C166: 0 | E166: =IF(OR(C166=9,B166=""),"",B166-$C$3) | F166: =IF(C166=9,"",IF(C166=0,E166,IF(C166=1,IF(COUNT(E158:E174)=0,"",TRIMMEAN(E158:E174,0.5)),IF(D166="","",D166))))
A167: 46275.01 | B167: 64.2183 | C167: 0 | E167: =IF(OR(C167=9,B167=""),"",B167-$C$3) | F167: =IF(C167=9,"",IF(C167=0,E167,IF(C167=1,IF(COUNT(E159:E175)=0,"",TRIMMEAN(E159:E175,0.5)),IF(D167="","",D167))))
A168: 46275.021 | B168: 67.3441 | C168: 0 | E168: =IF(OR(C168=9,B168=""),"",B168-$C$3) | F168: =IF(C168=9,"",IF(C168=0,E168,IF(C168=1,IF(COUNT(E160:E176)=0,"",TRIMMEAN(E160:E176,0.5)),IF(D168="","",D168))))
A169: 46275.031 | B169: 68.0919 | C169: 0 | E169: =IF(OR(C169=9,B169=""),"",B169-$C$3) | F169: =IF(C169=9,"",IF(C169=0,E169,IF(C169=1,IF(COUNT(E161:E177)=0,"",TRIMMEAN(E161:E177,0.5)),IF(D169="","",D169))))
A170: 46275.042 | B170: 66.9788 | C170: 0 | E170: =IF(OR(C170=9,B170=""),"",B170-$C$3) | F170: =IF(C170=9,"",IF(C170=0,E170,IF(C170=1,IF(COUNT(E162:E178)=0,"",TRIMMEAN(E162:E178,0.5)),IF(D170="","",D170))))
A171: 46275.052 | B171: 67.7529 | C171: 0 | E171: =IF(OR(C171=9,B171=""),"",B171-$C$3) | F171: =IF(C171=9,"",IF(C171=0,E171,IF(C171=1,IF(COUNT(E163:E179)=0,"",TRIMMEAN(E163:E179,0.5)),IF(D171="","",D171))))
A172: 46275.062 | B172: 67.0722 | C172: 0 | E172: =IF(OR(C172=9,B172=""),"",B172-$C$3) | F172: =IF(C172=9,"",IF(C172=0,E172,IF(C172=1,IF(COUNT(E164:E180)=0,"",TRIMMEAN(E164:E180,0.5)),IF(D172="","",D172))))
A173: 46275.073 | B173: 67.2954 | C173: 0 | E173: =IF(OR(C173=9,B173=""),"",B173-$C$3) | F173: =IF(C173=9,"",IF(C173=0,E173,IF(C173=1,IF(COUNT(E165:E181)=0,"",TRIMMEAN(E165:E181,0.5)),IF(D173="","",D173))))
A174: 46275.083 | B174: 67.6367 | C174: 0 | E174: =IF(OR(C174=9,B174=""),"",B174-$C$3) | F174: =IF(C174=9,"",IF(C174=0,E174,IF(C174=1,IF(COUNT(E166:E182)=0,"",TRIMMEAN(E166:E182,0.5)),IF(D174="","",D174))))
A175: 46275.094 | B175: 68.028 | C175: 0 | E175: =IF(OR(C175=9,B175=""),"",B175-$C$3) | F175: =IF(C175=9,"",IF(C175=0,E175,IF(C175=1,IF(COUNT(E167:E183)=0,"",TRIMMEAN(E167:E183,0.5)),IF(D175="","",D175))))
A176: 46275.104 | B176: 68.338 | C176: 0 | E176: =IF(OR(C176=9,B176=""),"",B176-$C$3) | F176: =IF(C176=9,"",IF(C176=0,E176,IF(C176=1,IF(COUNT(E168:E184)=0,"",TRIMMEAN(E168:E184,0.5)),IF(D176="","",D176))))
A177: 46275.115 | B177: 68.3104 | C177: 0 | E177: =IF(OR(C177=9,B177=""),"",B177-$C$3) | F177: =IF(C177=9,"",IF(C177=0,E177,IF(C177=1,IF(COUNT(E169:E185)=0,"",TRIMMEAN(E169:E185,0.5)),IF(D177="","",D177))))
... A212: 46275.479 | B212: 5.6413 | C212: 0 | E212: =IF(OR(C212=9,B212=""),"",B212-$C$3) | F212: =IF(C212=9,"",IF(C212=0,E212,IF(C212=1,IF(COUNT(E204:E220)=0,"",TRIMMEAN(E204:E220,0.5)),IF(D212="","",D212))))
A213: 46275.49 | B213: 2.6627 | C213: 9 | E213: =IF(OR(C213=9,B213=""),"",B213-$C$3) | F213: =IF(C213=9,"",IF(C213=0,E213,IF(C213=1,IF(COUNT(E205:E221)=0,"",TRIMMEAN(E205:E221,0.5)),IF(D213="","",D213)))) | G213: sin presión (corte o vaciado)
...

Sheet P2
A1: P2 · Presión (m) · VN3942278
A2: Válido
A3: Offset | C3: -0.27
A4: Ventana (lecturas a cada lado) | C4: 4
A6: Fecha y hora | B6: Dato inicial (m) | C6: Marca | D6: Reemplazo | E6: Corregido (m) | F6: Dato depurado (m) | G6: Motivo
A7: 46273.344 | B7: -0.2715 | C7: 9 | E7: =IF(OR(C7=9,B7=""),"",B7-$C$3) | F7: =IF(C7=9,"",IF(C7=0,E7,IF(C7=1,IF(COUNT(E7:E11)=0,"",TRIMMEAN(E7:E11,0.5)),IF(D7="","",D7)))) | G7: equipo sin instalar
A8: 46273.354 | B8: -0.2715 | C8: 9 | E8: =IF(OR(C8=9,B8=""),"",B8-$C$3) | F8: =IF(C8=9,"",IF(C8=0,E8,IF(C8=1,IF(COUNT(E7:E12)=0,"",TRIMMEAN(E7:E12,0.5)),IF(D8="","",D8)))) | G8: equipo sin instalar
A9: 46273.365 | B9: -0.813 | C9: 9 | E9: =IF(OR(C9=9,B9=""),"",B9-$C$3) | F9: =IF(C9=9,"",IF(C9=0,E9,IF(C9=1,IF(COUNT(E7:E13)=0,"",TRIMMEAN(E7:E13,0.5)),IF(D9="","",D9)))) | G9: equipo sin instalar
A10: 46273.375 | B10: -0.841 | C10: 9 | E10: =IF(OR(C10=9,B10=""),"",B10-$C$3) | F10: =IF(C10=9,"",IF(C10=0,E10,IF(C10=1,IF(COUNT(E7:E14)=0,"",TRIMMEAN(E7:E14,0.5)),IF(D10="","",D10)))) | G10: equipo sin instalar
A11: 46273.385 | B11: -0.841 | C11: 9 | E11: =IF(OR(C11=9,B11=""),"",B11-$C$3) | F11: =IF(C11=9,"",IF(C11=0,E11,IF(C11=1,IF(COUNT(E7:E15)=0,"",TRIMMEAN(E7:E15,0.5)),IF(D11="","",D11)))) | G11: equipo sin instalar
A12: 46273.396 | B12: -0.8597 | C12: 9 | E12: =IF(OR(C12=9,B12=""),"",B12-$C$3) | F12: =IF(C12=9,"",IF(C12=0,E12,IF(C12=1,IF(COUNT(E8:E16)=0,"",TRIMMEAN(E8:E16,0.5)),IF(D12="","",D12)))) | G12: equipo sin instalar
A13: 46273.406 | B13: -0.8597 | C13: 9 | E13: =IF(OR(C13=9,B13=""),"",B13-$C$3) | F13: =IF(C13=9,"",IF(C13=0,E13,IF(C13=1,IF(COUNT(E9:E17)=0,"",TRIMMEAN(E9:E17,0.5)),IF(D13="","",D13)))) | G13: equipo sin instalar
A14: 46273.417 | B14: -0.841 | C14: 9 | E14: =IF(OR(C14=9,B14=""),"",B14-$C$3) | F14: =IF(C14=9,"",IF(C14=0,E14,IF(C14=1,IF(COUNT(E10:E18)=0,"",TRIMMEAN(E10:E18,0.5)),IF(D14="","",D14)))) | G14: equipo sin instalar
A15: 46273.427 | B15: -0.5703 | C15: 9 | E15: =IF(OR(C15=9,B15=""),"",B15-$C$3) | F15: =IF(C15=9,"",IF(C15=0,E15,IF(C15=1,IF(COUNT(E11:E19)=0,"",TRIMMEAN(E11:E19,0.5)),IF(D15="","",D15)))) | G15: equipo sin instalar
A16: 46273.438 | B16: -0.3555 | C16: 9 | E16: =IF(OR(C16=9,B16=""),"",B16-$C$3) | F16: =IF(C16=9,"",IF(C16=0,E16,IF(C16=1,IF(COUNT(E12:E20)=0,"",TRIMMEAN(E12:E20,0.5)),IF(D16="","",D16)))) | G16: equipo sin instalar
A17: 46273.448 | B17: -0.2715 | C17: 9 | E17: =IF(OR(C17=9,B17=""),"",B17-$C$3) | F17: =IF(C17=9,"",IF(C17=0,E17,IF(C17=1,IF(COUNT(E13:E21)=0,"",TRIMMEAN(E13:E21,0.5)),IF(D17="","",D17)))) | G17: equipo sin instalar
A18: 46273.458 | B18: -0.2809 | C18: 9 | E18: =IF(OR(C18=9,B18=""),"",B18-$C$3) | F18: =IF(C18=9,"",IF(C18=0,E18,IF(C18=1,IF(COUNT(E14:E22)=0,"",TRIMMEAN(E14:E22,0.5)),IF(D18="","",D18)))) | G18: equipo sin instalar
A19: 46273.469 | B19: -0.2809 | C19: 9 | E19: =IF(OR(C19=9,B19=""),"",B19-$C$3) | F19: =IF(C19=9,"",IF(C19=0,E19,IF(C19=1,IF(COUNT(E15:E23)=0,"",TRIMMEAN(E15:E23,0.5)),IF(D19="","",D19)))) | G19: equipo sin instalar
A20: 46273.479 | B20: -0.2155 | C20: 9 | E20: =IF(OR(C20=9,B20=""),"",B20-$C$3) | F20: =IF(C20=9,"",IF(C20=0,E20,IF(C20=1,IF(COUNT(E16:E24)=0,"",TRIMMEAN(E16:E24,0.5)),IF(D20="","",D20)))) | G20: equipo sin instalar
A21: 46273.49 | B21: 63.6394 | C21: 9 | E21: =IF(OR(C21=9,B21=""),"",B21-$C$3) | F21: =IF(C21=9,"",IF(C21=0,E21,IF(C21=1,IF(COUNT(E17:E25)=0,"",TRIMMEAN(E17:E25,0.5)),IF(D21="","",D21)))) | G21: equipo sin instalar
A22: 46273.5 | B22: 78.8672 | C22: 0 | E22: =IF(OR(C22=9,B22=""),"",B22-$C$3) | F22: =IF(C22=9,"",IF(C22=0,E22,IF(C22=1,IF(COUNT(E18:E26)=0,"",TRIMMEAN(E18:E26,0.5)),IF(D22="","",D22))))
A23: 46273.51 | B23: 78.8733 | C23: 0 | E23: =IF(OR(C23=9,B23=""),"",B23-$C$3) | F23: =IF(C23=9,"",IF(C23=0,E23,IF(C23=1,IF(COUNT(E19:E27)=0,"",TRIMMEAN(E19:E27,0.5)),IF(D23="","",D23))))
A24: 46273.521 | B24: 78.5164 | C24: 0 | E24: =IF(OR(C24=9,B24=""),"",B24-$C$3) | F24: =IF(C24=9,"",IF(C24=0,E24,IF(C24=1,IF(COUNT(E20:E28)=0,"",TRIMMEAN(E20:E28,0.5)),IF(D24="","",D24))))
A25: 46273.531 | B25: 78.2679 | C25: 0 | E25: =IF(OR(C25=9,B25=""),"",B25-$C$3) | F25: =IF(C25=9,"",IF(C25=0,E25,IF(C25=1,IF(COUNT(E21:E29)=0,"",TRIMMEAN(E21:E29,0.5)),IF(D25="","",D25))))
A26: 46273.542 | B26: 78.6762 | C26: 0 | E26: =IF(OR(C26=9,B26=""),"",B26-$C$3) | F26: =IF(C26=9,"",IF(C26=0,E26,IF(C26=1,IF(COUNT(E22:E30)=0,"",TRIMMEAN(E22:E30,0.5)),IF(D26="","",D26))))
A27: 46273.552 | B27: 79.5099 | C27: 0 | E27: =IF(OR(C27=9,B27=""),"",B27-$C$3) | F27: =IF(C27=9,"",IF(C27=0,E27,IF(C27=1,IF(COUNT(E23:E31)=0,"",TRIMMEAN(E23:E31,0.5)),IF(D27="","",D27))))
A28: 46273.562 | B28: 79.0337 | C28: 0 | E28: =IF(OR(C28=9,B28=""),"",B28-$C$3) | F28: =IF(C28=9,"",IF(C28=0,E28,IF(C28=1,IF(COUNT(E24:E32)=0,"",TRIMMEAN(E24:E32,0.5)),IF(D28="","",D28))))
A29: 46273.573 | B29: 78.5429 | C29: 0 | E29: =IF(OR(C29=9,B29=""),"",B29-$C$3) | F29: =IF(C29=9,"",IF(C29=0,E29,IF(C29=1,IF(COUNT(E25:E33)=0,"",TRIMMEAN(E25:E33,0.5)),IF(D29="","",D29))))
A30: 46273.583 | B30: 79.2625 | C30: 0 | E30: =IF(OR(C30=9,B30=""),"",B30-$C$3) | F30: =IF(C30=9,"",IF(C30=0,E30,IF(C30=1,IF(COUNT(E26:E34)=0,"",TRIMMEAN(E26:E34,0.5)),IF(D30="","",D30))))
A31: 46273.594 | B31: 79.0854 | C31: 0 | E31: =IF(OR(C31=9,B31=""),"",B31-$C$3) | F31: =IF(C31=9,"",IF(C31=0,E31,IF(C31=1,IF(COUNT(E27:E35)=0,"",TRIMMEAN(E27:E35,0.5)),IF(D31="","",D31))))
A32: 46273.604 | B32: 78.566 | C32: 0 | E32: =IF(OR(C32=9,B32=""),"",B32-$C$3) | F32: =IF(C32=9,"",IF(C32=0,E32,IF(C32=1,IF(COUNT(E28:E36)=0,"",TRIMMEAN(E28:E36,0.5)),IF(D32="","",D32))))
A33: 46273.615 | B33: 78.0249 | C33: 0 | E33: =IF(OR(C33=9,B33=""),"",B33-$C$3) | F33: =IF(C33=9,"",IF(C33=0,E33,IF(C33=1,IF(COUNT(E29:E37)=0,"",TRIMMEAN(E29:E37,0.5)),IF(D33="","",D33))))
... A291: 46276.302 | B291: 78.6449 | C291: 0 | E291: =IF(OR(C291=9,B291=""),"",B291-$C$3) | F291: =IF(C291=9,"",IF(C291=0,E291,IF(C291=1,IF(COUNT(E287:E295)=0,"",TRIMMEAN(E287:E295,0.5)),IF(D291="","",D291))))
A292: 46276.312 | B292: 45.3235 | C292: 2 | D292: 78.4943 | E292: =IF(OR(C292=9,B292=""),"",B292-$C$3) | F292: =IF(C292=9,"",IF(C292=0,E292,IF(C292=1,IF(COUNT(E288:E296)=0,"",TRIMMEAN(E288:E296,0.5)),IF(D292="","",D292)))) | G292: pico aislado
A293: 46276.323 | B293: 35.799 | C293: 2 | D293: 78.0736 | E293: =IF(OR(C293=9,B293=""),"",B293-$C$3) | F293: =IF(C293=9,"",IF(C293=0,E293,IF(C293=1,IF(COUNT(E289:E297)=0,"",TRIMMEAN(E289:E297,0.5)),IF(D293="","",D293)))) | G293: pico aislado
A294: 46276.333 | B294: 53.587 | C294: 2 | D294: 77.653 | E294: =IF(OR(C294=9,B294=""),"",B294-$C$3) | F294: =IF(C294=9,"",IF(C294=0,E294,IF(C294=1,IF(COUNT(E290:E298)=0,"",TRIMMEAN(E290:E298,0.5)),IF(D294="","",D294)))) | G294: pico aislado
A295: 46276.344 | B295: 76.9623 | C295: 0 | E295: =IF(OR(C295=9,B295=""),"",B295-$C$3) | F295: =IF(C295=9,"",IF(C295=0,E295,IF(C295=1,IF(COUNT(E291:E299)=0,"",TRIMMEAN(E291:E299,0.5)),IF(D295="","",D295))))
A296: 46276.354 | B296: 81.6313 | C296: 0 | E296: =IF(OR(C296=9,B296=""),"",B296-$C$3) | F296: =IF(C296=9,"",IF(C296=0,E296,IF(C296=1,IF(COUNT(E292:E300)=0,"",TRIMMEAN(E292:E300,0.5)),IF(D296="","",D296))))
A297: 46276.365 | B297: 81.1728 | C297: 0 | E297: =IF(OR(C297=9,B297=""),"",B297-$C$3) | F297: =IF(C297=9,"",IF(C297=0,E297,IF(C297=1,IF(COUNT(E293:E301)=0,"",TRIMMEAN(E293:E301,0.5)),IF(D297="","",D297))))
A298: 46276.375 | B298: 81.3431 | C298: 0 | E298: =IF(OR(C298=9,B298=""),"",B298-$C$3) | F298: =IF(C298=9,"",IF(C298=0,E298,IF(C298=1,IF(COUNT(E294:E302)=0,"",TRIMMEAN(E294:E302,0.5)),IF(D298="","",D298))))
...

Sheet P3
A1: P3 · Presión (m) · VN3943135
A2: Válido (suavizado)
A3: Offset | C3: -0.29
A4: Ventana (lecturas a cada lado) | C4: 4
A6: Fecha y hora | B6: Dato inicial (m) | C6: Marca | D6: Reemplazo | E6: Corregido (m) | F6: Dato depurado (m) | G6: Motivo
A7: 46273.344 | B7: -0.2852 | C7: 9 | E7: =IF(OR(C7=9,B7=""),"",B7-$C$3) | F7: =IF(C7=9,"",IF(C7=0,E7,IF(C7=1,IF(COUNT(E7:E11)=0,"",TRIMMEAN(E7:E11,0.5)),IF(D7="","",D7)))) | G7: equipo sin instalar
A8: 46273.354 | B8: -0.2665 | C8: 9 | E8: =IF(OR(C8=9,B8=""),"",B8-$C$3) | F8: =IF(C8=9,"",IF(C8=0,E8,IF(C8=1,IF(COUNT(E7:E12)=0,"",TRIMMEAN(E7:E12,0.5)),IF(D8="","",D8)))) | G8: equipo sin instalar
A9: 46273.365 | B9: -0.836 | C9: 9 | E9: =IF(OR(C9=9,B9=""),"",B9-$C$3) | F9: =IF(C9=9,"",IF(C9=0,E9,IF(C9=1,IF(COUNT(E7:E13)=0,"",TRIMMEAN(E7:E13,0.5)),IF(D9="","",D9)))) | G9: equipo sin instalar
A10: 46273.375 | B10: -0.864 | C10: 9 | E10: =IF(OR(C10=9,B10=""),"",B10-$C$3) | F10: =IF(C10=9,"",IF(C10=0,E10,IF(C10=1,IF(COUNT(E7:E14)=0,"",TRIMMEAN(E7:E14,0.5)),IF(D10="","",D10)))) | G10: equipo sin instalar
A11: 46273.385 | B11: -0.864 | C11: 9 | E11: =IF(OR(C11=9,B11=""),"",B11-$C$3) | F11: =IF(C11=9,"",IF(C11=0,E11,IF(C11=1,IF(COUNT(E7:E15)=0,"",TRIMMEAN(E7:E15,0.5)),IF(D11="","",D11)))) | G11: equipo sin instalar
A12: 46273.396 | B12: -0.8733 | C12: 9 | E12: =IF(OR(C12=9,B12=""),"",B12-$C$3) | F12: =IF(C12=9,"",IF(C12=0,E12,IF(C12=1,IF(COUNT(E8:E16)=0,"",TRIMMEAN(E8:E16,0.5)),IF(D12="","",D12)))) | G12: equipo sin instalar
A13: 46273.406 | B13: -0.9013 | C13: 9 | E13: =IF(OR(C13=9,B13=""),"",B13-$C$3) | F13: =IF(C13=9,"",IF(C13=0,E13,IF(C13=1,IF(COUNT(E9:E17)=0,"",TRIMMEAN(E9:E17,0.5)),IF(D13="","",D13)))) | G13: equipo sin instalar
A14: 46273.417 | B14: -0.836 | C14: 9 | E14: =IF(OR(C14=9,B14=""),"",B14-$C$3) | F14: =IF(C14=9,"",IF(C14=0,E14,IF(C14=1,IF(COUNT(E10:E18)=0,"",TRIMMEAN(E10:E18,0.5)),IF(D14="","",D14)))) | G14: equipo sin instalar
A15: 46273.427 | B15: -0.5839 | C15: 9 | E15: =IF(OR(C15=9,B15=""),"",B15-$C$3) | F15: =IF(C15=9,"",IF(C15=0,E15,IF(C15=1,IF(COUNT(E11:E19)=0,"",TRIMMEAN(E11:E19,0.5)),IF(D15="","",D15)))) | G15: equipo sin instalar
A16: 46273.438 | B16: -0.3785 | C16: 9 | E16: =IF(OR(C16=9,B16=""),"",B16-$C$3) | F16: =IF(C16=9,"",IF(C16=0,E16,IF(C16=1,IF(COUNT(E12:E20)=0,"",TRIMMEAN(E12:E20,0.5)),IF(D16="","",D16)))) | G16: equipo sin instalar
A17: 46273.448 | B17: -0.2945 | C17: 9 | E17: =IF(OR(C17=9,B17=""),"",B17-$C$3) | F17: =IF(C17=9,"",IF(C17=0,E17,IF(C17=1,IF(COUNT(E13:E21)=0,"",TRIMMEAN(E13:E21,0.5)),IF(D17="","",D17)))) | G17: equipo sin instalar
A18: 46273.458 | B18: -0.2945 | C18: 9 | E18: =IF(OR(C18=9,B18=""),"",B18-$C$3) | F18: =IF(C18=9,"",IF(C18=0,E18,IF(C18=1,IF(COUNT(E14:E22)=0,"",TRIMMEAN(E14:E22,0.5)),IF(D18="","",D18)))) | G18: equipo sin instalar
A19: 46273.469 | B19: -0.2945 | C19: 9 | E19: =IF(OR(C19=9,B19=""),"",B19-$C$3) | F19: =IF(C19=9,"",IF(C19=0,E19,IF(C19=1,IF(COUNT(E15:E23)=0,"",TRIMMEAN(E15:E23,0.5)),IF(D19="","",D19)))) | G19: equipo sin instalar
A20: 46273.479 | B20: -0.2754 | C20: 9 | E20: =IF(OR(C20=9,B20=""),"",B20-$C$3) | F20: =IF(C20=9,"",IF(C20=0,E20,IF(C20=1,IF(COUNT(E16:E24)=0,"",TRIMMEAN(E16:E24,0.5)),IF(D20="","",D20)))) | G20: equipo sin instalar
A21: 46273.49 | B21: 35.4808 | C21: 9 | E21: =IF(OR(C21=9,B21=""),"",B21-$C$3) | F21: =IF(C21=9,"",IF(C21=0,E21,IF(C21=1,IF(COUNT(E17:E25)=0,"",TRIMMEAN(E17:E25,0.5)),IF(D21="","",D21)))) | G21: equipo sin instalar
A22: 46273.5 | B22: 102.7874 | C22: 1 | E22: =IF(OR(C22=9,B22=""),"",B22-$C$3) | F22: =IF(C22=9,"",IF(C22=0,E22,IF(C22=1,IF(COUNT(E18:E26)=0,"",TRIMMEAN(E18:E26,0.5)),IF(D22="","",D22)))) | G22: oscilación más rápida que el registro → media recortada de 2 h
... A69: 46273.99 | B69: 149.1137 | C69: 1 | E69: =IF(OR(C69=9,B69=""),"",B69-$C$3) | F69: =IF(C69=9,"",IF(C69=0,E69,IF(C69=1,IF(COUNT(E65:E73)=0,"",TRIMMEAN(E65:E73,0.5)),IF(D69="","",D69)))) | G69: oscilación más rápida que el registro → media recortada de 2 h
A70: 46274 | B70: 142.2693 | C70: 0 | E70: =IF(OR(C70=9,B70=""),"",B70-$C$3) | F70: =IF(C70=9,"",IF(C70=0,E70,IF(C70=1,IF(COUNT(E66:E74)=0,"",TRIMMEAN(E66:E74,0.5)),IF(D70="","",D70))))
A71: 46274.01 | B71: 134.8722 | C71: 0 | E71: =IF(OR(C71=9,B71=""),"",B71-$C$3) | F71: =IF(C71=9,"",IF(C71=0,E71,IF(C71=1,IF(COUNT(E67:E75)=0,"",TRIMMEAN(E67:E75,0.5)),IF(D71="","",D71))))
A72: 46274.021 | B72: 135.4542 | C72: 0 | E72: =IF(OR(C72=9,B72=""),"",B72-$C$3) | F72: =IF(C72=9,"",IF(C72=0,E72,IF(C72=1,IF(COUNT(E68:E76)=0,"",TRIMMEAN(E68:E76,0.5)),IF(D72="","",D72))))
A73: 46274.031 | B73: 134.2271 | C73: 0 | E73: =IF(OR(C73=9,B73=""),"",B73-$C$3) | F73: =IF(C73=9,"",IF(C73=0,E73,IF(C73=1,IF(COUNT(E69:E77)=0,"",TRIMMEAN(E69:E77,0.5)),IF(D73="","",D73))))
A74: 46274.042 | B74: 137.6459 | C74: 0 | E74: =IF(OR(C74=9,B74=""),"",B74-$C$3) | F74: =IF(C74=9,"",IF(C74=0,E74,IF(C74=1,IF(COUNT(E70:E78)=0,"",TRIMMEAN(E70:E78,0.5)),IF(D74="","",D74))))
A75: 46274.052 | B75: 136.9355 | C75: 0 | E75: =IF(OR(C75=9,B75=""),"",B75-$C$3) | F75: =IF(C75=9,"",IF(C75=0,E75,IF(C75=1,IF(COUNT(E71:E79)=0,"",TRIMMEAN(E71:E79,0.5)),IF(D75="","",D75))))
A76: 46274.062 | B76: 137.0572 | C76: 0 | E76: =IF(OR(C76=9,B76=""),"",B76-$C$3) | F76: =IF(C76=9,"",IF(C76=0,E76,IF(C76=1,IF(COUNT(E72:E80)=0,"",TRIMMEAN(E72:E80,0.5)),IF(D76="","",D76))))
A77: 46274.073 | B77: 135.7098 | C77: 0 | E77: =IF(OR(C77=9,B77=""),"",B77-$C$3) | F77: =IF(C77=9,"",IF(C77=0,E77,IF(C77=1,IF(COUNT(E73:E81)=0,"",TRIMMEAN(E73:E81,0.5)),IF(D77="","",D77))))
A78: 46274.083 | B78: 135.9647 | C78: 0 | E78: =IF(OR(C78=9,B78=""),"",B78-$C$3) | F78: =IF(C78=9,"",IF(C78=0,E78,IF(C78=1,IF(COUNT(E74:E82)=0,"",TRIMMEAN(E74:E82,0.5)),IF(D78="","",D78))))
A79: 46274.094 | B79: 137.5126 | C79: 0 | E79: =IF(OR(C79=9,B79=""),"",B79-$C$3) | F79: =IF(C79=9,"",IF(C79=0,E79,IF(C79=1,IF(COUNT(E75:E83)=0,"",TRIMMEAN(E75:E83,0.5)),IF(D79="","",D79))))
A80: 46274.104 | B80: 137.9355 | C80: 0 | E80: =IF(OR(C80=9,B80=""),"",B80-$C$3) | F80: =IF(C80=9,"",IF(C80=0,E80,IF(C80=1,IF(COUNT(E76:E84)=0,"",TRIMMEAN(E76:E84,0.5)),IF(D80="","",D80))))
A81: 46274.115 | B81: 137.6724 | C81: 0 | E81: =IF(OR(C81=9,B81=""),"",B81-$C$3) | F81: =IF(C81=9,"",IF(C81=0,E81,IF(C81=1,IF(COUNT(E77:E85)=0,"",TRIMMEAN(E77:E85,0.5)),IF(D81="","",D81))))
... A94: 46274.25 | B94: 103.2072 | C94: 0 | E94: =IF(OR(C94=9,B94=""),"",B94-$C$3) | F94: =IF(C94=9,"",IF(C94=0,E94,IF(C94=1,IF(COUNT(E90:E98)=0,"",TRIMMEAN(E90:E98,0.5)),IF(D94="","",D94))))
A95: 46274.26 | B95: 99.9081 | C95: 2 | D95: 105.5751 | E95: =IF(OR(C95=9,B95=""),"",B95-$C$3) | F95: =IF(C95=9,"",IF(C95=0,E95,IF(C95=1,IF(COUNT(E91:E99)=0,"",TRIMMEAN(E91:E99,0.5)),IF(D95="","",D95)))) | G95: pico aislado
A96: 46274.271 | B96: 107.3629 | C96: 0 | E96: =IF(OR(C96=9,B96=""),"",B96-$C$3) | F96: =IF(C96=9,"",IF(C96=0,E96,IF(C96=1,IF(COUNT(E92:E100)=0,"",TRIMMEAN(E92:E100,0.5)),IF(D96="","",D96))))
A97: 46274.281 | B97: 106.2412 | C97: 0 | E97: =IF(OR(C97=9,B97=""),"",B97-$C$3) | F97: =IF(C97=9,"",IF(C97=0,E97,IF(C97=1,IF(COUNT(E93:E101)=0,"",TRIMMEAN(E93:E101,0.5)),IF(D97="","",D97))))
A98: 46274.292 | B98: 112.2419 | C98: 0 | E98: =IF(OR(C98=9,B98=""),"",B98-$C$3) | F98: =IF(C98=9,"",IF(C98=0,E98,IF(C98=1,IF(COUNT(E94:E102)=0,"",TRIMMEAN(E94:E102,0.5)),IF(D98="","",D98))))
A99: 46274.302 | B99: 117.3331 | C99: 0 | E99: =IF(OR(C99=9,B99=""),"",B99-$C$3) | F99: =IF(C99=9,"",IF(C99=0,E99,IF(C99=1,IF(COUNT(E95:E103)=0,"",TRIMMEAN(E95:E103,0.5)),IF(D99="","",D99))))
...

Sheet P4
A1: P4 · Presión (m) · VN3950683
A2: Válido
A3: Offset | C3: 0.03
A4: Ventana (lecturas a cada lado) | C4: 4
A6: Fecha y hora | B6: Dato inicial (m) | C6: Marca | D6: Reemplazo | E6: Corregido (m) | F6: Dato depurado (m) | G6: Motivo
A7: 46273.344 | B7: -0.28 | C7: 9 | E7: =IF(OR(C7=9,B7=""),"",B7-$C$3) | F7: =IF(C7=9,"",IF(C7=0,E7,IF(C7=1,IF(COUNT(E7:E11)=0,"",TRIMMEAN(E7:E11,0.5)),IF(D7="","",D7)))) | G7: equipo sin instalar
A8: 46273.354 | B8: -0.2987 | C8: 9 | E8: =IF(OR(C8=9,B8=""),"",B8-$C$3) | F8: =IF(C8=9,"",IF(C8=0,E8,IF(C8=1,IF(COUNT(E7:E12)=0,"",TRIMMEAN(E7:E12,0.5)),IF(D8="","",D8)))) | G8: equipo sin instalar
A9: 46273.365 | B9: -0.8308 | C9: 9 | E9: =IF(OR(C9=9,B9=""),"",B9-$C$3) | F9: =IF(C9=9,"",IF(C9=0,E9,IF(C9=1,IF(COUNT(E7:E13)=0,"",TRIMMEAN(E7:E13,0.5)),IF(D9="","",D9)))) | G9: equipo sin instalar
A10: 46273.375 | B10: -0.8681 | C10: 9 | E10: =IF(OR(C10=9,B10=""),"",B10-$C$3) | F10: =IF(C10=9,"",IF(C10=0,E10,IF(C10=1,IF(COUNT(E7:E14)=0,"",TRIMMEAN(E7:E14,0.5)),IF(D10="","",D10)))) | G10: equipo sin instalar
A11: 46273.385 | B11: -0.8588 | C11: 9 | E11: =IF(OR(C11=9,B11=""),"",B11-$C$3) | F11: =IF(C11=9,"",IF(C11=0,E11,IF(C11=1,IF(COUNT(E7:E15)=0,"",TRIMMEAN(E7:E15,0.5)),IF(D11="","",D11)))) | G11: equipo sin instalar
A12: 46273.396 | B12: -0.8775 | C12: 9 | E12: =IF(OR(C12=9,B12=""),"",B12-$C$3) | F12: =IF(C12=9,"",IF(C12=0,E12,IF(C12=1,IF(COUNT(E8:E16)=0,"",TRIMMEAN(E8:E16,0.5)),IF(D12="","",D12)))) | G12: equipo sin instalar
A13: 46273.406 | B13: -0.8962 | C13: 9 | E13: =IF(OR(C13=9,B13=""),"",B13-$C$3) | F13: =IF(C13=9,"",IF(C13=0,E13,IF(C13=1,IF(COUNT(E9:E17)=0,"",TRIMMEAN(E9:E17,0.5)),IF(D13="","",D13)))) | G13: equipo sin instalar
A14: 46273.417 | B14: -0.8401 | C14: 9 | E14: =IF(OR(C14=9,B14=""),"",B14-$C$3) | F14: =IF(C14=9,"",IF(C14=0,E14,IF(C14=1,IF(COUNT(E10:E18)=0,"",TRIMMEAN(E10:E18,0.5)),IF(D14="","",D14)))) | G14: equipo sin instalar
A15: 46273.427 | B15: -0.5787 | C15: 9 | E15: =IF(OR(C15=9,B15=""),"",B15-$C$3) | F15: =IF(C15=9,"",IF(C15=0,E15,IF(C15=1,IF(COUNT(E11:E19)=0,"",TRIMMEAN(E11:E19,0.5)),IF(D15="","",D15)))) | G15: equipo sin instalar
A16: 46273.438 | B16: -0.3733 | C16: 9 | E16: =IF(OR(C16=9,B16=""),"",B16-$C$3) | F16: =IF(C16=9,"",IF(C16=0,E16,IF(C16=1,IF(COUNT(E12:E20)=0,"",TRIMMEAN(E12:E20,0.5)),IF(D16="","",D16)))) | G16: equipo sin instalar
A17: 46273.448 | B17: -0.2987 | C17: 9 | E17: =IF(OR(C17=9,B17=""),"",B17-$C$3) | F17: =IF(C17=9,"",IF(C17=0,E17,IF(C17=1,IF(COUNT(E13:E21)=0,"",TRIMMEAN(E13:E21,0.5)),IF(D17="","",D17)))) | G17: equipo sin instalar
A18: 46273.458 | B18: 61.8048 | C18: 9 | E18: =IF(OR(C18=9,B18=""),"",B18-$C$3) | F18: =IF(C18=9,"",IF(C18=0,E18,IF(C18=1,IF(COUNT(E14:E22)=0,"",TRIMMEAN(E14:E22,0.5)),IF(D18="","",D18)))) | G18: equipo sin instalar
A19: 46273.469 | B19: 70.031 | C19: 1 | E19: =IF(OR(C19=9,B19=""),"",B19-$C$3) | F19: =IF(C19=9,"",IF(C19=0,E19,IF(C19=1,IF(COUNT(E15:E23)=0,"",TRIMMEAN(E15:E23,0.5)),IF(D19="","",D19)))) | G19: oscilación más rápida que el registro → media recortada de 2 h
A20: 46273.479 | B20: 69.6061 | C20: 1 | E20: =IF(OR(C20=9,B20=""),"",B20-$C$3) | F20: =IF(C20=9,"",IF(C20=0,E20,IF(C20=1,IF(COUNT(E16:E24)=0,"",TRIMMEAN(E16:E24,0.5)),IF(D20="","",D20)))) | G20: oscilación más rápida que el registro → media recortada de 2 h
A21: 46273.49 | B21: 81.2394 | C21: 1 | E21: =IF(OR(C21=9,B21=""),"",B21-$C$3) | F21: =IF(C21=9,"",IF(C21=0,E21,IF(C21=1,IF(COUNT(E17:E25)=0,"",TRIMMEAN(E17:E25,0.5)),IF(D21="","",D21)))) | G21: oscilación más rápida que el registro → media recortada de 2 h
A22: 46273.5 | B22: 75.6292 | C22: 1 | E22: =IF(OR(C22=9,B22=""),"",B22-$C$3) | F22: =IF(C22=9,"",IF(C22=0,E22,IF(C22=1,IF(COUNT(E18:E26)=0,"",TRIMMEAN(E18:E26,0.5)),IF(D22="","",D22)))) | G22: oscilación más rápida que el registro → media recortada de 2 h
... A69: 46273.99 | B69: 107.1692 | C69: 1 | E69: =IF(OR(C69=9,B69=""),"",B69-$C$3) | F69: =IF(C69=9,"",IF(C69=0,E69,IF(C69=1,IF(COUNT(E65:E73)=0,"",TRIMMEAN(E65:E73,0.5)),IF(D69="","",D69)))) | G69: oscilación más rápida que el registro → media recortada de 2 h
A70: 46274 | B70: 106.9975 | C70: 0 | E70: =IF(OR(C70=9,B70=""),"",B70-$C$3) | F70: =IF(C70=9,"",IF(C70=0,E70,IF(C70=1,IF(COUNT(E66:E74)=0,"",TRIMMEAN(E66:E74,0.5)),IF(D70="","",D70))))
A71: 46274.01 | B71: 95.4203 | C71: 0 | E71: =IF(OR(C71=9,B71=""),"",B71-$C$3) | F71: =IF(C71=9,"",IF(C71=0,E71,IF(C71=1,IF(COUNT(E67:E75)=0,"",TRIMMEAN(E67:E75,0.5)),IF(D71="","",D71))))
A72: 46274.021 | B72: 94.3173 | C72: 0 | E72: =IF(OR(C72=9,B72=""),"",B72-$C$3) | F72: =IF(C72=9,"",IF(C72=0,E72,IF(C72=1,IF(COUNT(E68:E76)=0,"",TRIMMEAN(E68:E76,0.5)),IF(D72="","",D72))))
A73: 46274.031 | B73: 94.2357 | C73: 0 | E73: =IF(OR(C73=9,B73=""),"",B73-$C$3) | F73: =IF(C73=9,"",IF(C73=0,E73,IF(C73=1,IF(COUNT(E69:E77)=0,"",TRIMMEAN(E69:E77,0.5)),IF(D73="","",D73))))
A74: 46274.042 | B74: 96.61 | C74: 0 | E74: =IF(OR(C74=9,B74=""),"",B74-$C$3) | F74: =IF(C74=9,"",IF(C74=0,E74,IF(C74=1,IF(COUNT(E70:E78)=0,"",TRIMMEAN(E70:E78,0.5)),IF(D74="","",D74))))
A75: 46274.052 | B75: 95.9591 | C75: 0 | E75: =IF(OR(C75=9,B75=""),"",B75-$C$3) | F75: =IF(C75=9,"",IF(C75=0,E75,IF(C75=1,IF(COUNT(E71:E79)=0,"",TRIMMEAN(E71:E79,0.5)),IF(D75="","",D75))))
A76: 46274.062 | B76: 96.785 | C76: 0 | E76: =IF(OR(C76=9,B76=""),"",B76-$C$3) | F76: =IF(C76=9,"",IF(C76=0,E76,IF(C76=1,IF(COUNT(E72:E80)=0,"",TRIMMEAN(E72:E80,0.5)),IF(D76="","",D76))))
A77: 46274.073 | B77: 95.4662 | C77: 0 | E77: =IF(OR(C77=9,B77=""),"",B77-$C$3) | F77: =IF(C77=9,"",IF(C77=0,E77,IF(C77=1,IF(COUNT(E73:E81)=0,"",TRIMMEAN(E73:E81,0.5)),IF(D77="","",D77))))
A78: 46274.083 | B78: 95.3472 | C78: 0 | E78: =IF(OR(C78=9,B78=""),"",B78-$C$3) | F78: =IF(C78=9,"",IF(C78=0,E78,IF(C78=1,IF(COUNT(E74:E82)=0,"",TRIMMEAN(E74:E82,0.5)),IF(D78="","",D78))))
A79: 46274.094 | B79: 96.4723 | C79: 0 | E79: =IF(OR(C79=9,B79=""),"",B79-$C$3) | F79: =IF(C79=9,"",IF(C79=0,E79,IF(C79=1,IF(COUNT(E75:E83)=0,"",TRIMMEAN(E75:E83,0.5)),IF(D79="","",D79))))
A80: 46274.104 | B80: 97.0043 | C80: 0 | E80: =IF(OR(C80=9,B80=""),"",B80-$C$3) | F80: =IF(C80=9,"",IF(C80=0,E80,IF(C80=1,IF(COUNT(E76:E84)=0,"",TRIMMEAN(E76:E84,0.5)),IF(D80="","",D80))))
A81: 46274.115 | B81: 96.0389 | C81: 0 | E81: =IF(OR(C81=9,B81=""),"",B81-$C$3) | F81: =IF(C81=9,"",IF(C81=0,E81,IF(C81=1,IF(COUNT(E77:E85)=0,"",TRIMMEAN(E77:E85,0.5)),IF(D81="","",D81))))
... A94: 46274.25 | B94: 70.5119 | C94: 0 | E94: =IF(OR(C94=9,B94=""),"",B94-$C$3) | F94: =IF(C94=9,"",IF(C94=0,E94,IF(C94=1,IF(COUNT(E90:E98)=0,"",TRIMMEAN(E90:E98,0.5)),IF(D94="","",D94))))
A95: 46274.26 | B95: 66.2665 | C95: 2 | D95: 71.2612 | E95: =IF(OR(C95=9,B95=""),"",B95-$C$3) | F95: =IF(C95=9,"",IF(C95=0,E95,IF(C95=1,IF(COUNT(E91:E99)=0,"",TRIMMEAN(E91:E99,0.5)),IF(D95="","",D95)))) | G95: pico aislado
A96: 46274.271 | B96: 72.0704 | C96: 0 | E96: =IF(OR(C96=9,B96=""),"",B96-$C$3) | F96: =IF(C96=9,"",IF(C96=0,E96,IF(C96=1,IF(COUNT(E92:E100)=0,"",TRIMMEAN(E92:E100,0.5)),IF(D96="","",D96))))
A97: 46274.281 | B97: 72.5157 | C97: 0 | E97: =IF(OR(C97=9,B97=""),"",B97-$C$3) | F97: =IF(C97=9,"",IF(C97=0,E97,IF(C97=1,IF(COUNT(E93:E101)=0,"",TRIMMEAN(E93:E101,0.5)),IF(D97="","",D97))))
A98: 46274.292 | B98: 75.9267 | C98: 0 | E98: =IF(OR(C98=9,B98=""),"",B98-$C$3) | F98: =IF(C98=9,"",IF(C98=0,E98,IF(C98=1,IF(COUNT(E94:E102)=0,"",TRIMMEAN(E94:E102,0.5)),IF(D98="","",D98))))
A99: 46274.302 | B99: 77.4834 | C99: 0 | E99: =IF(OR(C99=9,B99=""),"",B99-$C$3) | F99: =IF(C99=9,"",IF(C99=0,E99,IF(C99=1,IF(COUNT(E95:E103)=0,"",TRIMMEAN(E95:E103,0.5)),IF(D99="","",D99))))
...

Sheet P5
A1: P5 · Presión (m) · VN3948890
A2: Válido (suavizado)
A3: Offset | C3: 0
A4: Ventana (lecturas a cada lado) | C4: 4
A6: Fecha y hora | B6: Dato inicial (m) | C6: Marca | D6: Reemplazo | E6: Corregido (m) | F6: Dato depurado (m) | G6: Motivo
A7: 46273.344 | B7: -0.3031 | C7: 9 | E7: =IF(OR(C7=9,B7=""),"",B7-$C$3) | F7: =IF(C7=9,"",IF(C7=0,E7,IF(C7=1,IF(COUNT(E7:E11)=0,"",TRIMMEAN(E7:E11,0.5)),IF(D7="","",D7)))) | G7: equipo sin instalar
A8: 46273.354 | B8: -0.2938 | C8: 9 | E8: =IF(OR(C8=9,B8=""),"",B8-$C$3) | F8: =IF(C8=9,"",IF(C8=0,E8,IF(C8=1,IF(COUNT(E7:E12)=0,"",TRIMMEAN(E7:E12,0.5)),IF(D8="","",D8)))) | G8: equipo sin instalar
A9: 46273.365 | B9: -0.8633 | C9: 9 | E9: =IF(OR(C9=9,B9=""),"",B9-$C$3) | F9: =IF(C9=9,"",IF(C9=0,E9,IF(C9=1,IF(COUNT(E7:E13)=0,"",TRIMMEAN(E7:E13,0.5)),IF(D9="","",D9)))) | G9: equipo sin instalar
A10: 46273.375 | B10: -0.8726 | C10: 9 | E10: =IF(OR(C10=9,B10=""),"",B10-$C$3) | F10: =IF(C10=9,"",IF(C10=0,E10,IF(C10=1,IF(COUNT(E7:E14)=0,"",TRIMMEAN(E7:E14,0.5)),IF(D10="","",D10)))) | G10: equipo sin instalar
A11: 46273.385 | B11: -0.8726 | C11: 9 | E11: =IF(OR(C11=9,B11=""),"",B11-$C$3) | F11: =IF(C11=9,"",IF(C11=0,E11,IF(C11=1,IF(COUNT(E7:E15)=0,"",TRIMMEAN(E7:E15,0.5)),IF(D11="","",D11)))) | G11: equipo sin instalar
A12: 46273.396 | B12: -0.8819 | C12: 9 | E12: =IF(OR(C12=9,B12=""),"",B12-$C$3) | F12: =IF(C12=9,"",IF(C12=0,E12,IF(C12=1,IF(COUNT(E8:E16)=0,"",TRIMMEAN(E8:E16,0.5)),IF(D12="","",D12)))) | G12: equipo sin instalar
A13: 46273.406 | B13: -0.9006 | C13: 9 | E13: =IF(OR(C13=9,B13=""),"",B13-$C$3) | F13: =IF(C13=9,"",IF(C13=0,E13,IF(C13=1,IF(COUNT(E9:E17)=0,"",TRIMMEAN(E9:E17,0.5)),IF(D13="","",D13)))) | G13: equipo sin instalar
A14: 46273.417 | B14: -0.8633 | C14: 9 | E14: =IF(OR(C14=9,B14=""),"",B14-$C$3) | F14: =IF(C14=9,"",IF(C14=0,E14,IF(C14=1,IF(COUNT(E10:E18)=0,"",TRIMMEAN(E10:E18,0.5)),IF(D14="","",D14)))) | G14: equipo sin instalar
A15: 46273.427 | B15: -0.6018 | C15: 9 | E15: =IF(OR(C15=9,B15=""),"",B15-$C$3) | F15: =IF(C15=9,"",IF(C15=0,E15,IF(C15=1,IF(COUNT(E11:E19)=0,"",TRIMMEAN(E11:E19,0.5)),IF(D15="","",D15)))) | G15: equipo sin instalar
A16: 46273.438 | B16: -0.3778 | C16: 9 | E16: =IF(OR(C16=9,B16=""),"",B16-$C$3) | F16: =IF(C16=9,"",IF(C16=0,E16,IF(C16=1,IF(COUNT(E12:E20)=0,"",TRIMMEAN(E12:E20,0.5)),IF(D16="","",D16)))) | G16: equipo sin instalar
A17: 46273.448 | B17: 63.3856 | C17: 9 | E17: =IF(OR(C17=9,B17=""),"",B17-$C$3) | F17: =IF(C17=9,"",IF(C17=0,E17,IF(C17=1,IF(COUNT(E13:E21)=0,"",TRIMMEAN(E13:E21,0.5)),IF(D17="","",D17)))) | G17: equipo sin instalar
A18: 46273.458 | B18: 58.1591 | C18: 1 | E18: =IF(OR(C18=9,B18=""),"",B18-$C$3) | F18: =IF(C18=9,"",IF(C18=0,E18,IF(C18=1,IF(COUNT(E14:E22)=0,"",TRIMMEAN(E14:E22,0.5)),IF(D18="","",D18)))) | G18: oscilación más rápida que el registro → media recortada de 2 h
A19: 46273.469 | B19: 69.6016 | C19: 1 | E19: =IF(OR(C19=9,B19=""),"",B19-$C$3) | F19: =IF(C19=9,"",IF(C19=0,E19,IF(C19=1,IF(COUNT(E15:E23)=0,"",TRIMMEAN(E15:E23,0.5)),IF(D19="","",D19)))) | G19: oscilación más rápida que el registro → media recortada de 2 h
A20: 46273.479 | B20: 62.183 | C20: 1 | E20: =IF(OR(C20=9,B20=""),"",B20-$C$3) | F20: =IF(C20=9,"",IF(C20=0,E20,IF(C20=1,IF(COUNT(E16:E24)=0,"",TRIMMEAN(E16:E24,0.5)),IF(D20="","",D20)))) | G20: oscilación más rápida que el registro → media recortada de 2 h
A21: 46273.49 | B21: 56.8234 | C21: 1 | E21: =IF(OR(C21=9,B21=""),"",B21-$C$3) | F21: =IF(C21=9,"",IF(C21=0,E21,IF(C21=1,IF(COUNT(E17:E25)=0,"",TRIMMEAN(E17:E25,0.5)),IF(D21="","",D21)))) | G21: oscilación más rápida que el registro → media recortada de 2 h
A22: 46273.5 | B22: 68.7222 | C22: 1 | E22: =IF(OR(C22=9,B22=""),"",B22-$C$3) | F22: =IF(C22=9,"",IF(C22=0,E22,IF(C22=1,IF(COUNT(E18:E26)=0,"",TRIMMEAN(E18:E26,0.5)),IF(D22="","",D22)))) | G22: oscilación más rápida que el registro → media recortada de 2 h
... A802: 46281.625 | B802: 0.005 | C802: 9 | E802: =IF(OR(C802=9,B802=""),"",B802-$C$3) | F802: =IF(C802=9,"",IF(C802=0,E802,IF(C802=1,IF(COUNT(E798:E806)=0,"",TRIMMEAN(E798:E806,0.5)),IF(D802="","",D802)))) | G802: equipo sin instalar
A803: 46281.635 | B803: 0.005 | C803: 9 | E803: =IF(OR(C803=9,B803=""),"",B803-$C$3) | F803: =IF(C803=9,"",IF(C803=0,E803,IF(C803=1,IF(COUNT(E799:E806)=0,"",TRIMMEAN(E799:E806,0.5)),IF(D803="","",D803)))) | G803: equipo sin instalar
A804: 46281.646 | B804: 0.005 | C804: 9 | E804: =IF(OR(C804=9,B804=""),"",B804-$C$3) | F804: =IF(C804=9,"",IF(C804=0,E804,IF(C804=1,IF(COUNT(E800:E806)=0,"",TRIMMEAN(E800:E806,0.5)),IF(D804="","",D804)))) | G804: equipo sin instalar
A805: 46281.656 | B805: 0.0041 | C805: 9 | E805: =IF(OR(C805=9,B805=""),"",B805-$C$3) | F805: =IF(C805=9,"",IF(C805=0,E805,IF(C805=1,IF(COUNT(E801:E806)=0,"",TRIMMEAN(E801:E806,0.5)),IF(D805="","",D805)))) | G805: equipo sin instalar
A806: 46281.667 | B806: -0.0044 | C806: 9 | E806: =IF(OR(C806=9,B806=""),"",B806-$C$3) | F806: =IF(C806=9,"",IF(C806=0,E806,IF(C806=1,IF(COUNT(E802:E806)=0,"",TRIMMEAN(E802:E806,0.5)),IF(D806="","",D806)))) | G806: equipo sin instalar

Sheet P6
A1: P6 · Presión (m) · VN3582511
A2: Válido
A3: Offset | C3: -0.24
A4: Ventana (lecturas a cada lado) | C4: 4
A6: Fecha y hora | B6: Dato inicial (m) | C6: Marca | D6: Reemplazo | E6: Corregido (m) | F6: Dato depurado (m) | G6: Motivo
A7: 46273.344 | B7: -0.2615 | C7: 9 | E7: =IF(OR(C7=9,B7=""),"",B7-$C$3) | F7: =IF(C7=9,"",IF(C7=0,E7,IF(C7=1,IF(COUNT(E7:E11)=0,"",TRIMMEAN(E7:E11,0.5)),IF(D7="","",D7)))) | G7: equipo sin instalar
A8: 46273.354 | B8: -0.2615 | C8: 9 | E8: =IF(OR(C8=9,B8=""),"",B8-$C$3) | F8: =IF(C8=9,"",IF(C8=0,E8,IF(C8=1,IF(COUNT(E7:E12)=0,"",TRIMMEAN(E7:E12,0.5)),IF(D8="","",D8)))) | G8: equipo sin instalar
A9: 46273.365 | B9: -0.8403 | C9: 9 | E9: =IF(OR(C9=9,B9=""),"",B9-$C$3) | F9: =IF(C9=9,"",IF(C9=0,E9,IF(C9=1,IF(COUNT(E7:E13)=0,"",TRIMMEAN(E7:E13,0.5)),IF(D9="","",D9)))) | G9: equipo sin instalar
A10: 46273.375 | B10: -0.8683 | C10: 9 | E10: =IF(OR(C10=9,B10=""),"",B10-$C$3) | F10: =IF(C10=9,"",IF(C10=0,E10,IF(C10=1,IF(COUNT(E7:E14)=0,"",TRIMMEAN(E7:E14,0.5)),IF(D10="","",D10)))) | G10: equipo sin instalar
A11: 46273.385 | B11: -0.8589 | C11: 9 | E11: =IF(OR(C11=9,B11=""),"",B11-$C$3) | F11: =IF(C11=9,"",IF(C11=0,E11,IF(C11=1,IF(COUNT(E7:E15)=0,"",TRIMMEAN(E7:E15,0.5)),IF(D11="","",D11)))) | G11: equipo sin instalar
A12: 46273.396 | B12: -0.8589 | C12: 9 | E12: =IF(OR(C12=9,B12=""),"",B12-$C$3) | F12: =IF(C12=9,"",IF(C12=0,E12,IF(C12=1,IF(COUNT(E8:E16)=0,"",TRIMMEAN(E8:E16,0.5)),IF(D12="","",D12)))) | G12: equipo sin instalar
A13: 46273.406 | B13: -0.887 | C13: 9 | E13: =IF(OR(C13=9,B13=""),"",B13-$C$3) | F13: =IF(C13=9,"",IF(C13=0,E13,IF(C13=1,IF(COUNT(E9:E17)=0,"",TRIMMEAN(E9:E17,0.5)),IF(D13="","",D13)))) | G13: equipo sin instalar
A14: 46273.417 | B14: -0.8496 | C14: 9 | E14: =IF(OR(C14=9,B14=""),"",B14-$C$3) | F14: =IF(C14=9,"",IF(C14=0,E14,IF(C14=1,IF(COUNT(E10:E18)=0,"",TRIMMEAN(E10:E18,0.5)),IF(D14="","",D14)))) | G14: equipo sin instalar
A15: 46273.427 | B15: -0.5789 | C15: 9 | E15: =IF(OR(C15=9,B15=""),"",B15-$C$3) | F15: =IF(C15=9,"",IF(C15=0,E15,IF(C15=1,IF(COUNT(E11:E19)=0,"",TRIMMEAN(E11:E19,0.5)),IF(D15="","",D15)))) | G15: equipo sin instalar
A16: 46273.438 | B16: -0.3735 | C16: 9 | E16: =IF(OR(C16=9,B16=""),"",B16-$C$3) | F16: =IF(C16=9,"",IF(C16=0,E16,IF(C16=1,IF(COUNT(E12:E20)=0,"",TRIMMEAN(E12:E20,0.5)),IF(D16="","",D16)))) | G16: equipo sin instalar
A17: 46273.448 | B17: -0.2895 | C17: 9 | E17: =IF(OR(C17=9,B17=""),"",B17-$C$3) | F17: =IF(C17=9,"",IF(C17=0,E17,IF(C17=1,IF(COUNT(E13:E21)=0,"",TRIMMEAN(E13:E21,0.5)),IF(D17="","",D17)))) | G17: equipo sin instalar
A18: 46273.458 | B18: -0.2801 | C18: 9 | E18: =IF(OR(C18=9,B18=""),"",B18-$C$3) | F18: =IF(C18=9,"",IF(C18=0,E18,IF(C18=1,IF(COUNT(E14:E22)=0,"",TRIMMEAN(E14:E22,0.5)),IF(D18="","",D18)))) | G18: equipo sin instalar
A19: 46273.469 | B19: -0.2801 | C19: 9 | E19: =IF(OR(C19=9,B19=""),"",B19-$C$3) | F19: =IF(C19=9,"",IF(C19=0,E19,IF(C19=1,IF(COUNT(E15:E23)=0,"",TRIMMEAN(E15:E23,0.5)),IF(D19="","",D19)))) | G19: equipo sin instalar
A20: 46273.479 | B20: -0.2428 | C20: 9 | E20: =IF(OR(C20=9,B20=""),"",B20-$C$3) | F20: =IF(C20=9,"",IF(C20=0,E20,IF(C20=1,IF(COUNT(E16:E24)=0,"",TRIMMEAN(E16:E24,0.5)),IF(D20="","",D20)))) | G20: equipo sin instalar
A21: 46273.49 | B21: -0.2428 | C21: 9 | E21: =IF(OR(C21=9,B21=""),"",B21-$C$3) | F21: =IF(C21=9,"",IF(C21=0,E21,IF(C21=1,IF(COUNT(E17:E25)=0,"",TRIMMEAN(E17:E25,0.5)),IF(D21="","",D21)))) | G21: equipo sin instalar
A22: 46273.5 | B22: -0.2895 | C22: 9 | E22: =IF(OR(C22=9,B22=""),"",B22-$C$3) | F22: =IF(C22=9,"",IF(C22=0,E22,IF(C22=1,IF(COUNT(E18:E26)=0,"",TRIMMEAN(E18:E26,0.5)),IF(D22="","",D22)))) | G22: equipo sin instalar
A23: 46273.51 | B23: 30.9108 | C23: 9 | E23: =IF(OR(C23=9,B23=""),"",B23-$C$3) | F23: =IF(C23=9,"",IF(C23=0,E23,IF(C23=1,IF(COUNT(E19:E27)=0,"",TRIMMEAN(E19:E27,0.5)),IF(D23="","",D23)))) | G23: equipo sin instalar
A24: 46273.521 | B24: 41.1074 | C24: 0 | E24: =IF(OR(C24=9,B24=""),"",B24-$C$3) | F24: =IF(C24=9,"",IF(C24=0,E24,IF(C24=1,IF(COUNT(E20:E28)=0,"",TRIMMEAN(E20:E28,0.5)),IF(D24="","",D24))))
A25: 46273.531 | B25: 41.2116 | C25: 0 | E25: =IF(OR(C25=9,B25=""),"",B25-$C$3) | F25: =IF(C25=9,"",IF(C25=0,E25,IF(C25=1,IF(COUNT(E21:E29)=0,"",TRIMMEAN(E21:E29,0.5)),IF(D25="","",D25))))
A26: 46273.542 | B26: 41.1749 | C26: 0 | E26: =IF(OR(C26=9,B26=""),"",B26-$C$3) | F26: =IF(C26=9,"",IF(C26=0,E26,IF(C26=1,IF(COUNT(E22:E30)=0,"",TRIMMEAN(E22:E30,0.5)),IF(D26="","",D26))))
A27: 46273.552 | B27: 41.0269 | C27: 0 | E27: =IF(OR(C27=9,B27=""),"",B27-$C$3) | F27: =IF(C27=9,"",IF(C27=0,E27,IF(C27=1,IF(COUNT(E23:E31)=0,"",TRIMMEAN(E23:E31,0.5)),IF(D27="","",D27))))
A28: 46273.562 | B28: 41.1033 | C28: 0 | E28: =IF(OR(C28=9,B28=""),"",B28-$C$3) | F28: =IF(C28=9,"",IF(C28=0,E28,IF(C28=1,IF(COUNT(E24:E32)=0,"",TRIMMEAN(E24:E32,0.5)),IF(D28="","",D28))))
A29: 46273.573 | B29: 41.3989 | C29: 0 | E29: =IF(OR(C29=9,B29=""),"",B29-$C$3) | F29: =IF(C29=9,"",IF(C29=0,E29,IF(C29=1,IF(COUNT(E25:E33)=0,"",TRIMMEAN(E25:E33,0.5)),IF(D29="","",D29))))
A30: 46273.583 | B30: 41.7131 | C30: 0 | E30: =IF(OR(C30=9,B30=""),"",B30-$C$3) | F30: =IF(C30=9,"",IF(C30=0,E30,IF(C30=1,IF(COUNT(E26:E34)=0,"",TRIMMEAN(E26:E34,0.5)),IF(D30="","",D30))))
A31: 46273.594 | B31: 41.5354 | C31: 0 | E31: =IF(OR(C31=9,B31=""),"",B31-$C$3) | F31: =IF(C31=9,"",IF(C31=0,E31,IF(C31=1,IF(COUNT(E27:E35)=0,"",TRIMMEAN(E27:E35,0.5)),IF(D31="","",D31))))
A32: 46273.604 | B32: 41.7835 | C32: 0 | E32: =IF(OR(C32=9,B32=""),"",B32-$C$3) | F32: =IF(C32=9,"",IF(C32=0,E32,IF(C32=1,IF(COUNT(E28:E36)=0,"",TRIMMEAN(E28:E36,0.5)),IF(D32="","",D32))))
A33: 46273.615 | B33: 41.4857 | C33: 0 | E33: =IF(OR(C33=9,B33=""),"",B33-$C$3) | F33: =IF(C33=9,"",IF(C33=0,E33,IF(C33=1,IF(COUNT(E29:E37)=0,"",TRIMMEAN(E29:E37,0.5)),IF(D33="","",D33))))
A34: 46273.625 | B34: 41.5435 | C34: 0 | E34: =IF(OR(C34=9,B34=""),"",B34-$C$3) | F34: =IF(C34=9,"",IF(C34=0,E34,IF(C34=1,IF(COUNT(E30:E38)=0,"",TRIMMEAN(E30:E38,0.5)),IF(D34="","",D34))))
A35: 46273.635 | B35: 41.1638 | C35: 0 | E35: =IF(OR(C35=9,B35=""),"",B35-$C$3) | F35: =IF(C35=9,"",IF(C35=0,E35,IF(C35=1,IF(COUNT(E31:E39)=0,"",TRIMMEAN(E31:E39,0.5)),IF(D35="","",D35))))
... A780: 46281.396 | B780: 40.129 | C780: 0 | E780: =IF(OR(C780=9,B780=""),"",B780-$C$3) | F780: =IF(C780=9,"",IF(C780=0,E780,IF(C780=1,IF(COUNT(E776:E784)=0,"",TRIMMEAN(E776:E784,0.5)),IF(D780="","",D780))))
A781: 46281.406 | B781: 13.7017 | C781: 9 | E781: =IF(OR(C781=9,B781=""),"",B781-$C$3) | F781: =IF(C781=9,"",IF(C781=0,E781,IF(C781=1,IF(COUNT(E777:E785)=0,"",TRIMMEAN(E777:E785,0.5)),IF(D781="","",D781)))) | G781: equipo sin instalar
A782: 46281.417 | B782: -0.2881 | C782: 9 | E782: =IF(OR(C782=9,B782=""),"",B782-$C$3) | F782: =IF(C782=9,"",IF(C782=0,E782,IF(C782=1,IF(COUNT(E778:E786)=0,"",TRIMMEAN(E778:E786,0.5)),IF(D782="","",D782)))) | G782: equipo sin instalar
A783: 46281.427 | B783: -0.2428 | C783: 9 | E783: =IF(OR(C783=9,B783=""),"",B783-$C$3) | F783: =IF(C783=9,"",IF(C783=0,E783,IF(C783=1,IF(COUNT(E779:E787)=0,"",TRIMMEAN(E779:E787,0.5)),IF(D783="","",D783)))) | G783: equipo sin instalar
A784: 46281.438 | B784: -0.316 | C784: 9 | E784: =IF(OR(C784=9,B784=""),"",B784-$C$3) | F784: =IF(C784=9,"",IF(C784=0,E784,IF(C784=1,IF(COUNT(E780:E788)=0,"",TRIMMEAN(E780:E788,0.5)),IF(D784="","",D784)))) | G784: equipo sin instalar
A785: 46281.448 | B785: -0.5927 | C785: 9 | E785: =IF(OR(C785=9,B785=""),"",B785-$C$3) | F785: =IF(C785=9,"",IF(C785=0,E785,IF(C785=1,IF(COUNT(E781:E789)=0,"",TRIMMEAN(E781:E789,0.5)),IF(D785="","",D785)))) | G785: equipo sin instalar
...

Sheet P7
A1: P7 · Presión (m) · VN3751475
A2: Válido
A3: Offset | C3: 0.03
A4: Ventana (lecturas a cada lado) | C4: 4
A6: Fecha y hora | B6: Dato inicial (m) | C6: Marca | D6: Reemplazo | E6: Corregido (m) | F6: Dato depurado (m) | G6: Motivo
A7: 46273.344 | B7: -0.28 | C7: 9 | E7: =IF(OR(C7=9,B7=""),"",B7-$C$3) | F7: =IF(C7=9,"",IF(C7=0,E7,IF(C7=1,IF(COUNT(E7:E11)=0,"",TRIMMEAN(E7:E11,0.5)),IF(D7="","",D7)))) | G7: equipo sin instalar
A8: 46273.354 | B8: -0.2613 | C8: 9 | E8: =IF(OR(C8=9,B8=""),"",B8-$C$3) | F8: =IF(C8=9,"",IF(C8=0,E8,IF(C8=1,IF(COUNT(E7:E12)=0,"",TRIMMEAN(E7:E12,0.5)),IF(D8="","",D8)))) | G8: equipo sin instalar
A9: 46273.365 | B9: -0.8215 | C9: 9 | E9: =IF(OR(C9=9,B9=""),"",B9-$C$3) | F9: =IF(C9=9,"",IF(C9=0,E9,IF(C9=1,IF(COUNT(E7:E13)=0,"",TRIMMEAN(E7:E13,0.5)),IF(D9="","",D9)))) | G9: equipo sin instalar
A10: 46273.375 | B10: -0.8495 | C10: 9 | E10: =IF(OR(C10=9,B10=""),"",B10-$C$3) | F10: =IF(C10=9,"",IF(C10=0,E10,IF(C10=1,IF(COUNT(E7:E14)=0,"",TRIMMEAN(E7:E14,0.5)),IF(D10="","",D10)))) | G10: equipo sin instalar
A11: 46273.385 | B11: -0.8495 | C11: 9 | E11: =IF(OR(C11=9,B11=""),"",B11-$C$3) | F11: =IF(C11=9,"",IF(C11=0,E11,IF(C11=1,IF(COUNT(E7:E15)=0,"",TRIMMEAN(E7:E15,0.5)),IF(D11="","",D11)))) | G11: equipo sin instalar
A12: 46273.396 | B12: -0.8401 | C12: 9 | E12: =IF(OR(C12=9,B12=""),"",B12-$C$3) | F12: =IF(C12=9,"",IF(C12=0,E12,IF(C12=1,IF(COUNT(E8:E16)=0,"",TRIMMEAN(E8:E16,0.5)),IF(D12="","",D12)))) | G12: equipo sin instalar
A13: 46273.406 | B13: -0.8775 | C13: 9 | E13: =IF(OR(C13=9,B13=""),"",B13-$C$3) | F13: =IF(C13=9,"",IF(C13=0,E13,IF(C13=1,IF(COUNT(E9:E17)=0,"",TRIMMEAN(E9:E17,0.5)),IF(D13="","",D13)))) | G13: equipo sin instalar
A14: 46273.417 | B14: -0.8215 | C14: 9 | E14: =IF(OR(C14=9,B14=""),"",B14-$C$3) | F14: =IF(C14=9,"",IF(C14=0,E14,IF(C14=1,IF(COUNT(E10:E18)=0,"",TRIMMEAN(E10:E18,0.5)),IF(D14="","",D14)))) | G14: equipo sin instalar
A15: 46273.427 | B15: -0.5787 | C15: 9 | E15: =IF(OR(C15=9,B15=""),"",B15-$C$3) | F15: =IF(C15=9,"",IF(C15=0,E15,IF(C15=1,IF(COUNT(E11:E19)=0,"",TRIMMEAN(E11:E19,0.5)),IF(D15="","",D15)))) | G15: equipo sin instalar
A16: 46273.438 | B16: -0.3733 | C16: 9 | E16: =IF(OR(C16=9,B16=""),"",B16-$C$3) | F16: =IF(C16=9,"",IF(C16=0,E16,IF(C16=1,IF(COUNT(E12:E20)=0,"",TRIMMEAN(E12:E20,0.5)),IF(D16="","",D16)))) | G16: equipo sin instalar
A17: 46273.448 | B17: -0.2613 | C17: 9 | E17: =IF(OR(C17=9,B17=""),"",B17-$C$3) | F17: =IF(C17=9,"",IF(C17=0,E17,IF(C17=1,IF(COUNT(E13:E21)=0,"",TRIMMEAN(E13:E21,0.5)),IF(D17="","",D17)))) | G17: equipo sin instalar
A18: 46273.458 | B18: -0.28 | C18: 9 | E18: =IF(OR(C18=9,B18=""),"",B18-$C$3) | F18: =IF(C18=9,"",IF(C18=0,E18,IF(C18=1,IF(COUNT(E14:E22)=0,"",TRIMMEAN(E14:E22,0.5)),IF(D18="","",D18)))) | G18: equipo sin instalar
A19: 46273.469 | B19: -0.2893 | C19: 9 | E19: =IF(OR(C19=9,B19=""),"",B19-$C$3) | F19: =IF(C19=9,"",IF(C19=0,E19,IF(C19=1,IF(COUNT(E15:E23)=0,"",TRIMMEAN(E15:E23,0.5)),IF(D19="","",D19)))) | G19: equipo sin instalar
A20: 46273.479 | B20: -0.224 | C20: 9 | E20: =IF(OR(C20=9,B20=""),"",B20-$C$3) | F20: =IF(C20=9,"",IF(C20=0,E20,IF(C20=1,IF(COUNT(E16:E24)=0,"",TRIMMEAN(E16:E24,0.5)),IF(D20="","",D20)))) | G20: equipo sin instalar
A21: 46273.49 | B21: -0.2333 | C21: 9 | E21: =IF(OR(C21=9,B21=""),"",B21-$C$3) | F21: =IF(C21=9,"",IF(C21=0,E21,IF(C21=1,IF(COUNT(E17:E25)=0,"",TRIMMEAN(E17:E25,0.5)),IF(D21="","",D21)))) | G21: equipo sin instalar
A22: 46273.5 | B22: 48.84 | C22: 9 | E22: =IF(OR(C22=9,B22=""),"",B22-$C$3) | F22: =IF(C22=9,"",IF(C22=0,E22,IF(C22=1,IF(COUNT(E18:E26)=0,"",TRIMMEAN(E18:E26,0.5)),IF(D22="","",D22)))) | G22: equipo sin instalar
A23: 46273.51 | B23: 86.2263 | C23: 0 | E23: =IF(OR(C23=9,B23=""),"",B23-$C$3) | F23: =IF(C23=9,"",IF(C23=0,E23,IF(C23=1,IF(COUNT(E19:E27)=0,"",TRIMMEAN(E19:E27,0.5)),IF(D23="","",D23))))
A24: 46273.521 | B24: 86.2928 | C24: 0 | E24: =IF(OR(C24=9,B24=""),"",B24-$C$3) | F24: =IF(C24=9,"",IF(C24=0,E24,IF(C24=1,IF(COUNT(E20:E28)=0,"",TRIMMEAN(E20:E28,0.5)),IF(D24="","",D24))))
A25: 46273.531 | B25: 85.5415 | C25: 0 | E25: =IF(OR(C25=9,B25=""),"",B25-$C$3) | F25: =IF(C25=9,"",IF(C25=0,E25,IF(C25=1,IF(COUNT(E21:E29)=0,"",TRIMMEAN(E21:E29,0.5)),IF(D25="","",D25))))
A26: 46273.542 | B26: 85.694 | C26: 0 | E26: =IF(OR(C26=9,B26=""),"",B26-$C$3) | F26: =IF(C26=9,"",IF(C26=0,E26,IF(C26=1,IF(COUNT(E22:E30)=0,"",TRIMMEAN(E22:E30,0.5)),IF(D26="","",D26))))
A27: 46273.552 | B27: 86.3988 | C27: 0 | E27: =IF(OR(C27=9,B27=""),"",B27-$C$3) | F27: =IF(C27=9,"",IF(C27=0,E27,IF(C27=1,IF(COUNT(E23:E31)=0,"",TRIMMEAN(E23:E31,0.5)),IF(D27="","",D27))))
A28: 46273.562 | B28: 85.7022 | C28: 0 | E28: =IF(OR(C28=9,B28=""),"",B28-$C$3) | F28: =IF(C28=9,"",IF(C28=0,E28,IF(C28=1,IF(COUNT(E24:E32)=0,"",TRIMMEAN(E24:E32,0.5)),IF(D28="","",D28))))
A29: 46273.573 | B29: 86.4172 | C29: 0 | E29: =IF(OR(C29=9,B29=""),"",B29-$C$3) | F29: =IF(C29=9,"",IF(C29=0,E29,IF(C29=1,IF(COUNT(E25:E33)=0,"",TRIMMEAN(E25:E33,0.5)),IF(D29="","",D29))))
A30: 46273.583 | B30: 85.2319 | C30: 0 | E30: =IF(OR(C30=9,B30=""),"",B30-$C$3) | F30: =IF(C30=9,"",IF(C30=0,E30,IF(C30=1,IF(COUNT(E26:E34)=0,"",TRIMMEAN(E26:E34,0.5)),IF(D30="","",D30))))
A31: 46273.594 | B31: 84.6918 | C31: 0 | E31: =IF(OR(C31=9,B31=""),"",B31-$C$3) | F31: =IF(C31=9,"",IF(C31=0,E31,IF(C31=1,IF(COUNT(E27:E35)=0,"",TRIMMEAN(E27:E35,0.5)),IF(D31="","",D31))))
A32: 46273.604 | B32: 86.378 | C32: 0 | E32: =IF(OR(C32=9,B32=""),"",B32-$C$3) | F32: =IF(C32=9,"",IF(C32=0,E32,IF(C32=1,IF(COUNT(E28:E36)=0,"",TRIMMEAN(E28:E36,0.5)),IF(D32="","",D32))))
A33: 46273.615 | B33: 86.3878 | C33: 0 | E33: =IF(OR(C33=9,B33=""),"",B33-$C$3) | F33: =IF(C33=9,"",IF(C33=0,E33,IF(C33=1,IF(COUNT(E29:E37)=0,"",TRIMMEAN(E29:E37,0.5)),IF(D33="","",D33))))
A34: 46273.625 | B34: 85.8665 | C34: 0 | E34: =IF(OR(C34=9,B34=""),"",B34-$C$3) | F34: =IF(C34=9,"",IF(C34=0,E34,IF(C34=1,IF(COUNT(E30:E38)=0,"",TRIMMEAN(E30:E38,0.5)),IF(D34="","",D34))))
... A779: 46281.385 | B779: 84.7432 | C779: 0 | E779: =IF(OR(C779=9,B779=""),"",B779-$C$3) | F779: =IF(C779=9,"",IF(C779=0,E779,IF(C779=1,IF(COUNT(E775:E783)=0,"",TRIMMEAN(E775:E783,0.5)),IF(D779="","",D779))))
A780: 46281.396 | B780: 64.5202 | C780: 9 | E780: =IF(OR(C780=9,B780=""),"",B780-$C$3) | F780: =IF(C780=9,"",IF(C780=0,E780,IF(C780=1,IF(COUNT(E776:E784)=0,"",TRIMMEAN(E776:E784,0.5)),IF(D780="","",D780)))) | G780: equipo sin instalar
A781: 46281.406 | B781: -0.3046 | C781: 9 | E781: =IF(OR(C781=9,B781=""),"",B781-$C$3) | F781: =IF(C781=9,"",IF(C781=0,E781,IF(C781=1,IF(COUNT(E777:E785)=0,"",TRIMMEAN(E777:E785,0.5)),IF(D781="","",D781)))) | G781: equipo sin instalar
A782: 46281.417 | B782: -0.3558 | C782: 9 | E782: =IF(OR(C782=9,B782=""),"",B782-$C$3) | F782: =IF(C782=9,"",IF(C782=0,E782,IF(C782=1,IF(COUNT(E778:E786)=0,"",TRIMMEAN(E778:E786,0.5)),IF(D782="","",D782)))) | G782: equipo sin instalar
A783: 46281.427 | B783: -0.2684 | C783: 9 | E783: =IF(OR(C783=9,B783=""),"",B783-$C$3) | F783: =IF(C783=9,"",IF(C783=0,E783,IF(C783=1,IF(COUNT(E779:E787)=0,"",TRIMMEAN(E779:E787,0.5)),IF(D783="","",D783)))) | G783: equipo sin instalar
A784: 46281.438 | B784: -0.3845 | C784: 9 | E784: =IF(OR(C784=9,B784=""),"",B784-$C$3) | F784: =IF(C784=9,"",IF(C784=0,E784,IF(C784=1,IF(COUNT(E780:E788)=0,"",TRIMMEAN(E780:E788,0.5)),IF(D784="","",D784)))) | G784: equipo sin instalar
A785: 46281.448 | B785: -0.7591 | C785: 9 | E785: =IF(OR(C785=9,B785=""),"",B785-$C$3) | F785: =IF(C785=9,"",IF(C785=0,E785,IF(C785=1,IF(COUNT(E781:E789)=0,"",TRIMMEAN(E781:E789,0.5)),IF(D785="","",D785)))) | G785: equipo sin instalar
...

Sheet P8
A1: P8 · Presión (m) · VN3950311
A2: Válido (suavizado)
A3: Offset | C3: -0.28
A4: Ventana (lecturas a cada lado) | C4: 4
A6: Fecha y hora | B6: Dato inicial (m) | C6: Marca | D6: Reemplazo | E6: Corregido (m) | F6: Dato depurado (m) | G6: Motivo
A7: 46273.344 | B7: -0.2801 | C7: 9 | E7: =IF(OR(C7=9,B7=""),"",B7-$C$3) | F7: =IF(C7=9,"",IF(C7=0,E7,IF(C7=1,IF(COUNT(E7:E11)=0,"",TRIMMEAN(E7:E11,0.5)),IF(D7="","",D7)))) | G7: equipo sin instalar
A8: 46273.354 | B8: -0.2708 | C8: 9 | E8: =IF(OR(C8=9,B8=""),"",B8-$C$3) | F8: =IF(C8=9,"",IF(C8=0,E8,IF(C8=1,IF(COUNT(E7:E12)=0,"",TRIMMEAN(E7:E12,0.5)),IF(D8="","",D8)))) | G8: equipo sin instalar
A9: 46273.365 | B9: -0.8403 | C9: 9 | E9: =IF(OR(C9=9,B9=""),"",B9-$C$3) | F9: =IF(C9=9,"",IF(C9=0,E9,IF(C9=1,IF(COUNT(E7:E13)=0,"",TRIMMEAN(E7:E13,0.5)),IF(D9="","",D9)))) | G9: equipo sin instalar
A10: 46273.375 | B10: -0.8683 | C10: 9 | E10: =IF(OR(C10=9,B10=""),"",B10-$C$3) | F10: =IF(C10=9,"",IF(C10=0,E10,IF(C10=1,IF(COUNT(E7:E14)=0,"",TRIMMEAN(E7:E14,0.5)),IF(D10="","",D10)))) | G10: equipo sin instalar
A11: 46273.385 | B11: -0.8589 | C11: 9 | E11: =IF(OR(C11=9,B11=""),"",B11-$C$3) | F11: =IF(C11=9,"",IF(C11=0,E11,IF(C11=1,IF(COUNT(E7:E15)=0,"",TRIMMEAN(E7:E15,0.5)),IF(D11="","",D11)))) | G11: equipo sin instalar
A12: 46273.396 | B12: -0.8683 | C12: 9 | E12: =IF(OR(C12=9,B12=""),"",B12-$C$3) | F12: =IF(C12=9,"",IF(C12=0,E12,IF(C12=1,IF(COUNT(E8:E16)=0,"",TRIMMEAN(E8:E16,0.5)),IF(D12="","",D12)))) | G12: equipo sin instalar
A13: 46273.406 | B13: -0.8683 | C13: 9 | E13: =IF(OR(C13=9,B13=""),"",B13-$C$3) | F13: =IF(C13=9,"",IF(C13=0,E13,IF(C13=1,IF(COUNT(E9:E17)=0,"",TRIMMEAN(E9:E17,0.5)),IF(D13="","",D13)))) | G13: equipo sin instalar
A14: 46273.417 | B14: -0.8496 | C14: 9 | E14: =IF(OR(C14=9,B14=""),"",B14-$C$3) | F14: =IF(C14=9,"",IF(C14=0,E14,IF(C14=1,IF(COUNT(E10:E18)=0,"",TRIMMEAN(E10:E18,0.5)),IF(D14="","",D14)))) | G14: equipo sin instalar
A15: 46273.427 | B15: -0.5882 | C15: 9 | E15: =IF(OR(C15=9,B15=""),"",B15-$C$3) | F15: =IF(C15=9,"",IF(C15=0,E15,IF(C15=1,IF(COUNT(E11:E19)=0,"",TRIMMEAN(E11:E19,0.5)),IF(D15="","",D15)))) | G15: equipo sin instalar
A16: 46273.438 | B16: -0.3735 | C16: 9 | E16: =IF(OR(C16=9,B16=""),"",B16-$C$3) | F16: =IF(C16=9,"",IF(C16=0,E16,IF(C16=1,IF(COUNT(E12:E20)=0,"",TRIMMEAN(E12:E20,0.5)),IF(D16="","",D16)))) | G16: equipo sin instalar
A17: 46273.448 | B17: -0.3095 | C17: 9 | E17: =IF(OR(C17=9,B17=""),"",B17-$C$3) | F17: =IF(C17=9,"",IF(C17=0,E17,IF(C17=1,IF(COUNT(E13:E21)=0,"",TRIMMEAN(E13:E21,0.5)),IF(D17="","",D17)))) | G17: equipo sin instalar
A18: 46273.458 | B18: -0.2895 | C18: 9 | E18: =IF(OR(C18=9,B18=""),"",B18-$C$3) | F18: =IF(C18=9,"",IF(C18=0,E18,IF(C18=1,IF(COUNT(E14:E22)=0,"",TRIMMEAN(E14:E22,0.5)),IF(D18="","",D18)))) | G18: equipo sin instalar
A19: 46273.469 | B19: -0.283 | C19: 9 | E19: =IF(OR(C19=9,B19=""),"",B19-$C$3) | F19: =IF(C19=9,"",IF(C19=0,E19,IF(C19=1,IF(COUNT(E15:E23)=0,"",TRIMMEAN(E15:E23,0.5)),IF(D19="","",D19)))) | G19: equipo sin instalar
A20: 46273.479 | B20: -0.2544 | C20: 9 | E20: =IF(OR(C20=9,B20=""),"",B20-$C$3) | F20: =IF(C20=9,"",IF(C20=0,E20,IF(C20=1,IF(COUNT(E16:E24)=0,"",TRIMMEAN(E16:E24,0.5)),IF(D20="","",D20)))) | G20: equipo sin instalar
A21: 46273.49 | B21: -0.2492 | C21: 9 | E21: =IF(OR(C21=9,B21=""),"",B21-$C$3) | F21: =IF(C21=9,"",IF(C21=0,E21,IF(C21=1,IF(COUNT(E17:E25)=0,"",TRIMMEAN(E17:E25,0.5)),IF(D21="","",D21)))) | G21: equipo sin instalar
A22: 46273.5 | B22: -0.2971 | C22: 9 | E22: =IF(OR(C22=9,B22=""),"",B22-$C$3) | F22: =IF(C22=9,"",IF(C22=0,E22,IF(C22=1,IF(COUNT(E18:E26)=0,"",TRIMMEAN(E18:E26,0.5)),IF(D22="","",D22)))) | G22: equipo sin instalar
... A24: 46273.521 | B24: 22.9054 | C24: 9 | E24: =IF(OR(C24=9,B24=""),"",B24-$C$3) | F24: =IF(C24=9,"",IF(C24=0,E24,IF(C24=1,IF(COUNT(E20:E28)=0,"",TRIMMEAN(E20:E28,0.5)),IF(D24="","",D24)))) | G24: equipo sin instalar
A25: 46273.531 | B25: 56.2808 | C25: 0 | E25: =IF(OR(C25=9,B25=""),"",B25-$C$3) | F25: =IF(C25=9,"",IF(C25=0,E25,IF(C25=1,IF(COUNT(E21:E29)=0,"",TRIMMEAN(E21:E29,0.5)),IF(D25="","",D25))))
A26: 46273.542 | B26: 61.7483 | C26: 0 | E26: =IF(OR(C26=9,B26=""),"",B26-$C$3) | F26: =IF(C26=9,"",IF(C26=0,E26,IF(C26=1,IF(COUNT(E22:E30)=0,"",TRIMMEAN(E22:E30,0.5)),IF(D26="","",D26))))
A27: 46273.552 | B27: 62.0588 | C27: 0 | E27: =IF(OR(C27=9,B27=""),"",B27-$C$3) | F27: =IF(C27=9,"",IF(C27=0,E27,IF(C27=1,IF(COUNT(E23:E31)=0,"",TRIMMEAN(E23:E31,0.5)),IF(D27="","",D27))))
A28: 46273.562 | B28: 61.9566 | C28: 0 | E28: =IF(OR(C28=9,B28=""),"",B28-$C$3) | F28: =IF(C28=9,"",IF(C28=0,E28,IF(C28=1,IF(COUNT(E24:E32)=0,"",TRIMMEAN(E24:E32,0.5)),IF(D28="","",D28))))
A29: 46273.573 | B29: 61.8453 | C29: 0 | E29: =IF(OR(C29=9,B29=""),"",B29-$C$3) | F29: =IF(C29=9,"",IF(C29=0,E29,IF(C29=1,IF(COUNT(E25:E33)=0,"",TRIMMEAN(E25:E33,0.5)),IF(D29="","",D29))))
A30: 46273.583 | B30: 62.5377 | C30: 0 | E30: =IF(OR(C30=9,B30=""),"",B30-$C$3) | F30: =IF(C30=9,"",IF(C30=0,E30,IF(C30=1,IF(COUNT(E26:E34)=0,"",TRIMMEAN(E26:E34,0.5)),IF(D30="","",D30))))
A31: 46273.594 | B31: 61.6587 | C31: 0 | E31: =IF(OR(C31=9,B31=""),"",B31-$C$3) | F31: =IF(C31=9,"",IF(C31=0,E31,IF(C31=1,IF(COUNT(E27:E35)=0,"",TRIMMEAN(E27:E35,0.5)),IF(D31="","",D31))))
A32: 46273.604 | B32: 62.1349 | C32: 0 | E32: =IF(OR(C32=9,B32=""),"",B32-$C$3) | F32: =IF(C32=9,"",IF(C32=0,E32,IF(C32=1,IF(COUNT(E28:E36)=0,"",TRIMMEAN(E28:E36,0.5)),IF(D32="","",D32))))
A33: 46273.615 | B33: 62.3863 | C33: 0 | E33: =IF(OR(C33=9,B33=""),"",B33-$C$3) | F33: =IF(C33=9,"",IF(C33=0,E33,IF(C33=1,IF(COUNT(E29:E37)=0,"",TRIMMEAN(E29:E37,0.5)),IF(D33="","",D33))))
A34: 46273.625 | B34: 62.3839 | C34: 0 | E34: =IF(OR(C34=9,B34=""),"",B34-$C$3) | F34: =IF(C34=9,"",IF(C34=0,E34,IF(C34=1,IF(COUNT(E30:E38)=0,"",TRIMMEAN(E30:E38,0.5)),IF(D34="","",D34))))
A35: 46273.635 | B35: 62.9491 | C35: 0 | E35: =IF(OR(C35=9,B35=""),"",B35-$C$3) | F35: =IF(C35=9,"",IF(C35=0,E35,IF(C35=1,IF(COUNT(E31:E39)=0,"",TRIMMEAN(E31:E39,0.5)),IF(D35="","",D35))))
