Workbook

Sheet Resumen
A1: Tanque Durazno · fuga entre el caudalímetro de entrada y el tanque
A2: ZP-05 Vista del Mar · Q2 (entrada) y Q3 (salida), datos crudos del equipo ultrasónico cada 15 min
A4: Parámetro | B4: Valor | H4: Origen / criterio
A5: Factor del medidor Q2 (k) | B5: 1.259 | H5: Q2 = k × entrada real + fuga. Ajustado con los días sin fuga (30/08 y 01–03/09): media diaria, noche 01–05 h y mediodía 10–14 h. Q2 lee de más: señal 0,004 V (Q3 0,30 V) y velocidad del sonido 1603 m/s (agua ≈ 1500).
A6: Inicio de la fuga | B6: 46269.698 | H6: Cambio de nivel del exceso Q2 − k·Q3 (segmentación). Entre 10:00 y 16:45 del 04/09 la entrada estuvo estrangulada y el tanque bajó; al reabrir aparece la fuga.
A7: Reparación | B7: 46281.354 | H7: Inicio de la maniobra de reparación (16/09); a las 12:00 se retira el equipo.
A8: Diámetro del tanque (m) | B8: 5.19 | H8: INP, tanque 3949679
A9: Área (m²) | B9: =PI()*B8^2/4 -> 21.155563
A10: Nivel de control (m) | B10: 1.85 | H10: Nivel que mantiene la VRP 3960324 de entrada (consigna 2,45 m en cota 1587,1 → carga 1589,55 m; fondo 1587,70 m). Ancla de la curva.
A11: Inicio del balance | B11: 46266 | H11: Antes del 01/09 hay cortes y pérdidas de señal en Q2/Q3 que impiden integrar el balance.
A13: Resultado por día
A14: Día | B14: Q2 medio (L/s) | C14: Q3 medio (L/s) | D14: Entrada real (L/s) | E14: Fuga media (L/s) | F14: Fuga (m³/día) | G14: Fuga / Q2 (%)
A15: 46261 | B15: =IFERROR(AVERAGEIFS(Datos!$B$8:$B$1936,Datos!$A$8:$A$1936,">="&$A15,Datos!$A$8:$A$1936,"<"&($A15+1)),"") -> 3.6601038 | C15: =IFERROR(AVERAGEIFS(Datos!$C$8:$C$1936,Datos!$A$8:$A$1936,">="&$A15,Datos!$A$8:$A$1936,"<"&($A15+1)),"") -> 3.0479212 | D15: =IFERROR(AVERAGEIFS(Datos!$F$8:$F$1936,Datos!$A$8:$A$1936,">="&$A15,Datos!$A$8:$A$1936,"<"&($A15+1)),"") -> 2.9071516 | E15: =IFERROR(AVERAGEIFS(Datos!$E$8:$E$1936,Datos!$A$8:$A$1936,">="&$A15,Datos!$A$8:$A$1936,"<"&($A15+1)),"") -> 0 | F15: =IF(E15="","",E15*86.4) -> 0 | G15: =IF(OR(E15="",B15="",B15=0),"",E15/B15) -> 0
A16: 46262 | B16: =IFERROR(AVERAGEIFS(Datos!$B$8:$B$1936,Datos!$A$8:$A$1936,">="&$A16,Datos!$A$8:$A$1936,"<"&($A16+1)),"") -> 1.8514656 | C16: =IFERROR(AVERAGEIFS(Datos!$C$8:$C$1936,Datos!$A$8:$A$1936,">="&$A16,Datos!$A$8:$A$1936,"<"&($A16+1)),"") -> 1.4431542 | D16: =IFERROR(AVERAGEIFS(Datos!$F$8:$F$1936,Datos!$A$8:$A$1936,">="&$A16,Datos!$A$8:$A$1936,"<"&($A16+1)),"") -> 1.4705843 | E16: =IFERROR(AVERAGEIFS(Datos!$E$8:$E$1936,Datos!$A$8:$A$1936,">="&$A16,Datos!$A$8:$A$1936,"<"&($A16+1)),"") -> 0 | F16: =IF(E16="","",E16*86.4) -> 0 | G16: =IF(OR(E16="",B16="",B16=0),"",E16/B16) -> 0
A17: 46263 | B17: =IFERROR(AVERAGEIFS(Datos!$B$8:$B$1936,Datos!$A$8:$A$1936,">="&$A17,Datos!$A$8:$A$1936,"<"&($A17+1)),"") -> 3.7166573 | C17: =IFERROR(AVERAGEIFS(Datos!$C$8:$C$1936,Datos!$A$8:$A$1936,">="&$A17,Datos!$A$8:$A$1936,"<"&($A17+1)),"") -> 1.5012396 | D17: =IFERROR(AVERAGEIFS(Datos!$F$8:$F$1936,Datos!$A$8:$A$1936,">="&$A17,Datos!$A$8:$A$1936,"<"&($A17+1)),"") -> 2.9520709 | E17: =IFERROR(AVERAGEIFS(Datos!$E$8:$E$1936,Datos!$A$8:$A$1936,">="&$A17,Datos!$A$8:$A$1936,"<"&($A17+1)),"") -> 0 | F17: =IF(E17="","",E17*86.4) -> 0 | G17: =IF(OR(E17="",B17="",B17=0),"",E17/B17) -> 0
A18: 46264 | B18: =IFERROR(AVERAGEIFS(Datos!$B$8:$B$1936,Datos!$A$8:$A$1936,">="&$A18,Datos!$A$8:$A$1936,"<"&($A18+1)),"") -> 3.2332813 | C18: =IFERROR(AVERAGEIFS(Datos!$C$8:$C$1936,Datos!$A$8:$A$1936,">="&$A18,Datos!$A$8:$A$1936,"<"&($A18+1)),"") -> 2.6813417 | D18: =IFERROR(AVERAGEIFS(Datos!$F$8:$F$1936,Datos!$A$8:$A$1936,">="&$A18,Datos!$A$8:$A$1936,"<"&($A18+1)),"") -> 2.5681344 | E18: =IFERROR(AVERAGEIFS(Datos!$E$8:$E$1936,Datos!$A$8:$A$1936,">="&$A18,Datos!$A$8:$A$1936,"<"&($A18+1)),"") -> 0 | F18: =IF(E18="","",E18*86.4) -> 0 | G18: =IF(OR(E18="",B18="",B18=0),"",E18/B18) -> 0
A19: 46265 | B19: =IFERROR(AVERAGEIFS(Datos!$B$8:$B$1936,Datos!$A$8:$A$1936,">="&$A19,Datos!$A$8:$A$1936,"<"&($A19+1)),"") -> 3.4705344 | C19: =IFERROR(AVERAGEIFS(Datos!$C$8:$C$1936,Datos!$A$8:$A$1936,">="&$A19,Datos!$A$8:$A$1936,"<"&($A19+1)),"") -> 1.941275 | D19: =IFERROR(AVERAGEIFS(Datos!$F$8:$F$1936,Datos!$A$8:$A$1936,">="&$A19,Datos!$A$8:$A$1936,"<"&($A19+1)),"") -> 2.7565801 | E19: =IFERROR(AVERAGEIFS(Datos!$E$8:$E$1936,Datos!$A$8:$A$1936,">="&$A19,Datos!$A$8:$A$1936,"<"&($A19+1)),"") -> 0 | F19: =IF(E19="","",E19*86.4) -> 0 | G19: =IF(OR(E19="",B19="",B19=0),"",E19/B19) -> 0
A20: 46266 | B20: =IFERROR(AVERAGEIFS(Datos!$B$8:$B$1936,Datos!$A$8:$A$1936,">="&$A20,Datos!$A$8:$A$1936,"<"&($A20+1)),"") -> 3.4728344 | C20: =IFERROR(AVERAGEIFS(Datos!$C$8:$C$1936,Datos!$A$8:$A$1936,">="&$A20,Datos!$A$8:$A$1936,"<"&($A20+1)),"") -> 2.7024438 | D20: =IFERROR(AVERAGEIFS(Datos!$F$8:$F$1936,Datos!$A$8:$A$1936,">="&$A20,Datos!$A$8:$A$1936,"<"&($A20+1)),"") -> 2.758407 | E20: =IFERROR(AVERAGEIFS(Datos!$E$8:$E$1936,Datos!$A$8:$A$1936,">="&$A20,Datos!$A$8:$A$1936,"<"&($A20+1)),"") -> 0 | F20: =IF(E20="","",E20*86.4) -> 0 | G20: =IF(OR(E20="",B20="",B20=0),"",E20/B20) -> 0
A21: 46267 | B21: =IFERROR(AVERAGEIFS(Datos!$B$8:$B$1936,Datos!$A$8:$A$1936,">="&$A21,Datos!$A$8:$A$1936,"<"&($A21+1)),"") -> 3.5544667 | C21: =IFERROR(AVERAGEIFS(Datos!$C$8:$C$1936,Datos!$A$8:$A$1936,">="&$A21,Datos!$A$8:$A$1936,"<"&($A21+1)),"") -> 2.8433031 | D21: =IFERROR(AVERAGEIFS(Datos!$F$8:$F$1936,Datos!$A$8:$A$1936,">="&$A21,Datos!$A$8:$A$1936,"<"&($A21+1)),"") -> 2.823246 | E21: =IFERROR(AVERAGEIFS(Datos!$E$8:$E$1936,Datos!$A$8:$A$1936,">="&$A21,Datos!$A$8:$A$1936,"<"&($A21+1)),"") -> 0 | F21: =IF(E21="","",E21*86.4) -> 0 | G21: =IF(OR(E21="",B21="",B21=0),"",E21/B21) -> 0
A22: 46268 | B22: =IFERROR(AVERAGEIFS(Datos!$B$8:$B$1936,Datos!$A$8:$A$1936,">="&$A22,Datos!$A$8:$A$1936,"<"&($A22+1)),"") -> 3.8226896 | C22: =IFERROR(AVERAGEIFS(Datos!$C$8:$C$1936,Datos!$A$8:$A$1936,">="&$A22,Datos!$A$8:$A$1936,"<"&($A22+1)),"") -> 2.8495 | D22: =IFERROR(AVERAGEIFS(Datos!$F$8:$F$1936,Datos!$A$8:$A$1936,">="&$A22,Datos!$A$8:$A$1936,"<"&($A22+1)),"") -> 3.0362904 | E22: =IFERROR(AVERAGEIFS(Datos!$E$8:$E$1936,Datos!$A$8:$A$1936,">="&$A22,Datos!$A$8:$A$1936,"<"&($A22+1)),"") -> 0 | F22: =IF(E22="","",E22*86.4) -> 0 | G22: =IF(OR(E22="",B22="",B22=0),"",E22/B22) -> 0
A23: 46269 | B23: =IFERROR(AVERAGEIFS(Datos!$B$8:$B$1936,Datos!$A$8:$A$1936,">="&$A23,Datos!$A$8:$A$1936,"<"&($A23+1)),"") -> 4.002 | C23: =IFERROR(AVERAGEIFS(Datos!$C$8:$C$1936,Datos!$A$8:$A$1936,">="&$A23,Datos!$A$8:$A$1936,"<"&($A23+1)),"") -> 3.0411094 | D23: =IFERROR(AVERAGEIFS(Datos!$F$8:$F$1936,Datos!$A$8:$A$1936,">="&$A23,Datos!$A$8:$A$1936,"<"&($A23+1)),"") -> 3.1377962 | E23: =IFERROR(AVERAGEIFS(Datos!$E$8:$E$1936,Datos!$A$8:$A$1936,">="&$A23,Datos!$A$8:$A$1936,"<"&($A23+1)),"") -> 0.051514607 | F23: =IF(E23="","",E23*86.4) -> 4.450862 | G23: =IF(OR(E23="",B23="",B23=0),"",E23/B23) -> 0.012872216
A24: 46270 | B24: =IFERROR(AVERAGEIFS(Datos!$B$8:$B$1936,Datos!$A$8:$A$1936,">="&$A24,Datos!$A$8:$A$1936,"<"&($A24+1)),"") -> 3.9310229 | C24: =IFERROR(AVERAGEIFS(Datos!$C$8:$C$1936,Datos!$A$8:$A$1936,">="&$A24,Datos!$A$8:$A$1936,"<"&($A24+1)),"") -> 2.709676 | D24: =IFERROR(AVERAGEIFS(Datos!$F$8:$F$1936,Datos!$A$8:$A$1936,">="&$A24,Datos!$A$8:$A$1936,"<"&($A24+1)),"") -> 2.68741 | E24: =IFERROR(AVERAGEIFS(Datos!$E$8:$E$1936,Datos!$A$8:$A$1936,">="&$A24,Datos!$A$8:$A$1936,"<"&($A24+1)),"") -> 0.54757375 | F24: =IF(E24="","",E24*86.4) -> 47.310372 | G24: =IF(OR(E24="",B24="",B24=0),"",E24/B24) -> 0.13929549
A25: 46271 | B25: =IFERROR(AVERAGEIFS(Datos!$B$8:$B$1936,Datos!$A$8:$A$1936,">="&$A25,Datos!$A$8:$A$1936,"<"&($A25+1)),"") -> 3.9025333 | C25: =IFERROR(AVERAGEIFS(Datos!$C$8:$C$1936,Datos!$A$8:$A$1936,">="&$A25,Datos!$A$8:$A$1936,"<"&($A25+1)),"") -> 2.6785563 | D25: =IFERROR(AVERAGEIFS(Datos!$F$8:$F$1936,Datos!$A$8:$A$1936,">="&$A25,Datos!$A$8:$A$1936,"<"&($A25+1)),"") -> 2.6942573 | E25: =IFERROR(AVERAGEIFS(Datos!$E$8:$E$1936,Datos!$A$8:$A$1936,">="&$A25,Datos!$A$8:$A$1936,"<"&($A25+1)),"") -> 0.51046343 | F25: =IF(E25="","",E25*86.4) -> 44.10404 | G25: =IF(OR(E25="",B25="",B25=0),"",E25/B25) -> 0.13080309
A26: 46272 | B26: =IFERROR(AVERAGEIFS(Datos!$B$8:$B$1936,Datos!$A$8:$A$1936,">="&$A26,Datos!$A$8:$A$1936,"<"&($A26+1)),"") -> 4.2129052 | C26: =IFERROR(AVERAGEIFS(Datos!$C$8:$C$1936,Datos!$A$8:$A$1936,">="&$A26,Datos!$A$8:$A$1936,"<"&($A26+1)),"") -> 2.870875 | D26: =IFERROR(AVERAGEIFS(Datos!$F$8:$F$1936,Datos!$A$8:$A$1936,">="&$A26,Datos!$A$8:$A$1936,"<"&($A26+1)),"") -> 2.8523254 | E26: =IFERROR(AVERAGEIFS(Datos!$E$8:$E$1936,Datos!$A$8:$A$1936,">="&$A26,Datos!$A$8:$A$1936,"<"&($A26+1)),"") -> 0.62182751 | F26: =IF(E26="","",E26*86.4) -> 53.725897 | G26: =IF(OR(E26="",B26="",B26=0),"",E26/B26) -> 0.14760064
... A35: 46281 | B35: =IFERROR(AVERAGEIFS(Datos!$B$8:$B$1936,Datos!$A$8:$A$1936,">="&$A35,Datos!$A$8:$A$1936,"<"&($A35+1)),"") -> 4.6048 | C35: =IFERROR(AVERAGEIFS(Datos!$C$8:$C$1936,Datos!$A$8:$A$1936,">="&$A35,Datos!$A$8:$A$1936,"<"&($A35+1)),"") -> 3.1523566 | D35: =IFERROR(AVERAGEIFS(Datos!$F$8:$F$1936,Datos!$A$8:$A$1936,">="&$A35,Datos!$A$8:$A$1936,"<"&($A35+1)),"") -> 2.8399276 | E35: =IFERROR(AVERAGEIFS(Datos!$E$8:$E$1936,Datos!$A$8:$A$1936,">="&$A35,Datos!$A$8:$A$1936,"<"&($A35+1)),"") -> 1.0293311 | F35: =IF(E35="","",E35*86.4) -> 88.934211 | G35: =IF(OR(E35="",B35="",B35=0),"",E35/B35) -> 0.22353439
A36: Volumen perdido hasta la reparación (m³) | F36: =SUMPRODUCT(Datos!$E$8:$E$1936)*0.9 -> 821.25074
A37: Fuga media entre el inicio y la reparación (L/s) | E37: =AVERAGEIFS(Datos!$E$8:$E$1936,Datos!$A$8:$A$1936,">="&$B$6,Datos!$A$8:$A$1936,"<"&$B$7) -> 0.81546097
A39: En azul: valores editables. Todo lo demás se calcula con fórmulas a partir de los datos crudos de la hoja «Datos».

Sheet Datos
A1: Datos crudos y cálculo del balance del tanque Durazno
A2: Fuga = media móvil 24 h de Q2 − k × media móvil 24 h de Q3 (≥ 0), solo entre el inicio y la reparación · Entrada real = (Q2 − fuga)/k · Nivel = acumulado del balance (entrada − Q3)/área, sin la deriva de 24 h y anclado al nivel de control
A7: Fecha y hora | B7: Q2 entrada crudo (L/s) | C7: Q3 salida crudo (L/s) | D7: Válido | E7: Fuga (L/s) | F7: Entrada real al tanque (L/s) | G7: Balance (m³ en 15 min) | H7: Nivel acumulado (m) | I7: Nivel sin deriva (m) | J7: Nivel estimado (m)
A8: 46261.458 | B8: 4.1962 | C8: 4.0014 | D8: =IF(OR(B8="",C8="",B8<=0.05,C8<=0.05),0,1) -> 1 | E8: =IF(OR(A8<Resumen!$B$6,A8>=Resumen!$B$7),0,MAX(0,AVERAGEIFS(B8:B56,D8:D56,1)-Resumen!$B$5*AVERAGEIFS(C8:C56,D8:D56,1))) -> 0 | F8: =IF(B8="","",(B8-E8)/Resumen!$B$5) -> 3.3329627 | G8: =IF(OR(F8="",C8=""),0,(F8-C8)*0.9) -> -0.6015936 | H8: =IF(A8<Resumen!$B$11,"",IF(0="",0,0)+G8/Resumen!$B$9) | I8: =IF(H8="","",H8-AVERAGE(H8:H56)) | J8: =IF(I8="","",Resumen!$B$10-(MAX(I8:I56)-I8))
A9: 46261.469 | B9: 5.0434 | C9: 4.2185 | D9: =IF(OR(B9="",C9="",B9<=0.05,C9<=0.05),0,1) -> 1 | E9: =IF(OR(A9<Resumen!$B$6,A9>=Resumen!$B$7),0,MAX(0,AVERAGEIFS(B8:B57,D8:D57,1)-Resumen!$B$5*AVERAGEIFS(C8:C57,D8:D57,1))) -> 0 | F9: =IF(B9="","",(B9-E9)/Resumen!$B$5) -> 4.0058777 | G9: =IF(OR(F9="",C9=""),0,(F9-C9)*0.9) -> -0.19136009 | H9: =IF(A9<Resumen!$B$11,"",IF(H8="",0,H8)+G9/Resumen!$B$9) | I9: =IF(H9="","",H9-AVERAGE(H8:H57)) | J9: =IF(I9="","",Resumen!$B$10-(MAX(I8:I57)-I9))
A10: 46261.479 | B10: 5.4454 | C10: 4.6153 | D10: =IF(OR(B10="",C10="",B10<=0.05,C10<=0.05),0,1) -> 1 | E10: =IF(OR(A10<Resumen!$B$6,A10>=Resumen!$B$7),0,MAX(0,AVERAGEIFS(B8:B58,D8:D58,1)-Resumen!$B$5*AVERAGEIFS(C8:C58,D8:D58,1))) -> 0 | F10: =IF(B10="","",(B10-E10)/Resumen!$B$5) -> 4.3251787 | G10: =IF(OR(F10="",C10=""),0,(F10-C10)*0.9) -> -0.26110916 | H10: =IF(A10<Resumen!$B$11,"",IF(H9="",0,H9)+G10/Resumen!$B$9) | I10: =IF(H10="","",H10-AVERAGE(H8:H58)) | J10: =IF(I10="","",Resumen!$B$10-(MAX(I8:I58)-I10))
A11: 46261.49 | B11: 5.7613 | C11: 5.6418 | D11: =IF(OR(B11="",C11="",B11<=0.05,C11<=0.05),0,1) -> 1 | E11: =IF(OR(A11<Resumen!$B$6,A11>=Resumen!$B$7),0,MAX(0,AVERAGEIFS(B8:B59,D8:D59,1)-Resumen!$B$5*AVERAGEIFS(C8:C59,D8:D59,1))) -> 0 | F11: =IF(B11="","",(B11-E11)/Resumen!$B$5) -> 4.5760921 | G11: =IF(OR(F11="",C11=""),0,(F11-C11)*0.9) -> -0.95913708 | H11: =IF(A11<Resumen!$B$11,"",IF(H10="",0,H10)+G11/Resumen!$B$9) | I11: =IF(H11="","",H11-AVERAGE(H8:H59)) | J11: =IF(I11="","",Resumen!$B$10-(MAX(I8:I59)-I11))
A12: 46261.5 | B12: 7.3245 | C12: 5.8711 | D12: =IF(OR(B12="",C12="",B12<=0.05,C12<=0.05),0,1) -> 1 | E12: =IF(OR(A12<Resumen!$B$6,A12>=Resumen!$B$7),0,MAX(0,AVERAGEIFS(B8:B60,D8:D60,1)-Resumen!$B$5*AVERAGEIFS(C8:C60,D8:D60,1))) -> 0 | F12: =IF(B12="","",(B12-E12)/Resumen!$B$5) -> 5.8177125 | G12: =IF(OR(F12="",C12=""),0,(F12-C12)*0.9) -> -0.048048777 | H12: =IF(A12<Resumen!$B$11,"",IF(H11="",0,H11)+G12/Resumen!$B$9) | I12: =IF(H12="","",H12-AVERAGE(H8:H60)) | J12: =IF(I12="","",Resumen!$B$10-(MAX(I8:I60)-I12))
A13: 46261.51 | B13: 8.43 | C13: 5.6696 | D13: =IF(OR(B13="",C13="",B13<=0.05,C13<=0.05),0,1) -> 1 | E13: =IF(OR(A13<Resumen!$B$6,A13>=Resumen!$B$7),0,MAX(0,AVERAGEIFS(B8:B61,D8:D61,1)-Resumen!$B$5*AVERAGEIFS(C8:C61,D8:D61,1))) -> 0 | F13: =IF(B13="","",(B13-E13)/Resumen!$B$5) -> 6.6957903 | G13: =IF(OR(F13="",C13=""),0,(F13-C13)*0.9) -> 0.92357128 | H13: =IF(A13<Resumen!$B$11,"",IF(H12="",0,H12)+G13/Resumen!$B$9) | I13: =IF(H13="","",H13-AVERAGE(H8:H61)) | J13: =IF(I13="","",Resumen!$B$10-(MAX(I8:I61)-I13))
A14: 46261.521 | B14: 4.2937 | C14: 3.6802 | D14: =IF(OR(B14="",C14="",B14<=0.05,C14<=0.05),0,1) -> 1 | E14: =IF(OR(A14<Resumen!$B$6,A14>=Resumen!$B$7),0,MAX(0,AVERAGEIFS(B8:B62,D8:D62,1)-Resumen!$B$5*AVERAGEIFS(C8:C62,D8:D62,1))) -> 0 | F14: =IF(B14="","",(B14-E14)/Resumen!$B$5) -> 3.4104051 | G14: =IF(OR(F14="",C14=""),0,(F14-C14)*0.9) -> -0.24281542 | H14: =IF(A14<Resumen!$B$11,"",IF(H13="",0,H13)+G14/Resumen!$B$9) | I14: =IF(H14="","",H14-AVERAGE(H8:H62)) | J14: =IF(I14="","",Resumen!$B$10-(MAX(I8:I62)-I14))
A15: 46261.531 | B15: 4.4944 | C15: 3.806 | D15: =IF(OR(B15="",C15="",B15<=0.05,C15<=0.05),0,1) -> 1 | E15: =IF(OR(A15<Resumen!$B$6,A15>=Resumen!$B$7),0,MAX(0,AVERAGEIFS(B8:B63,D8:D63,1)-Resumen!$B$5*AVERAGEIFS(C8:C63,D8:D63,1))) -> 0 | F15: =IF(B15="","",(B15-E15)/Resumen!$B$5) -> 3.5698173 | G15: =IF(OR(F15="",C15=""),0,(F15-C15)*0.9) -> -0.21256442 | H15: =IF(A15<Resumen!$B$11,"",IF(H14="",0,H14)+G15/Resumen!$B$9) | I15: =IF(H15="","",H15-AVERAGE(H8:H63)) | J15: =IF(I15="","",Resumen!$B$10-(MAX(I8:I63)-I15))
A16: 46261.542 | B16: 4.867 | C16: 3.9966 | D16: =IF(OR(B16="",C16="",B16<=0.05,C16<=0.05),0,1) -> 1 | E16: =IF(OR(A16<Resumen!$B$6,A16>=Resumen!$B$7),0,MAX(0,AVERAGEIFS(B8:B64,D8:D64,1)-Resumen!$B$5*AVERAGEIFS(C8:C64,D8:D64,1))) -> 0 | F16: =IF(B16="","",(B16-E16)/Resumen!$B$5) -> 3.8657665 | G16: =IF(OR(F16="",C16=""),0,(F16-C16)*0.9) -> -0.11775017 | H16: =IF(A16<Resumen!$B$11,"",IF(H15="",0,H15)+G16/Resumen!$B$9) | I16: =IF(H16="","",H16-AVERAGE(H8:H64)) | J16: =IF(I16="","",Resumen!$B$10-(MAX(I8:I64)-I16))
A17: 46261.552 | B17: 4.5879 | C17: 4.3679 | D17: =IF(OR(B17="",C17="",B17<=0.05,C17<=0.05),0,1) -> 1 | E17: =IF(OR(A17<Resumen!$B$6,A17>=Resumen!$B$7),0,MAX(0,AVERAGEIFS(B8:B65,D8:D65,1)-Resumen!$B$5*AVERAGEIFS(C8:C65,D8:D65,1))) -> 0 | F17: =IF(B17="","",(B17-E17)/Resumen!$B$5) -> 3.6440826 | G17: =IF(OR(F17="",C17=""),0,(F17-C17)*0.9) -> -0.65143566 | H17: =IF(A17<Resumen!$B$11,"",IF(H16="",0,H16)+G17/Resumen!$B$9) | I17: =IF(H17="","",H17-AVERAGE(H8:H65)) | J17: =IF(I17="","",Resumen!$B$10-(MAX(I8:I65)-I17))
A18: 46261.562 | B18: 7.8124 | C18: 5.1017 | D18: =IF(OR(B18="",C18="",B18<=0.05,C18<=0.05),0,1) -> 1 | E18: =IF(OR(A18<Resumen!$B$6,A18>=Resumen!$B$7),0,MAX(0,AVERAGEIFS(B8:B66,D8:D66,1)-Resumen!$B$5*AVERAGEIFS(C8:C66,D8:D66,1))) -> 0 | F18: =IF(B18="","",(B18-E18)/Resumen!$B$5) -> 6.2052423 | G18: =IF(OR(F18="",C18=""),0,(F18-C18)*0.9) -> 0.99318803 | H18: =IF(A18<Resumen!$B$11,"",IF(H17="",0,H17)+G18/Resumen!$B$9) | I18: =IF(H18="","",H18-AVERAGE(H8:H66)) | J18: =IF(I18="","",Resumen!$B$10-(MAX(I8:I66)-I18))
A19: 46261.573 | B19: 3.4571 | C19: 3.1217 | D19: =IF(OR(B19="",C19="",B19<=0.05,C19<=0.05),0,1) -> 1 | E19: =IF(OR(A19<Resumen!$B$6,A19>=Resumen!$B$7),0,MAX(0,AVERAGEIFS(B8:B67,D8:D67,1)-Resumen!$B$5*AVERAGEIFS(C8:C67,D8:D67,1))) -> 0 | F19: =IF(B19="","",(B19-E19)/Resumen!$B$5) -> 2.7459095 | G19: =IF(OR(F19="",C19=""),0,(F19-C19)*0.9) -> -0.33821149 | H19: =IF(A19<Resumen!$B$11,"",IF(H18="",0,H18)+G19/Resumen!$B$9) | I19: =IF(H19="","",H19-AVERAGE(H8:H67)) | J19: =IF(I19="","",Resumen!$B$10-(MAX(I8:I67)-I19))
A20: 46261.583 | B20: 4.2035 | C20: 2.5615 | D20: =IF(OR(B20="",C20="",B20<=0.05,C20<=0.05),0,1) -> 1 | E20: =IF(OR(A20<Resumen!$B$6,A20>=Resumen!$B$7),0,MAX(0,AVERAGEIFS(B8:B68,D8:D68,1)-Resumen!$B$5*AVERAGEIFS(C8:C68,D8:D68,1))) -> 0 | F20: =IF(B20="","",(B20-E20)/Resumen!$B$5) -> 3.3387609 | G20: =IF(OR(F20="",C20=""),0,(F20-C20)*0.9) -> 0.69953483 | H20: =IF(A20<Resumen!$B$11,"",IF(H19="",0,H19)+G20/Resumen!$B$9) | I20: =IF(H20="","",H20-AVERAGE(H8:H68)) | J20: =IF(I20="","",Resumen!$B$10-(MAX(I8:I68)-I20))
A21: 46261.594 | B21: 4.6767 | C21: 2.7378 | D21: =IF(OR(B21="",C21="",B21<=0.05,C21<=0.05),0,1) -> 1 | E21: =IF(OR(A21<Resumen!$B$6,A21>=Resumen!$B$7),0,MAX(0,AVERAGEIFS(B8:B69,D8:D69,1)-Resumen!$B$5*AVERAGEIFS(C8:C69,D8:D69,1))) -> 0 | F21: =IF(B21="","",(B21-E21)/Resumen!$B$5) -> 3.7146148 | G21: =IF(OR(F21="",C21=""),0,(F21-C21)*0.9) -> 0.8791333 | H21: =IF(A21<Resumen!$B$11,"",IF(H20="",0,H20)+G21/Resumen!$B$9) | I21: =IF(H21="","",H21-AVERAGE(H8:H69)) | J21: =IF(I21="","",Resumen!$B$10-(MAX(I8:I69)-I21))
A22: 46261.604 | B22: 4.5846 | C22: 2.8554 | D22: =IF(OR(B22="",C22="",B22<=0.05,C22<=0.05),0,1) -> 1 | E22: =IF(OR(A22<Resumen!$B$6,A22>=Resumen!$B$7),0,MAX(0,AVERAGEIFS(B8:B70,D8:D70,1)-Resumen!$B$5*AVERAGEIFS(C8:C70,D8:D70,1))) -> 0 | F22: =IF(B22="","",(B22-E22)/Resumen!$B$5) -> 3.6414615 | G22: =IF(OR(F22="",C22=""),0,(F22-C22)*0.9) -> 0.70745533 | H22: =IF(A22<Resumen!$B$11,"",IF(H21="",0,H21)+G22/Resumen!$B$9) | I22: =IF(H22="","",H22-AVERAGE(H8:H70)) | J22: =IF(I22="","",Resumen!$B$10-(MAX(I8:I70)-I22))
A23: 46261.615 | B23: 4.3548 | C23: 3.6647 | D23: =IF(OR(B23="",C23="",B23<=0.05,C23<=0.05),0,1) -> 1 | E23: =IF(OR(A23<Resumen!$B$6,A23>=Resumen!$B$7),0,MAX(0,AVERAGEIFS(B8:B71,D8:D71,1)-Resumen!$B$5*AVERAGEIFS(C8:C71,D8:D71,1))) -> 0 | F23: =IF(B23="","",(B23-E23)/Resumen!$B$5) -> 3.4589357 | G23: =IF(OR(F23="",C23=""),0,(F23-C23)*0.9) -> -0.1851879 | H23: =IF(A23<Resumen!$B$11,"",IF(H22="",0,H22)+G23/Resumen!$B$9) | I23: =IF(H23="","",H23-AVERAGE(H8:H71)) | J23: =IF(I23="","",Resumen!$B$10-(MAX(I8:I71)-I23))
A24: 46261.625 | B24: 2.8312 | C24: 2.8198 | D24: =IF(OR(B24="",C24="",B24<=0.05,C24<=0.05),0,1) -> 1 | E24: =IF(OR(A24<Resumen!$B$6,A24>=Resumen!$B$7),0,MAX(0,AVERAGEIFS(B8:B72,D8:D72,1)-Resumen!$B$5*AVERAGEIFS(C8:C72,D8:D72,1))) -> 0 | F24: =IF(B24="","",(B24-E24)/Resumen!$B$5) -> 2.2487689 | G24: =IF(OR(F24="",C24=""),0,(F24-C24)*0.9) -> -0.51392802 | H24: =IF(A24<Resumen!$B$11,"",IF(H23="",0,H23)+G24/Resumen!$B$9) | I24: =IF(H24="","",H24-AVERAGE(H8:H72)) | J24: =IF(I24="","",Resumen!$B$10-(MAX(I8:I72)-I24))
A25: 46261.635 | B25: 4.3069 | C25: 2.5429 | D25: =IF(OR(B25="",C25="",B25<=0.05,C25<=0.05),0,1) -> 1 | E25: =IF(OR(A25<Resumen!$B$6,A25>=Resumen!$B$7),0,MAX(0,AVERAGEIFS(B8:B73,D8:D73,1)-Resumen!$B$5*AVERAGEIFS(C8:C73,D8:D73,1))) -> 0 | F25: =IF(B25="","",(B25-E25)/Resumen!$B$5) -> 3.4208896 | G25: =IF(OR(F25="",C25=""),0,(F25-C25)*0.9) -> 0.79019064 | H25: =IF(A25<Resumen!$B$11,"",IF(H24="",0,H24)+G25/Resumen!$B$9) | I25: =IF(H25="","",H25-AVERAGE(H8:H73)) | J25: =IF(I25="","",Resumen!$B$10-(MAX(I8:I73)-I25))
A26: 46261.646 | B26: 3.0314 | C26: 3.232 | D26: =IF(OR(B26="",C26="",B26<=0.05,C26<=0.05),0,1) -> 1 | E26: =IF(OR(A26<Resumen!$B$6,A26>=Resumen!$B$7),0,MAX(0,AVERAGEIFS(B8:B74,D8:D74,1)-Resumen!$B$5*AVERAGEIFS(C8:C74,D8:D74,1))) -> 0 | F26: =IF(B26="","",(B26-E26)/Resumen!$B$5) -> 2.407784 | G26: =IF(OR(F26="",C26=""),0,(F26-C26)*0.9) -> -0.74179444 | H26: =IF(A26<Resumen!$B$11,"",IF(H25="",0,H25)+G26/Resumen!$B$9) | I26: =IF(H26="","",H26-AVERAGE(H8:H74)) | J26: =IF(I26="","",Resumen!$B$10-(MAX(I8:I74)-I26))
A27: 46261.656 | B27: 3.4577 | C27: 3.0622 | D27: =IF(OR(B27="",C27="",B27<=0.05,C27<=0.05),0,1) -> 1 | E27: =IF(OR(A27<Resumen!$B$6,A27>=Resumen!$B$7),0,MAX(0,AVERAGEIFS(B8:B75,D8:D75,1)-Resumen!$B$5*AVERAGEIFS(C8:C75,D8:D75,1))) -> 0 | F27: =IF(B27="","",(B27-E27)/Resumen!$B$5) -> 2.746386 | G27: =IF(OR(F27="",C27=""),0,(F27-C27)*0.9) -> -0.28423258 | H27: =IF(A27<Resumen!$B$11,"",IF(H26="",0,H26)+G27/Resumen!$B$9) | I27: =IF(H27="","",H27-AVERAGE(H8:H75)) | J27: =IF(I27="","",Resumen!$B$10-(MAX(I8:I75)-I27))
A28: 46261.667 | B28: 1.9004 | C28: 2.2455 | D28: =IF(OR(B28="",C28="",B28<=0.05,C28<=0.05),0,1) -> 1 | E28: =IF(OR(A28<Resumen!$B$6,A28>=Resumen!$B$7),0,MAX(0,AVERAGEIFS(B8:B76,D8:D76,1)-Resumen!$B$5*AVERAGEIFS(C8:C76,D8:D76,1))) -> 0 | F28: =IF(B28="","",(B28-E28)/Resumen!$B$5) -> 1.5094519 | G28: =IF(OR(F28="",C28=""),0,(F28-C28)*0.9) -> -0.66244325 | H28: =IF(A28<Resumen!$B$11,"",IF(H27="",0,H27)+G28/Resumen!$B$9) | I28: =IF(H28="","",H28-AVERAGE(H8:H76)) | J28: =IF(I28="","",Resumen!$B$10-(MAX(I8:I76)-I28))
A29: 46261.677 | B29: 3.3761 | C29: 3.1342 | D29: =IF(OR(B29="",C29="",B29<=0.05,C29<=0.05),0,1) -> 1 | E29: =IF(OR(A29<Resumen!$B$6,A29>=Resumen!$B$7),0,MAX(0,AVERAGEIFS(B8:B77,D8:D77,1)-Resumen!$B$5*AVERAGEIFS(C8:C77,D8:D77,1))) -> 0 | F29: =IF(B29="","",(B29-E29)/Resumen!$B$5) -> 2.6815727 | G29: =IF(OR(F29="",C29=""),0,(F29-C29)*0.9) -> -0.40736459 | H29: =IF(A29<Resumen!$B$11,"",IF(H28="",0,H28)+G29/Resumen!$B$9) | I29: =IF(H29="","",H29-AVERAGE(H8:H77)) | J29: =IF(I29="","",Resumen!$B$10-(MAX(I8:I77)-I29))
A30: 46261.688 | B30: 4.6826 | C30: 2.6085 | D30: =IF(OR(B30="",C30="",B30<=0.05,C30<=0.05),0,1) -> 1 | E30: =IF(OR(A30<Resumen!$B$6,A30>=Resumen!$B$7),0,MAX(0,AVERAGEIFS(B8:B78,D8:D78,1)-Resumen!$B$5*AVERAGEIFS(C8:C78,D8:D78,1))) -> 0 | F30: =IF(B30="","",(B30-E30)/Resumen!$B$5) -> 3.719301 | G30: =IF(OR(F30="",C30=""),0,(F30-C30)*0.9) -> 0.99972093 | H30: =IF(A30<Resumen!$B$11,"",IF(H29="",0,H29)+G30/Resumen!$B$9) | I30: =IF(H30="","",H30-AVERAGE(H8:H78)) | J30: =IF(I30="","",Resumen!$B$10-(MAX(I8:I78)-I30))
A31: 46261.698 | B31: 3.1266 | C31: 2.8243 | D31: =IF(OR(B31="",C31="",B31<=0.05,C31<=0.05),0,1) -> 1 | E31: =IF(OR(A31<Resumen!$B$6,A31>=Resumen!$B$7),0,MAX(0,AVERAGEIFS(B8:B79,D8:D79,1)-Resumen!$B$5*AVERAGEIFS(C8:C79,D8:D79,1))) -> 0 | F31: =IF(B31="","",(B31-E31)/Resumen!$B$5) -> 2.4833995 | G31: =IF(OR(F31="",C31=""),0,(F31-C31)*0.9) -> -0.30681043 | H31: =IF(A31<Resumen!$B$11,"",IF(H30="",0,H30)+G31/Resumen!$B$9) | I31: =IF(H31="","",H31-AVERAGE(H8:H79)) | J31: =IF(I31="","",Resumen!$B$10-(MAX(I8:I79)-I31))
A32: 46261.708 | B32: 3.4414 | C32: 3.1303 | D32: =IF(OR(B32="",C32="",B32<=0.05,C32<=0.05),0,1) -> 1 | E32: =IF(OR(A32<Resumen!$B$6,A32>=Resumen!$B$7),0,MAX(0,AVERAGEIFS(B8:B80,D8:D80,1)-Resumen!$B$5*AVERAGEIFS(C8:C80,D8:D80,1))) -> 0 | F32: =IF(B32="","",(B32-E32)/Resumen!$B$5) -> 2.7334392 | G32: =IF(OR(F32="",C32=""),0,(F32-C32)*0.9) -> -0.35717469 | H32: =IF(A32<Resumen!$B$11,"",IF(H31="",0,H31)+G32/Resumen!$B$9) | I32: =IF(H32="","",H32-AVERAGE(H8:H80)) | J32: =IF(I32="","",Resumen!$B$10-(MAX(I8:I80)-I32))
A33: 46261.719 | B33: 3.2393 | C33: 2.9127 | D33: =IF(OR(B33="",C33="",B33<=0.05,C33<=0.05),0,1) -> 1 | E33: =IF(OR(A33<Resumen!$B$6,A33>=Resumen!$B$7),0,MAX(0,AVERAGEIFS(B8:B81,D8:D81,1)-Resumen!$B$5*AVERAGEIFS(C8:C81,D8:D81,1))) -> 0 | F33: =IF(B33="","",(B33-E33)/Resumen!$B$5) -> 2.572915 | G33: =IF(OR(F33="",C33=""),0,(F33-C33)*0.9) -> -0.30580649 | H33: =IF(A33<Resumen!$B$11,"",IF(H32="",0,H32)+G33/Resumen!$B$9) | I33: =IF(H33="","",H33-AVERAGE(H8:H81)) | J33: =IF(I33="","",Resumen!$B$10-(MAX(I8:I81)-I33))
A34: 46261.729 | B34: 2.6601 | C34: 2.6336 | D34: =IF(OR(B34="",C34="",B34<=0.05,C34<=0.05),0,1) -> 1 | E34: =IF(OR(A34<Resumen!$B$6,A34>=Resumen!$B$7),0,MAX(0,AVERAGEIFS(B8:B82,D8:D82,1)-Resumen!$B$5*AVERAGEIFS(C8:C82,D8:D82,1))) -> 0 | F34: =IF(B34="","",(B34-E34)/Resumen!$B$5) -> 2.1128674 | G34: =IF(OR(F34="",C34=""),0,(F34-C34)*0.9) -> -0.46865938 | H34: =IF(A34<Resumen!$B$11,"",IF(H33="",0,H33)+G34/Resumen!$B$9) | I34: =IF(H34="","",H34-AVERAGE(H8:H82)) | J34: =IF(I34="","",Resumen!$B$10-(MAX(I8:I82)-I34))
A35: 46261.74 | B35: 3.8938 | C35: 3.078 | D35: =IF(OR(B35="",C35="",B35<=0.05,C35<=0.05),0,1) -> 1 | E35: =IF(OR(A35<Resumen!$B$6,A35>=Resumen!$B$7),0,MAX(0,AVERAGEIFS(B8:B83,D8:D83,1)-Resumen!$B$5*AVERAGEIFS(C8:C83,D8:D83,1))) -> 0 | F35: =IF(B35="","",(B35-E35)/Resumen!$B$5) -> 3.092772 | G35: =IF(OR(F35="",C35=""),0,(F35-C35)*0.9) -> 0.013294837 | H35: =IF(A35<Resumen!$B$11,"",IF(H34="",0,H34)+G35/Resumen!$B$9) | I35: =IF(H35="","",H35-AVERAGE(H8:H83)) | J35: =IF(I35="","",Resumen!$B$10-(MAX(I8:I83)-I35))
A36: 46261.75 | B36: 2.7428 | C36: 2.956 | D36: =IF(OR(B36="",C36="",B36<=0.05,C36<=0.05),0,1) -> 1 | E36: =IF(OR(A36<Resumen!$B$6,A36>=Resumen!$B$7),0,MAX(0,AVERAGEIFS(B8:B84,D8:D84,1)-Resumen!$B$5*AVERAGEIFS(C8:C84,D8:D84,1))) -> 0 | F36: =IF(B36="","",(B36-E36)/Resumen!$B$5) -> 2.1785544 | G36: =IF(OR(F36="",C36=""),0,(F36-C36)*0.9) -> -0.69970103 | H36: =IF(A36<Resumen!$B$11,"",IF(H35="",0,H35)+G36/Resumen!$B$9) | I36: =IF(H36="","",H36-AVERAGE(H8:H84)) | J36: =IF(I36="","",Resumen!$B$10-(MAX(I8:I84)-I36))
A37: 46261.76 | B37: 4.37 | C37: 3.5497 | D37: =IF(OR(B37="",C37="",B37<=0.05,C37<=0.05),0,1) -> 1 | E37: =IF(OR(A37<Resumen!$B$6,A37>=Resumen!$B$7),0,MAX(0,AVERAGEIFS(B8:B85,D8:D85,1)-Resumen!$B$5*AVERAGEIFS(C8:C85,D8:D85,1))) -> 0 | F37: =IF(B37="","",(B37-E37)/Resumen!$B$5) -> 3.4710087 | G37: =IF(OR(F37="",C37=""),0,(F37-C37)*0.9) -> -0.070822137 | H37: =IF(A37<Resumen!$B$11,"",IF(H36="",0,H36)+G37/Resumen!$B$9) | I37: =IF(H37="","",H37-AVERAGE(H8:H85)) | J37: =IF(I37="","",Resumen!$B$10-(MAX(I8:I85)-I37))
A38: 46261.771 | B38: 2.6606 | C38: 2.6152 | D38: =IF(OR(B38="",C38="",B38<=0.05,C38<=0.05),0,1) -> 1 | E38: =IF(OR(A38<Resumen!$B$6,A38>=Resumen!$B$7),0,MAX(0,AVERAGEIFS(B8:B86,D8:D86,1)-Resumen!$B$5*AVERAGEIFS(C8:C86,D8:D86,1))) -> 0 | F38: =IF(B38="","",(B38-E38)/Resumen!$B$5) -> 2.1132645 | G38: =IF(OR(F38="",C38=""),0,(F38-C38)*0.9) -> -0.45174195 | H38: =IF(A38<Resumen!$B$11,"",IF(H37="",0,H37)+G38/Resumen!$B$9) | I38: =IF(H38="","",H38-AVERAGE(H8:H86)) | J38: =IF(I38="","",Resumen!$B$10-(MAX(I8:I86)-I38))
A39: 46261.781 | B39: 2.3544 | C39: 2.1813 | D39: =IF(OR(B39="",C39="",B39<=0.05,C39<=0.05),0,1) -> 1 | E39: =IF(OR(A39<Resumen!$B$6,A39>=Resumen!$B$7),0,MAX(0,AVERAGEIFS(B8:B87,D8:D87,1)-Resumen!$B$5*AVERAGEIFS(C8:C87,D8:D87,1))) -> 0 | F39: =IF(B39="","",(B39-E39)/Resumen!$B$5) -> 1.8700556 | G39: =IF(OR(F39="",C39=""),0,(F39-C39)*0.9) -> -0.28011996 | H39: =IF(A39<Resumen!$B$11,"",IF(H38="",0,H38)+G39/Resumen!$B$9) | I39: =IF(H39="","",H39-AVERAGE(H8:H87)) | J39: =IF(I39="","",Resumen!$B$10-(MAX(I8:I87)-I39))
A40: 46261.792 | B40: 2.7328 | C40: 2.3653 | D40: =IF(OR(B40="",C40="",B40<=0.05,C40<=0.05),0,1) -> 1 | E40: =IF(OR(A40<Resumen!$B$6,A40>=Resumen!$B$7),0,MAX(0,AVERAGEIFS(B8:B88,D8:D88,1)-Resumen!$B$5*AVERAGEIFS(C8:C88,D8:D88,1))) -> 0 | F40: =IF(B40="","",(B40-E40)/Resumen!$B$5) -> 2.1706116 | G40: =IF(OR(F40="",C40=""),0,(F40-C40)*0.9) -> -0.17521956 | H40: =IF(A40<Resumen!$B$11,"",IF(H39="",0,H39)+G40/Resumen!$B$9) | I40: =IF(H40="","",H40-AVERAGE(H8:H88)) | J40: =IF(I40="","",Resumen!$B$10-(MAX(I8:I88)-I40))
A41: 46261.802 | B41: 2.7361 | C41: 2.3777 | D41: =IF(OR(B41="",C41="",B41<=0.05,C41<=0.05),0,1) -> 1 | E41: =IF(OR(A41<Resumen!$B$6,A41>=Resumen!$B$7),0,MAX(0,AVERAGEIFS(B8:B89,D8:D89,1)-Resumen!$B$5*AVERAGEIFS(C8:C89,D8:D89,1))) -> 0 | F41: =IF(B41="","",(B41-E41)/Resumen!$B$5) -> 2.1732327 | G41: =IF(OR(F41="",C41=""),0,(F41-C41)*0.9) -> -0.18402055 | H41: =IF(A41<Resumen!$B$11,"",IF(H40="",0,H40)+G41/Resumen!$B$9) | I41: =IF(H41="","",H41-AVERAGE(H8:H89)) | J41: =IF(I41="","",Resumen!$B$10-(MAX(I8:I89)-I41))
A42: 46261.812 | B42: 2.6838 | C42: 2.225 | D42: =IF(OR(B42="",C42="",B42<=0.05,C42<=0.05),0,1) -> 1 | E42: =IF(OR(A42<Resumen!$B$6,A42>=Resumen!$B$7),0,MAX(0,AVERAGEIFS(B8:B90,D8:D90,1)-Resumen!$B$5*AVERAGEIFS(C8:C90,D8:D90,1))) -> 0 | F42: =IF(B42="","",(B42-E42)/Resumen!$B$5) -> 2.1316918 | G42: =IF(OR(F42="",C42=""),0,(F42-C42)*0.9) -> -0.083977363 | H42: =IF(A42<Resumen!$B$11,"",IF(H41="",0,H41)+G42/Resumen!$B$9) | I42: =IF(H42="","",H42-AVERAGE(H8:H90)) | J42: =IF(I42="","",Resumen!$B$10-(MAX(I8:I90)-I42))
A43: 46261.823 | B43: 3.9584 | C43: 2.8794 | D43: =IF(OR(B43="",C43="",B43<=0.05,C43<=0.05),0,1) -> 1 | E43: =IF(OR(A43<Resumen!$B$6,A43>=Resumen!$B$7),0,MAX(0,AVERAGEIFS(B8:B91,D8:D91,1)-Resumen!$B$5*AVERAGEIFS(C8:C91,D8:D91,1))) -> 0 | F43: =IF(B43="","",(B43-E43)/Resumen!$B$5) -> 3.1440826 | G43: =IF(OR(F43="",C43=""),0,(F43-C43)*0.9) -> 0.23821434 | H43: =IF(A43<Resumen!$B$11,"",IF(H42="",0,H42)+G43/Resumen!$B$9) | I43: =IF(H43="","",H43-AVERAGE(H8:H91)) | J43: =IF(I43="","",Resumen!$B$10-(MAX(I8:I91)-I43))
A44: 46261.833 | B44: 3.2071 | C44: 2.5711 | D44: =IF(OR(B44="",C44="",B44<=0.05,C44<=0.05),0,1) -> 1 | E44: =IF(OR(A44<Resumen!$B$6,A44>=Resumen!$B$7),0,MAX(0,AVERAGEIFS(B8:B92,D8:D92,1)-Resumen!$B$5*AVERAGEIFS(C8:C92,D8:D92,1))) -> 0 | F44: =IF(B44="","",(B44-E44)/Resumen!$B$5) -> 2.5473392 | G44: =IF(OR(F44="",C44=""),0,(F44-C44)*0.9) -> -0.021384758 | H44: =IF(A44<Resumen!$B$11,"",IF(H43="",0,H43)+G44/Resumen!$B$9) | I44: =IF(H44="","",H44-AVERAGE(H8:H92)) | J44: =IF(I44="","",Resumen!$B$10-(MAX(I8:I92)-I44))
...
